Workbook
Name _xlfn_IFERROR: none
Name _xlfn_QUARTILE_INC: none
Name Excel_BuiltIn_Print_Area: DCF!$A$1:$O$66,#REF!
Name TrialPrice: 'Monte Carlo'!$BF$27:$BF$526

Sheet DCF
B1: A DCF does not tell you the “true” value of a company. It tells you what the company could be worth if your assumptions about future cash flows are reasonably correct. The basic logic of DCF is straightforward: A company is worth the cash it can generate in the future. Those future cash flows are uncertain, so we estimate cash flows on the basis of ASSUMPTIONS and discount those cash flows back to present value to find intrinsic value. DCF is not about intrinsic value it is about margin of error around intrinsic value. Thus we perform scenario and sensitivity analysis.
A2: Granules India Limited: Discounted Cash Flow Analysis
A3: (Rs. in crore, fiscal year ending March 31) | M3: =B4 -> Operating Scenario | O3: =+CHOOSE(D4,'A1'!B10,'A1'!B11,'A1'!B12,'A1'!B13,'A1'!B14) -> Base
B4: Operating Scenario | D4: 1
B5: Mid-Year Convention | D5: N | E5: Historical Period | I5: CAGR | J5: Projection Period | O5: CAGR
E6: 2023 | F6: 2024 | G6: 2025 | H6: 2026 | I6: ('23 - '26) | J6: 2027 | K6: 2028 | L6: 2029 | M6: 2030 | N6: 2031 | O6: ('26 - '31)
B7: Sales | E7: 4511.92 | F7: 4506.37 | G7: 4481.61 | H7: 5365.64 | I7: =+IF(ISERROR((H7/E7)^(1/($H$6-$E$6))-1),"-",(H7/E7)^(1/($H$6-$E$6))-1) -> 0.059465242 | J7: =H7*(1+J35) -> 6277.7988 | K7: =J7*(1+K35) -> 7219.4686 | L7: =K7*(1+L35) -> 8085.8049 | M7: =L7*(1+M35) -> 8894.3853 | N7: =M7*(1+N35) -> 9694.88 | O7: =+IF(ISERROR((N7/H7)^(1/($N$6-$H$6))-1),"-",(N7/H7)^(1/($N$6-$H$6))-1) -> 0.12560025
B8: % growth | E8: NA | F8: =+IF(ISERROR(F7/E7-1),0,F7/E7-1) -> -0.001230075 | G8: =+IF(ISERROR(G7/F7-1),0,G7/F7-1) -> -0.0054944445 | H8: =+IF(ISERROR(H7/G7-1),0,H7/G7-1) -> 0.19725724 | J8: =+IF(ISERROR(J7/H7-1),0,J7/H7-1) -> 0.17 | K8: =+IF(ISERROR(K7/J7-1),0,K7/J7-1) -> 0.15 | L8: =+IF(ISERROR(L7/K7-1),0,L7/K7-1) -> 0.12 | M8: =+IF(ISERROR(M7/L7-1),0,M7/L7-1) -> 0.1 | N8: =+IF(ISERROR(N7/M7-1),0,N7/M7-1) -> 0.09
B9: COGS | E9: 2307.28 | F9: 2021.25 | G9: 1725.7 | H9: 1875.7 | J9: =J7*J36 -> 2165.8406 | K9: =K7*K36 -> 2454.6193 | L9: =L7*L36 -> 2708.7446 | M9: =M7*M36 -> 2935.1472 | N9: =N7*N36 -> 3179.9206
B10: Gross Profit | E10: =+E7-E9 -> 2204.64 | F10: =+F7-F9 -> 2485.12 | G10: =+G7-G9 -> 2755.91 | H10: =+H7-H9 -> 3489.94 | I10: =+IF(ISERROR((H10/E10)^(1/($H$6-$E$6))-1),"-",(H10/E10)^(1/($H$6-$E$6))-1) -> 0.16544941 | J10: =+J7-J9 -> 4111.9582 | K10: =+K7-K9 -> 4764.8493 | L10: =+L7-L9 -> 5377.0602 | M10: =+M7-M9 -> 5959.2382 | N10: =+N7-N9 -> 6514.9594 | O10: =+IF(ISERROR((N10/H10)^(1/($N$6-$H$6))-1),"-",(N10/H10)^(1/($N$6-$H$6))-1) -> 0.13297089
B11: % margin | E11: =+IF(ISERROR(E10/E7),0,E10/E7) -> 0.48862568 | F11: =+IF(ISERROR(F10/F7),0,F10/F7) -> 0.55146825 | G11: =+IF(ISERROR(G10/G7),0,G10/G7) -> 0.61493749 | H11: =+IF(ISERROR(H10/H7),0,H10/H7) -> 0.65042381 | J11: =+IF(ISERROR(J10/J7),0,J10/J7) -> 0.655 | K11: =+IF(ISERROR(K10/K7),0,K10/K7) -> 0.66 | L11: =+IF(ISERROR(L10/L7),0,L10/L7) -> 0.665 | M11: =+IF(ISERROR(M10/M7),0,M10/M7) -> 0.67 | N11: =+IF(ISERROR(N10/N7),0,N10/N7) -> 0.672
B12: SG&A | E12: 1290.81 | F12: 1629.14 | G12: 1810.67 | H12: 2304.8 | J12: =J7*J37 -> 2699.4535 | K12: =K7*K37 -> 3104.3715 | L12: =L7*L37 -> 3436.4671 | M12: =M7*M37 -> 3735.6418 | N12: =N7*N37 -> 4042.765
B13: EBITDA | E13: =E10-E12 -> 913.83 | F13: =F10-F12 -> 855.98 | G13: =G10-G12 -> 945.24 | H13: =H10-H12 -> 1185.14 | I13: =+IF(ISERROR((H13/E13)^(1/($H$6-$E$6))-1),"-",(H13/E13)^(1/($H$6-$E$6))-1) -> 0.090522796 | J13: =J10-J12 -> 1412.5047 | K13: =K10-K12 -> 1660.4778 | L13: =L10-L12 -> 1940.5932 | M13: =M10-M12 -> 2223.5963 | N13: =N10-N12 -> 2472.1944 | O13: =+IF(ISERROR((N13/H13)^(1/($N$6-$H$6))-1),"-",(N13/H13)^(1/($N$6-$H$6))-1) -> 0.15841079
B14: % margin | E14: =+IF(ISERROR(E13/E7),0,E13/E7) -> 0.20253684 | F14: =+IF(ISERROR(F13/F7),0,F13/F7) -> 0.18994889 | G14: =+IF(ISERROR(G13/G7),0,G13/G7) -> 0.21091527 | H14: =+IF(ISERROR(H13/H7),0,H13/H7) -> 0.22087579 | J14: =+IF(ISERROR(J13/J7),0,J13/J7) -> 0.225 | K14: =+IF(ISERROR(K13/K7),0,K13/K7) -> 0.23 | L14: =+IF(ISERROR(L13/L7),0,L13/L7) -> 0.24 | M14: =+IF(ISERROR(M13/M7),0,M13/M7) -> 0.25 | N14: =+IF(ISERROR(N13/N7),0,N13/N7) -> 0.255
B15: Depreciation & Amortization | E15: 184.49 | F15: 207.33 | G15: 225.5 | H15: 296.14 | J15: =J7*J38 -> 351.55673 | K15: =K7*K38 -> 397.07077 | L15: =L7*L38 -> 428.54766 | M15: =M7*M38 -> 444.71927 | N15: =N7*N38 -> 465.35424
B16: EBIT | E16: =+E13-E15 -> 729.34 | F16: =+F13-F15 -> 648.65 | G16: =+G13-G15 -> 719.74 | H16: =+H13-H15 -> 889 | I16: =+IF(ISERROR((H16/E16)^(1/($H$6-$E$6))-1),"-",(H16/E16)^(1/($H$6-$E$6))-1) -> 0.068211484 | J16: =+J13-J15 -> 1060.948 | K16: =+K13-K15 -> 1263.407 | L16: =+L13-L15 -> 1512.0455 | M16: =+M13-M15 -> 1778.8771 | N16: =+N13-N15 -> 2006.8402 | O16: =+IF(ISERROR((N16/H16)^(1/($N$6-$H$6))-1),"-",(N16/H16)^(1/($N$6-$H$6))-1) -> 0.17685296
B17: % margin | E17: =+IF(ISERROR(E16/E7),0,E16/E7) -> 0.16164737 | F17: =+IF(ISERROR(F16/F7),0,F16/F7) -> 0.14394069 | G17: =+IF(ISERROR(G16/G7),0,G16/G7) -> 0.16059853 | H17: =+IF(ISERROR(H16/H7),0,H16/H7) -> 0.16568387 | J17: =+IF(ISERROR(J16/J7),0,J16/J7) -> 0.169 | K17: =+IF(ISERROR(K16/K7),0,K16/K7) -> 0.175 | L17: =+IF(ISERROR(L16/L7),0,L16/L7) -> 0.187 | M17: =+IF(ISERROR(M16/M7),0,M16/M7) -> 0.2 | N17: =+IF(ISERROR(N16/N7),0,N16/N7) -> 0.207
B18: Taxes | E18: =+E16*E40 -> 181.02219 | F18: =+F16*F40 -> 168.25981 | G18: =+G16*G40 -> 172.95352 | H18: =+H16*H40 -> 215.138 | J18: =+J16*J40 -> 256.74942 | K18: =+K16*K40 -> 305.7445 | L18: =+L16*L40 -> 365.91501 | M18: =+M16*M40 -> 430.48825 | N18: =+N16*N40 -> 485.65532
B19: EBIAT | E19: =+E16-E18 -> 548.31781 | F19: =+F16-F18 -> 480.39019 | G19: =+G16-G18 -> 546.78648 | H19: =+H16-H18 -> 673.862 | I19: =+IF(ISERROR((H19/E19)^(1/($H$6-$E$6))-1),"-",(H19/E19)^(1/($H$6-$E$6))-1) -> 0.071139917 | J19: =+J16-J18 -> 804.19858 | K19: =+K16-K18 -> 957.66251 | L19: =+L16-L18 -> 1146.1305 | M19: =+M16-M18 -> 1348.3888 | N19: =+N16-N18 -> 1521.1848 | O19: =+IF(ISERROR((N19/H19)^(1/($N$6-$H$6))-1),"-",(N19/H19)^(1/($N$6-$H$6))-1) -> 0.17685296
B21: Plus: Depreciation & Amortization | E21: =E15 -> 184.49 | F21: =F15 -> 207.33 | G21: =G15 -> 225.5 | H21: =H15 -> 296.14 | J21: =J15 -> 351.55673 | K21: =K15 -> 397.07077 | L21: =L15 -> 428.54766 | M21: =M15 -> 444.71927 | N21: =N15 -> 465.35424
B22: Less: Capital Expenditures | E22: -410.68 | F22: -380.58 | G22: -571.69 | H22: -558.21 | J22: =-(J7*J39) -> -596.39089 | K22: =-(K7*K39) -> -649.75218 | L22: =-(L7*L39) -> -646.86439 | M22: =-(M7*M39) -> -622.60697 | N22: =-(N7*N39) -> -630.1672
B23: Less: Increase in Net Working Capital | F23: =NWC!D25 -> -333.51 | G23: =NWC!E25 -> 99.24 | H23: =NWC!F25 -> -280.51 | J23: =NWC!H25 -> -275.24411 | K23: =NWC!I25 -> -197.30348 | L23: =NWC!J25 -> -88.935942 | M23: =NWC!K25 -> -54.850556 | N23: =NWC!L25 -> -41.899622
B25: Unlevered Free Cash Flow | F25: =+F19+SUM(F21:F23) -> -26.36981 | G25: =+G19+SUM(G21:G23) -> 299.83648 | H25: =+H19+SUM(H21:H23) -> 131.282 | J25: =+J19+SUM(J21:J23) -> 284.12031 | K25: =+K19+SUM(K21:K23) -> 507.67763 | L25: =+L19+SUM(L21:L23) -> 838.87782 | M25: =+M19+SUM(M21:M23) -> 1115.6506 | N25: =+N19+SUM(N21:N23) -> 1314.4723
B26: WACC | E26: =WACC!D26 -> 0.10254788
B27: Discount Period | J27: =IF($D$5="Y",J6-$H$6-0.5,J6-$H$6) -> 1 | K27: =IF($D$5="Y",K6-$H$6-0.5,K6-$H$6) -> 2 | L27: =IF($D$5="Y",L6-$H$6-0.5,L6-$H$6) -> 3 | M27: =IF($D$5="Y",M6-$H$6-0.5,M6-$H$6) -> 4 | N27: =IF($D$5="Y",N6-$H$6-0.5,N6-$H$6) -> 5
B28: Discount Factor | J28: =1/((1+$E$26)^(J27)) -> 0.90699009 | K28: =1/((1+$E$26)^(K27)) -> 0.82263102 | L28: =1/((1+$E$26)^(L27)) -> 0.74611818 | M28: =1/((1+$E$26)^(M27)) -> 0.6767218 | N28: =1/((1+$E$26)^(N27)) -> 0.61377996
B29: Present Value of Free Cash Flow | J29: =+J25*J28 -> 257.69431 | K29: =+K25*K28 -> 417.63137 | L29: =+L25*L28 -> 625.902 | M29: =+M25*M28 -> 754.98505 | N29: =+N25*N28 -> 806.79674
B34: Assumptions
B35: Sales (% growth) | E35: NA | F35: =+IF(ISERROR(F7/E7-1),0,F7/E7-1) -> -0.001230075 | G35: =+IF(ISERROR(G7/F7-1),0,G7/F7-1) -> -0.0054944445 | H35: =+IF(ISERROR(H7/G7-1),0,H7/G7-1) -> 0.19725724 | J35: ='A1'!F9 -> 0.17 | K35: ='A1'!G9 -> 0.15 | L35: ='A1'!H9 -> 0.12 | M35: ='A1'!I9 -> 0.1 | N35: ='A1'!J9 -> 0.09
B36: COGS (% sales) | E36: =+IF(ISERROR(E9/E7),0,E9/E7) -> 0.51137432 | F36: =+IF(ISERROR(F9/F7),0,F9/F7) -> 0.44853175 | G36: =+IF(ISERROR(G9/G7),0,G9/G7) -> 0.38506251 | H36: =+IF(ISERROR(H9/H7),0,H9/H7) -> 0.34957619 | J36: ='A1'!F16 -> 0.345 | K36: ='A1'!G16 -> 0.34 | L36: ='A1'!H16 -> 0.335 | M36: ='A1'!I16 -> 0.33 | N36: ='A1'!J16 -> 0.328
B37: SG&A (% sales) | E37: =+IF(ISERROR(E12/E7),0,E12/E7) -> 0.28608885 | F37: =+IF(ISERROR(F12/F7),0,F12/F7) -> 0.36151936 | G37: =+IF(ISERROR(G12/G7),0,G12/G7) -> 0.40402222 | H37: =+IF(ISERROR(H12/H7),0,H12/H7) -> 0.42954801 | J37: ='A1'!F23 -> 0.43 | K37: ='A1'!G23 -> 0.43 | L37: ='A1'!H23 -> 0.425 | M37: ='A1'!I23 -> 0.42 | N37: ='A1'!J23 -> 0.417
B38: Depreciation & Amortization (% sales) | E38: =+IF(ISERROR(E15/E7),0,E15/E7) -> 0.040889466 | F38: =+IF(ISERROR(F15/F7),0,F15/F7) -> 0.046008206 | G38: =+IF(ISERROR(G15/G7),0,G15/G7) -> 0.050316739 | H38: =+IF(ISERROR(H15/H7),0,H15/H7) -> 0.055191925 | J38: ='A1'!F30 -> 0.056 | K38: ='A1'!G30 -> 0.055 | L38: ='A1'!H30 -> 0.053 | M38: ='A1'!I30 -> 0.05 | N38: ='A1'!J30 -> 0.048
B39: Capital Expenditures (% sales) | E39: =+IF(ISERROR(-E22/E7),0,-E22/E7) -> 0.091021117 | F39: =+IF(ISERROR(-F22/F7),0,-F22/F7) -> 0.084453784 | G39: =+IF(ISERROR(-G22/G7),0,-G22/G7) -> 0.12756353 | H39: =+IF(ISERROR(-H22/H7),0,-H22/H7) -> 0.10403419 | J39: ='A1'!F38 -> 0.095 | K39: ='A1'!G38 -> 0.09 | L39: ='A1'!H38 -> 0.08 | M39: ='A1'!I38 -> 0.07 | N39: ='A1'!J38 -> 0.065
B40: Tax Rate | E40: 0.2482 | F40: 0.2594 | G40: 0.2403 | H40: 0.242 | J40: =H40 -> 0.242 | K40: =J40 -> 0.242 | L40: =K40 -> 0.242 | M40: =L40 -> 0.242 | N40: =M40 -> 0.242
B41: Working Capital (% sales) | E41: =NWC!C23 -> 0.28053246 | F41: =NWC!D23 -> 0.35488653 | G41: =NWC!E23 -> 0.33470338 | H41: =NWC!F23 -> 0.33183739 | J41: =NWC!H23 -> 0.32746575 | K41: =NWC!I23 -> 0.31208219 | L41: =NWC!J23 -> 0.28964384 | M41: =NWC!K23 -> 0.26947945 | N41: =NWC!L23 -> 0.25155068
B46: Enterprise Value | G46: Implied Equity Value and Share Price | L46: Implied Perpetuity Growth Rate
B47: Cumulative Present Value of FCF | E47: =+SUM(J29:N29) -> 2863.0095 | G47: Enterprise Value | J47: =+E57 -> 21071.61 | L47: ="Terminal Year Free Cash Flow ("&N6&"E)" -> Terminal Year Free Cash Flow (2031E) | O47: =+N25 -> 1314.4723
G48: Less: Net Financial Obligations (Financial Obligations - Investments) | J48: =1512.04-0.84 -> 1511.2 | L48: WACC | O48: =+E26 -> 0.10254788
B49: Terminal Value | G49: Less: Preferred Securities | J49: 0 | L49: =+B49 -> Terminal Value | O49: =+E52 -> 29666.333
B50: ="Terminal Year EBITDA ("&N6&"E)" -> Terminal Year EBITDA (2031E) | E50: =+N13 -> 2472.1944 | G50: Less: Noncontrolling Interest | J50: 0
...

Sheet NWC
A1: =+DCF!A1 -> 0
A2: Granules India Limited: Working Capital Projections
A3: (Rs. in crore)
C5: Historical Period | H5: Projection Period
C6: =+DCF!E6 -> 2023 | D6: =+DCF!F6 -> 2024 | E6: =+DCF!G6 -> 2025 | F6: =+DCF!H6 -> 2026 | H6: =+DCF!J6 -> 2027 | I6: =+DCF!K6 -> 2028 | J6: =+DCF!L6 -> 2029 | K6: =+DCF!M6 -> 2030 | L6: =+DCF!N6 -> 2031
B8: Sales | C8: =+DCF!E7 -> 4511.92 | D8: =+DCF!F7 -> 4506.37 | E8: =+DCF!G7 -> 4481.61 | F8: =+DCF!H7 -> 5365.64 | H8: =+DCF!J7 -> 6277.7988 | I8: =+DCF!K7 -> 7219.4686 | J8: =+DCF!L7 -> 8085.8049 | K8: =+DCF!M7 -> 8894.3853 | L8: =+DCF!N7 -> 9694.88
B9: Cost of Goods Sold | C9: =+DCF!E9 -> 2307.28 | D9: =+DCF!F9 -> 2021.25 | E9: =+DCF!G9 -> 1725.7 | F9: =+DCF!H9 -> 1875.7 | H9: =+DCF!J9 -> 2165.8406 | I9: =+DCF!K9 -> 2454.6193 | J9: =+DCF!L9 -> 2708.7446 | K9: =+DCF!M9 -> 2935.1472 | L9: =+DCF!N9 -> 3179.9206
B11: Current Assets
B12: Accounts Receivable | C12: 948.54 | D12: 985.83 | E12: 942.22 | F12: 909.37 | H12: =+H8/365*H28 -> 1083.5653 | I12: =+I8/365*I28 -> 1226.3207 | J12: =+J8/365*J28 -> 1329.1734 | K12: =+K8/365*K28 -> 1413.3544 | L12: =+L8/365*L28 -> 1487.4336
B13: Inventories | C13: 1149.41 | D13: 1300.55 | E13: 1342.82 | F13: 1673.03 | H13: =+H9/365*H29 -> 1898.8191 | I13: =+I9/365*I29 -> 2084.7452 | J13: =+J9/365*J29 -> 2189.2594 | K13: =+K9/365*K29 -> 2251.6197 | L13: =+L9/365*L29 -> 2308.7095
B14: Advances and other current assets | C14: 163.41 | D14: 232.28 | E14: 234.07 | F14: 236.2 | H14: =+H8*H30 -> 282.50095 | I14: =+I8*I30 -> 324.87609 | J14: =+J8*J30 -> 347.68961 | K14: =+K8*K30 -> 373.56418 | L14: =+L8*L30 -> 387.7952
B15: Total Current Assets | C15: =SUM(C12:C14) -> 2261.36 | D15: =SUM(D12:D14) -> 2518.66 | E15: =SUM(E12:E14) -> 2519.11 | F15: =SUM(F12:F14) -> 2818.6 | H15: =SUM(H12:H14) -> 3264.8854 | I15: =SUM(I12:I14) -> 3635.942 | J15: =SUM(J12:J14) -> 3866.1224 | K15: =SUM(K12:K14) -> 4038.5383 | L15: =SUM(L12:L14) -> 4183.9384
B17: Current Liabilities
B18: Accounts Payable | C18: 782.13 | D18: 749.53 | E18: 726.07 | F18: 672.8 | H18: =+H9/365*H31 -> 801.06433 | I18: =+I9/365*I31 -> 928.04786 | J18: =+J9/365*J31 -> 1038.9705 | K18: =+K9/365*K31 -> 1125.8099 | L18: =+L9/365*L31 -> 1202.2714
B19: Other Current Liabilities | C19: 213.49 | D19: 169.88 | E19: 293.03 | F19: 365.28 | H19: =+H8*H32 -> 408.05692 | I19: =+I8*I32 -> 454.82652 | J19: =+J8*J32 -> 485.14829 | K19: =+K8*K32 -> 515.87435 | L19: =+L8*L32 -> 542.91328
B20: Total Current Liabilities | C20: =SUM(C18:C19) -> 995.62 | D20: =SUM(D18:D19) -> 919.41 | E20: =SUM(E18:E19) -> 1019.1 | F20: =SUM(F18:F19) -> 1038.08 | H20: =SUM(H18:H19) -> 1209.1212 | I20: =SUM(I18:I19) -> 1382.8744 | J20: =SUM(J18:J19) -> 1524.1188 | K20: =SUM(K18:K19) -> 1641.6842 | L20: =SUM(L18:L19) -> 1745.1846
B22: Net Working Capital | C22: =+C15-C20 -> 1265.74 | D22: =+D15-D20 -> 1599.25 | E22: =+E15-E20 -> 1500.01 | F22: =+F15-F20 -> 1780.52 | H22: =+H15-H20 -> 2055.7641 | I22: =+I15-I20 -> 2253.0676 | J22: =+J15-J20 -> 2342.0035 | K22: =+K15-K20 -> 2396.8541 | L22: =+L15-L20 -> 2438.7537
B23: % sales | C23: =+IF(ISERROR(C22/C8),0,C22/C8) -> 0.28053246 | D23: =+IF(ISERROR(D22/D8),0,D22/D8) -> 0.35488653 | E23: =+IF(ISERROR(E22/E8),0,E22/E8) -> 0.33470338 | F23: =+IF(ISERROR(F22/F8),0,F22/F8) -> 0.33183739 | H23: =+IF(ISERROR(H22/H8),0,H22/H8) -> 0.32746575 | I23: =+IF(ISERROR(I22/I8),0,I22/I8) -> 0.31208219 | J23: =+IF(ISERROR(J22/J8),0,J22/J8) -> 0.28964384 | K23: =+IF(ISERROR(K22/K8),0,K22/K8) -> 0.26947945 | L23: =+IF(ISERROR(L22/L8),0,L22/L8) -> 0.25155068
B25: (Increase) / Decrease in NWC | D25: =+C22-D22 -> -333.51 | E25: =+D22-E22 -> 99.24 | F25: =+E22-F22 -> -280.51 | H25: =+F22-H22 -> -275.24411 | I25: =+H22-I22 -> -197.30348 | J25: =+I22-J22 -> -88.935942 | K25: =+J22-K22 -> -54.850556 | L25: =+K22-L22 -> -41.899622
B27: Assumptions
B28: Days Sales Outstanding | C28: =+IF(ISERROR(C12/C8*365),0,C12/C8*365) -> 76.733874 | D28: =+IF(ISERROR(D12/D8*365),0,D12/D8*365) -> 79.848736 | E28: =+IF(ISERROR(E12/E8*365),0,E12/E8*365) -> 76.738114 | F28: =E28 -> 76.738114 | H28: ='A2'!F9 -> 63 | I28: ='A2'!G9 -> 62 | J28: ='A2'!H9 -> 60 | K28: ='A2'!I9 -> 58 | L28: ='A2'!J9 -> 56
B29: Days Inventory Held | C29: =+IF(ISERROR(C13/C9*365),0,C13/C9*365) -> 181.83084 | D29: =+IF(ISERROR(D13/D9*365),0,D13/D9*365) -> 234.85504 | E29: =+IF(ISERROR(E13/E9*365),0,E13/E9*365) -> 284.01767 | F29: =E29 -> 284.01767 | H29: ='A2'!F16 -> 320 | I29: ='A2'!G16 -> 310 | J29: ='A2'!H16 -> 295 | K29: ='A2'!I16 -> 280 | L29: ='A2'!J16 -> 265
B30: Advanvces and Other CA (% of sales) | C30: =+IF(ISERROR(C14/C8),0,C14/C8) -> 0.036217397 | D30: =+IF(ISERROR(D14/D8),0,D14/D8) -> 0.051544813 | E30: =+IF(ISERROR(E14/E8),0,E14/E8) -> 0.052228998 | F30: =E30 -> 0.052228998 | H30: ='A2'!F23 -> 0.045 | I30: ='A2'!G23 -> 0.045 | J30: ='A2'!H23 -> 0.043 | K30: ='A2'!I23 -> 0.042 | L30: ='A2'!J23 -> 0.04
B31: Days Payable Outstanding | C31: =+IF(ISERROR(C18/C9*365),0,C18/C9*365) -> 123.729 | D31: =+IF(ISERROR(D18/D9*365),0,D18/D9*365) -> 135.35112 | E31: =+IF(ISERROR(E18/E9*365),0,E18/E9*365) -> 153.56988 | F31: =E31 -> 153.56988 | H31: ='A2'!F31 -> 135 | I31: ='A2'!G31 -> 138 | J31: ='A2'!H31 -> 140 | K31: ='A2'!I31 -> 140 | L31: ='A2'!J31 -> 138
B32: Other Current Liabilities (% of sales) | C32: =+IF(ISERROR(C19/C8),0,C19/C8) -> 0.047316885 | D32: =+IF(ISERROR(D19/D8),0,D19/D8) -> 0.037697748 | E32: =+IF(ISERROR(E19/E8),0,E19/E8) -> 0.065384984 | F32: =E32 -> 0.065384984 | H32: ='A2'!F38 -> 0.065 | I32: ='A2'!G38 -> 0.063 | J32: ='A2'!H38 -> 0.06 | K32: ='A2'!I38 -> 0.058 | L32: ='A2'!J38 -> 0.056

Sheet WACC
A1: =+DCF!A1 -> 0
A2: Granules India Limited: Weighted Average Cost of Capital Analysis
A3: (Rs. in crore)
B6: WACC Calculation | F6: Comparable Companies Unlevered Beta
B7: Target Capital Structure | G7: Predicted | H7: Market | I7: Market | J7: Debt/ | K7: Marginal | L7: Unlevered
B8: Debt-to-Total Capitalization | D8: 0.0685 | F8: Company | G8: Levered Beta(3) | H8: Value of Debt | I8: Value of Equity | J8: Equity | K8: Tax Rate | L8: Beta
B9: Equity-to-Total Capitalization | D9: =1-D8 -> 0.9315 | F9: Strides Pharma | G9: 0.5708 | H9: 1757.99 | I9: 9061.5 | J9: =+IF(ISERROR(H9/I9),0,H9/I9) -> 0.19400651 | K9: =$D$14 -> 0.2522 | L9: =+G9/(1+(J9)*(1-K9)) -> 0.4984813
B10: Memo: Book-value Debt/(Debt+Equity) | D10: =1512.04/(1512.04+5085) -> 0.22919976 | F10: FDC | G10: 0.4282 | H10: 21.17 | I10: 5673.93 | J10: =+IF(ISERROR(H10/I10),0,H10/I10) -> 0.0037311 | K10: =$D$14 -> 0.2522 | L10: =+G10/(1+(J10)*(1-K10)) -> 0.4270086
F11: Orchid Pharma | G11: 1.0266 | H11: 174.61 | I11: 5819.34 | J11: =+IF(ISERROR(H11/I11),0,H11/I11) -> 0.030005121 | K11: =$D$14 -> 0.2522 | L11: =+G11/(1+(J11)*(1-K11)) -> 1.0040708
B12: Cost of Debt | F12: RPG LifeScience. | G12: 0.7832 | H12: 20 | I12: 4295.93 | J12: =+IF(ISERROR(H12/I12),0,H12/I12) -> 0.0046555693 | K12: =$D$14 -> 0.2522 | L12: =+G12/(1+(J12)*(1-K12)) -> 0.7804828
B13: Cost of Debt | D13: 0.07387 | F13: Unichem Labs. | G13: 0.6236 | H13: 500.15 | I13: 3737.49 | J13: =+IF(ISERROR(H13/I13),0,H13/I13) -> 0.13381976 | K13: =$D$14 -> 0.2522 | L13: =+G13/(1+(J13)*(1-K13)) -> 0.5668728
B14: Tax Rate | D14: 0.2522
B15: After-tax Cost of Debt | D15: =+D13*(1-D14) -> 0.055239986 | F15: Mean | G15: =AVERAGE(G9:G14) -> 0.68648 | J15: =AVERAGE(J9:J14) -> 0.073243611 | L15: =AVERAGE(L9:L13) -> 0.65538327
F16: Median | G16: =MEDIAN(G9:G14) -> 0.6236 | J16: =MEDIAN(J9:J14) -> 0.030005121 | L16: =MEDIAN(L9:L12) -> 0.63948205
B18: Cost of Equity | F18: ValueCo Relevered Beta
B19: Risk-free Rate(1) | D19: 0.067771 | I19: Mean | J19: Target | K19: Target
B20: Market Risk Premium(2) | D20: 0.055329 | I20: Unlevered | J20: Debt/ | K20: Marginal | L20: Relevered
B21: Levered Beta | D21: =L22 -> 0.69142358 | I21: Beta | J21: Equity | K21: Tax Rate | L21: Beta
F22: Relevered Beta | I22: =L15 -> 0.65538327 | J22: =D8/D9 -> 0.073537305 | K22: =D14 -> 0.2522 | L22: =+I22*(1+(J22)*(1-K22)) -> 0.69142358
B23: Cost of Equity | D23: =+D19+(D21*D20) -> 0.10602678
I24: Adjusted Regression levered beta | L24: 0.99
I25: Domodaran Industry levered beta | L25: 0.98
B26: WACC | D26: =(D8*D15)+(D9*D23) -> 0.10254788
B28: (1) 10 year Indian government bond | F28: WACC Sensitivity Analysis
B29: (2) 10 year Indian government bond minus BSE 10 years return | H29: Pre-tax Cost of Debt
B30: (3) Levered beta directly taken from capitaline on 15-07-2026 | F30: Debt-to-Total Capitalization | G30: =+D26 -> 0.10254788 | H30: =I30-0.005 -> 0.06387 | I30: =J30-0.005 -> 0.06887 | J30: =D13 -> 0.07387 | K30: =J30+0.005 -> 0.07887 | L30: =K30+0.005 -> 0.08387
G31: =G32-0.02 -> 0.0285 | H31: =$G31*H$30*(1-$D$14)+(1-$G31)*$D$23-$D$26 -> 0.0018183486 | I31: =$G31*I$30*(1-$D$14)+(1-$G31)*$D$23-$D$26 -> 0.0019249101 | J31: =$G31*J$30*(1-$D$14)+(1-$G31)*$D$23-$D$26 -> 0.0020314716 | K31: =$G31*K$30*(1-$D$14)+(1-$G31)*$D$23-$D$26 -> 0.0021380331 | L31: =$G31*L$30*(1-$D$14)+(1-$G31)*$D$23-$D$26 -> 0.0022445946
G32: =G33-0.02 -> 0.0485 | H32: =$G32*H$30*(1-$D$14)+(1-$G32)*$D$23-$D$26 -> 0.00065305278 | I32: =$G32*I$30*(1-$D$14)+(1-$G32)*$D$23-$D$26 -> 0.00083439428 | J32: =$G32*J$30*(1-$D$14)+(1-$G32)*$D$23-$D$26 -> 0.0010157358 | K32: =$G32*K$30*(1-$D$14)+(1-$G32)*$D$23-$D$26 -> 0.0011970773 | L32: =$G32*L$30*(1-$D$14)+(1-$G32)*$D$23-$D$26 -> 0.0013784188
G33: =D8 -> 0.0685 | H33: =$G33*H$30*(1-$D$14)+(1-$G33)*$D$23-$D$26 -> -0.000512243 | I33: =$G33*I$30*(1-$D$14)+(1-$G33)*$D$23-$D$26 -> -0.0002561215 | J33: =$G33*J$30*(1-$D$14)+(1-$G33)*$D$23-$D$26 -> 0 | K33: =$G33*K$30*(1-$D$14)+(1-$G33)*$D$23-$D$26 -> 0.0002561215 | L33: =$G33*L$30*(1-$D$14)+(1-$G33)*$D$23-$D$26 -> 0.000512243
G34: =G33+0.02 -> 0.0885 | H34: =$G34*H$30*(1-$D$14)+(1-$G34)*$D$23-$D$26 -> -0.0016775388 | I34: =$G34*I$30*(1-$D$14)+(1-$G34)*$D$23-$D$26 -> -0.0013466373 | J34: =$G34*J$30*(1-$D$14)+(1-$G34)*$D$23-$D$26 -> -0.0010157358 | K34: =$G34*K$30*(1-$D$14)+(1-$G34)*$D$23-$D$26 -> -0.00068483428 | L34: =$G34*L$30*(1-$D$14)+(1-$G34)*$D$23-$D$26 -> -0.00035393278
G35: =G34+0.02 -> 0.1085 | H35: =$G35*H$30*(1-$D$14)+(1-$G35)*$D$23-$D$26 -> -0.0028428346 | I35: =$G35*I$30*(1-$D$14)+(1-$G35)*$D$23-$D$26 -> -0.0024371531 | J35: =$G35*J$30*(1-$D$14)+(1-$G35)*$D$23-$D$26 -> -0.0020314716 | K35: =$G35*K$30*(1-$D$14)+(1-$G35)*$D$23-$D$26 -> -0.0016257901 | L35: =$G35*L$30*(1-$D$14)+(1-$G35)*$D$23-$D$26 -> -0.0012201086

Sheet A1
A1: `
B2: Assumptions Page 1 - Income Statement and Cash Flow Statement
F4: Projection Period | Q4: What is base cae? Base (Analyst) Case assumption should preferably have three anchors: Historical evidence + External/industry evidence + Company/management evidence. FY26 Sales Growth Historical Average Industry expected Management expects Analyst conclusion Groups need them to prove that their conculed number is correct. Groups need to explain why their estimation is more reasonable than min or maxium number.
F5: 1 | G5: 2 | H5: 3 | I5: 4 | J5: 5
F6: 2027 | G6: 2028 | H6: 2029 | I6: 2030 | J6: 2031
B8: Income Statement Assumptions
B9: Sales (% growth) | F9: =CHOOSE(DCF!$D$4,F10,F11,F12,F13,F14) -> 0.17 | G9: =CHOOSE(DCF!$D$4,G10,G11,G12,G13,G14) -> 0.15 | H9: =CHOOSE(DCF!$D$4,H10,H11,H12,H13,H14) -> 0.12 | I9: =CHOOSE(DCF!$D$4,I10,I11,I12,I13,I14) -> 0.1 | J9: =CHOOSE(DCF!$D$4,J10,J11,J12,J13,J14) -> 0.09 | M9: Previous year | N9: =DCF!H35 -> 0.19725724
B10: Base | E10: 1 | F10: 0.17 | G10: 0.15 | H10: 0.12 | I10: 0.1 | J10: 0.09 | M10: Historical Average | N10: =AVERAGE(DCF!F35:H35) -> 0.063510905
B11: Management | E11: 2 | F11: 0.21 | G11: 0.18 | H11: 0.15 | I11: 0.12 | J11: 0.1 | M11: Industry average | N11: 0.09
B12: Upside | E12: 3 | F12: 0.23 | G12: 0.21 | H12: 0.18 | I12: 0.14 | J12: 0.12 | M12: Industry expectation | N12: 0.1
B13: Downside 1 | E13: 4 | F13: 0.14 | G13: 0.11 | H13: 0.09 | I13: 0.08 | J13: 0.07 | M13: Earnings call or MD&A (if avilable) | N13: 0.22
B14: Downside 2 | E14: 5 | F14: 0.12 | G14: 0.06 | H14: 0.05 | I14: 0.05 | J14: 0.05
B16: Cost of Goods Sold (% sales) | F16: =CHOOSE(DCF!$D$4,F17,F18,F19,F20,F21) -> 0.345 | G16: =CHOOSE(DCF!$D$4,G17,G18,G19,G20,G21) -> 0.34 | H16: =CHOOSE(DCF!$D$4,H17,H18,H19,H20,H21) -> 0.335 | I16: =CHOOSE(DCF!$D$4,I17,I18,I19,I20,I21) -> 0.33 | J16: =CHOOSE(DCF!$D$4,J17,J18,J19,J20,J21) -> 0.328 | M16: Previous year | N16: =DCF!H36 -> 0.34957619
B17: Base | E17: 1 | F17: 0.345 | G17: 0.34 | H17: 0.335 | I17: 0.33 | J17: 0.328 | M17: Historical Average | N17: =AVERAGE(DCF!E36:H36) -> 0.42363619
B18: Management | E18: 2 | F18: 0.335 | G18: 0.325 | H18: 0.315 | I18: 0.31 | J18: 0.305 | M18: Industry average | N18: 0.44
B19: Upside | E19: 3 | F19: 0.325 | G19: 0.31 | H19: 0.295 | I19: 0.29 | J19: 0.285 | M19: Earnings call or MD&A (if avilable) | N19: 0.344
B20: Downside 1 | E20: 4 | F20: 0.36 | G20: 0.36 | H20: 0.355 | I20: 0.355 | J20: 0.35
B21: Downside 2 | E21: 5 | F21: 0.38 | G21: 0.385 | H21: 0.38 | I21: 0.375 | J21: 0.37 | Q21: What is Management cae? What happens if management broadly delivers what it is communicating? Management Case = Management's story converted into numbers.
B23: SG&A (% sales) | F23: =CHOOSE(DCF!$D$4,F24,F25,F26,F27,F28) -> 0.43 | G23: =CHOOSE(DCF!$D$4,G24,G25,G26,G27,G28) -> 0.43 | H23: =CHOOSE(DCF!$D$4,H24,H25,H26,H27,H28) -> 0.425 | I23: =CHOOSE(DCF!$D$4,I24,I25,I26,I27,I28) -> 0.42 | J23: =CHOOSE(DCF!$D$4,J24,J25,J26,J27,J28) -> 0.417 | M23: Previous year | N23: =DCF!H37 -> 0.42954801
B24: Base | E24: 1 | F24: 0.43 | G24: 0.43 | H24: 0.425 | I24: 0.42 | J24: 0.417 | M24: Historical Average | N24: =AVERAGE(DCF!E37:H37) -> 0.37029461
B25: Management | E25: 2 | F25: 0.435 | G25: 0.425 | H25: 0.415 | I25: 0.41 | J25: 0.405 | M25: Industry average | N25: 0.38
B26: Upside | E26: 3 | F26: 0.435 | G26: 0.42 | H26: 0.405 | I26: 0.4 | J26: 0.395 | M26: Earnings call or MD&A (if avilable) | N26: 0.431
B27: Downside 1 | E27: 4 | F27: 0.45 | G27: 0.45 | H27: 0.45 | I27: 0.445 | J27: 0.445
B28: Downside 2 | E28: 5 | F28: 0.46 | G28: 0.465 | H28: 0.465 | I28: 0.465 | J28: 0.465
B30: Depreciation & Amortization (% sales) | F30: =CHOOSE(DCF!$D$4,F31,F32,F33,F34,F35) -> 0.056 | G30: =CHOOSE(DCF!$D$4,G31,G32,G33,G34,G35) -> 0.055 | H30: =CHOOSE(DCF!$D$4,H31,H32,H33,H34,H35) -> 0.053 | I30: =CHOOSE(DCF!$D$4,I31,I32,I33,I34,I35) -> 0.05 | J30: =CHOOSE(DCF!$D$4,J31,J32,J33,J34,J35) -> 0.048 | M30: Previous year | N30: =DCF!H38 -> 0.055191925 | Q30: What is upside cae? If all the positive findings of qualitative analysis (SWOT, PORTER 5, PORTER GENERIC, etc) will be activated than what will happen to specific deriver? Upside Case = Base case positive adjustments (Generally 1-2%)
B31: Base | E31: 1 | F31: 0.056 | G31: 0.055 | H31: 0.053 | I31: 0.05 | J31: 0.048 | M31: Historical Average | N31: =AVERAGE(DCF!E38:H38) -> 0.048101584
B32: Management | E32: 2 | F32: 0.057 | G32: 0.056 | H32: 0.053 | I32: 0.05 | J32: 0.047 | M32: Industry average | N32: 0.05
B33: Upside | E33: 3 | F33: 0.055 | G33: 0.052 | H33: 0.049 | I33: 0.046 | J33: 0.044 | M33: Earnings call or MD&A (if avilable) | N33: Not separately guided
B34: Downside 1 | E34: 4 | F34: 0.058 | G34: 0.058 | H34: 0.056 | I34: 0.054 | J34: 0.052
B35: Downside 2 | E35: 5 | F35: 0.06 | G35: 0.062 | H35: 0.06 | I35: 0.058 | J35: 0.056
B37: Cash Flow Statement Assumptions
B38: Capital Expenditures (% of sales) | F38: =CHOOSE(DCF!$D$4,F39,F40,F41,F42,F43) -> 0.095 | G38: =CHOOSE(DCF!$D$4,G39,G40,G41,G42,G43) -> 0.09 | H38: =CHOOSE(DCF!$D$4,H39,H40,H41,H42,H43) -> 0.08 | I38: =CHOOSE(DCF!$D$4,I39,I40,I41,I42,I43) -> 0.07 | J38: =CHOOSE(DCF!$D$4,J39,J40,J41,J42,J43) -> 0.065 | M38: Previous year | N38: =DCF!H39 -> 0.10403419 | Q38: What is downside1 cae? If all the negative findings of qualitative analysis (SWOT, PORTER 5, PORTER GENERIC, etc) will be activated (Moderate Stress) than what will happen to specific deriver? Downside1 Case = Base case negative adjustments (Generally 1-2%)
B39: Base | E39: 1 | F39: 0.095 | G39: 0.09 | H39: 0.08 | I39: 0.07 | J39: 0.065 | M39: Historical Average | N39: =AVERAGE(DCF!E39:H39) -> 0.10176816
B40: Management | E40: 2 | F40: 0.1 | G40: 0.095 | H40: 0.08 | I40: 0.065 | J40: 0.06 | M40: Industry average | N40: 0.08
B41: Upside | E41: 3 | F41: 0.09 | G41: 0.08 | H41: 0.07 | I41: 0.06 | J41: 0.055 | M41: Earnings call or MD&A (if avilable) | N41: 0.0956
B42: Downside 1 | E42: 4 | F42: 0.105 | G42: 0.105 | H42: 0.095 | I42: 0.085 | J42: 0.08
B43: Downside 2 | E43: 5 | F43: 0.11 | G43: 0.115 | H43: 0.105 | I43: 0.095 | J43: 0.09
Q46: What is downside2 cae? If all the negative findings of qualitative analysis (SWOT, PORTER 5, PORTER GENERIC, etc) will be activated (Severe Stress) than what will happen to specific deriver? Downside2 Case = Base case negative adjustments (Generally 3-4%)

Sheet A2
B2: Assumptions Page 2 - Balance Sheet
F4: Projection Period
F5: 1 | G5: 2 | H5: 3 | I5: 4 | J5: 5
F6: ='A1'!F6 -> 2027 | G6: ='A1'!G6 -> 2028 | H6: ='A1'!H6 -> 2029 | I6: ='A1'!I6 -> 2030 | J6: ='A1'!J6 -> 2031
B8: Current Assets
B9: Days Sales Outstanding (DSO) | F9: =CHOOSE(DCF!$D$4,F10,F11,F12,F13,F14) -> 63 | G9: =CHOOSE(DCF!$D$4,G10,G11,G12,G13,G14) -> 62 | H9: =CHOOSE(DCF!$D$4,H10,H11,H12,H13,H14) -> 60 | I9: =CHOOSE(DCF!$D$4,I10,I11,I12,I13,I14) -> 58 | J9: =CHOOSE(DCF!$D$4,J10,J11,J12,J13,J14) -> 56 | M9: Previous year | N9: =NWC!F28 -> 76.738114
B10: Base | E10: 1 | F10: 63 | G10: 62 | H10: 60 | I10: 58 | J10: 56 | M10: Historical Average | N10: =AVERAGE(NWC!C28:F28) -> 77.51471
B11: Management | E11: 2 | F11: 64 | G11: 63 | H11: 61 | I11: 59 | J11: 57 | M11: Industry average | N11: 65
B12: Upside | E12: 3 | F12: 55 | G12: 52 | H12: 50 | I12: 48 | J12: 47 | M12: Earnings call or MD&A (if avilable) | N12: Rises slightly (qualitative)
B13: Downside 1 | E13: 4 | F13: 65 | G13: 64 | H13: 62 | I13: 61 | J13: 60
B14: Downside 2 | E14: 5 | F14: 72 | G14: 72 | H14: 70 | I14: 68 | J14: 66
B16: Days Inventory Held (DIH) | F16: =CHOOSE(DCF!$D$4,F17,F18,F19,F20,F21) -> 320 | G16: =CHOOSE(DCF!$D$4,G17,G18,G19,G20,G21) -> 310 | H16: =CHOOSE(DCF!$D$4,H17,H18,H19,H20,H21) -> 295 | I16: =CHOOSE(DCF!$D$4,I17,I18,I19,I20,I21) -> 280 | J16: =CHOOSE(DCF!$D$4,J17,J18,J19,J20,J21) -> 265 | M16: Previous year | N16: =NWC!F29 -> 284.01767
B17: Base | E17: 1 | F17: 320 | G17: 310 | H17: 295 | I17: 280 | J17: 265 | M17: Historical Average | N17: =AVERAGE(NWC!C29:F29) -> 246.18031
B18: Management | E18: 2 | F18: 322 | G18: 312 | H18: 297 | I18: 282 | J18: 267 | M18: Industry average | N18: 150
B19: Upside | E19: 3 | F19: 285 | G19: 265 | H19: 250 | I19: 240 | J19: 230 | M19: Earnings call or MD&A (if avilable) | N19: Held deliberately elevated
B20: Downside 1 | E20: 4 | F20: 330 | G20: 325 | H20: 315 | I20: 305 | J20: 295
B21: Downside 2 | E21: 5 | F21: 350 | G21: 355 | H21: 345 | I21: 335 | J21: 325
B23: Advances and other current assets (% of sales) | F23: =CHOOSE(DCF!$D$4,F24,F25,F26,F27,F28) -> 0.045 | G23: =CHOOSE(DCF!$D$4,G24,G25,G26,G27,G28) -> 0.045 | H23: =CHOOSE(DCF!$D$4,H24,H25,H26,H27,H28) -> 0.043 | I23: =CHOOSE(DCF!$D$4,I24,I25,I26,I27,I28) -> 0.042 | J23: =CHOOSE(DCF!$D$4,J24,J25,J26,J27,J28) -> 0.04 | M23: Previous year | N23: =NWC!F30 -> 0.052228998
B24: Base | E24: 1 | F24: 0.045 | G24: 0.045 | H24: 0.043 | I24: 0.042 | J24: 0.04 | M24: Historical Average | N24: =AVERAGE(NWC!C30:F30) -> 0.048055052
B25: Management | E25: 2 | F25: 0.043 | G25: 0.042 | H25: 0.04 | I25: 0.039 | J25: 0.038 | M25: Industry average | N25: 0.04
B26: Upside | E26: 3 | F26: 0.04 | G26: 0.039 | H26: 0.037 | I26: 0.036 | J26: 0.035 | M26: Earnings call or MD&A (if avilable) | N26: Not guided
B27: Downside 1 | E27: 4 | F27: 0.05 | G27: 0.05 | H27: 0.048 | I27: 0.047 | J27: 0.046
B28: Downside 2 | E28: 5 | F28: 0.055 | G28: 0.055 | H28: 0.053 | I28: 0.052 | J28: 0.05
B30: Current Liabilities
B31: Days Payable Outstanding (DPO) | F31: =CHOOSE(DCF!$D$4,F32,F33,F34,F35,F36) -> 135 | G31: =CHOOSE(DCF!$D$4,G32,G33,G34,G35,G36) -> 138 | H31: =CHOOSE(DCF!$D$4,H32,H33,H34,H35,H36) -> 140 | I31: =CHOOSE(DCF!$D$4,I32,I33,I34,I35,I36) -> 140 | J31: =CHOOSE(DCF!$D$4,J32,J33,J34,J35,J36) -> 138 | M31: Previous year | N31: =NWC!F31 -> 153.56988
B32: Base | E32: 1 | F32: 135 | G32: 138 | H32: 140 | I32: 140 | J32: 138 | M32: Historical Average | N32: =AVERAGE(NWC!C31:F31) -> 141.55497
B33: Management | E33: 2 | F33: 140 | G33: 145 | H33: 148 | I33: 148 | J33: 145 | M33: Industry average | N33: 90
B34: Upside | E34: 3 | F34: 145 | G34: 150 | H34: 152 | I34: 152 | J34: 150 | M34: Earnings call or MD&A (if avilable) | N34: General comment only
B35: Downside 1 | E35: 4 | F35: 128 | G35: 128 | H35: 130 | I35: 130 | J35: 128
B36: Downside 2 | E36: 5 | F36: 120 | G36: 118 | H36: 120 | I36: 120 | J36: 118
B38: Other Current Liabilities (% of sales) | F38: =CHOOSE(DCF!$D$4,F39,F40,F41,F42,F43) -> 0.065 | G38: =CHOOSE(DCF!$D$4,G39,G40,G41,G42,G43) -> 0.063 | H38: =CHOOSE(DCF!$D$4,H39,H40,H41,H42,H43) -> 0.06 | I38: =CHOOSE(DCF!$D$4,I39,I40,I41,I42,I43) -> 0.058 | J38: =CHOOSE(DCF!$D$4,J39,J40,J41,J42,J43) -> 0.056 | M38: Previous year | N38: =NWC!F32 -> 0.065384984
B39: Base | E39: 1 | F39: 0.065 | G39: 0.063 | H39: 0.06 | I39: 0.058 | J39: 0.056 | M39: Historical Average | N39: =AVERAGE(NWC!C32:F32) -> 0.05394615
B40: Management | E40: 2 | F40: 0.06 | G40: 0.057 | H40: 0.054 | I40: 0.052 | J40: 0.05 | M40: Industry average | N40: 0.02
B41: Upside | E41: 3 | F41: 0.055 | G41: 0.052 | H41: 0.049 | I41: 0.047 | J41: 0.045 | M41: Earnings call or MD&A (if avilable) | N41: Not guided
B42: Downside 1 | E42: 4 | F42: 0.07 | G42: 0.072 | H42: 0.07 | I42: 0.068 | J42: 0.066
B43: Downside 2 | E43: 5 | F43: 0.075 | G43: 0.078 | H43: 0.076 | I43: 0.074 | J43: 0.072

Sheet Rights
A1: Copyright © 2009 by Joshua Rosenbaum and Joshua Pearl. All rights reserved.
A3: Published by John Wiley & Sons, Inc., Hoboken, New Jersey.
A4: Published simultaneously in Canada.
A6: No part of this publication may be reproduced, stored in a retrieval system, or transmitted in
A7: any form or by any means, electronic, mechanical, photocopying, recording, scanning, or
A8: otherwise, except as permitted under Section 107 or 108 of the 1976 United States Copyright
A9: Act, without either the prior written permission of the Publisher, or authorization through
A10: payment of the appropriate per-copy fee to the Copyright Clearance Center, Inc., 222
A11: Rosewood Drive, Danvers, MA 01923, (978) 750-8400, fax (978) 750-4470, or on the web
A12: at www.copyright.com. Requests to the Publisher for permission should be addressed to the
A13: Permissions Department, John Wiley & Sons, Inc., 111 River Street, Hoboken, NJ 07030,
A14: (201) 748-6011, fax (201) 748-6008, or online at http://www.wiley.com/go/permissions.
... A42: 10 9 8 7 6 5 4 3 2 1

Sheet Monte Carlo
A1: Granules India Limited: Monte Carlo Simulation of Intrinsic Value
A2: (Rs. in crore, except per-share data; 500 trials, present-year (FY27-31) DCF)
A4: Methodology: each trial draws two independent uniform random numbers and converts them to a symmetric triangular(0, 0.5, 1) weight:
A5: w1 (Operating Scenario weight) - interpolates Sales Growth, COGS%, SG&A%, D&A% and CapEx% linearly between the Downside 2 case (w1=0) and the Upside case (w1=1) built in the A1 sheet, for each forecast year FY27-31.
A6: w2 (Market/Discount-Rate weight) - interpolates WACC and the Exit Multiple linearly between the low and high ends of the sensitivity ranges already used on the DCF sheet.
A7: A triangular(0,0.5,1) shape is used (not uniform) so trials cluster around the Base case, matching how the case was built (three-anchor Base case, with Upside/Downside as deliberate stress scenarios rather than equally likely outcomes).
A8: Simplifications (for tractability, disclosed rather than hidden): (1) Net debt is held fixed at Rs562.14cr (J48-J51 on the DCF sheet) in every trial - financing risk is not separately randomized. (2) The change in Net Working Capital is approximated as (change in Sales) x the FY26 actual NWC-to-Sales ratio (33.2%), held constant across trials, rather than re-deriving DSO/DIH/DPO per trial. (3) Shares outstanding are held fixed at 24.78cr.
A9: Everything else (Sales, COGS, SG&A, EBITDA, D&A, CapEx, Tax, FCF, discounting, terminal value, Enterprise/Equity Value, Share Price) is computed fresh for every trial from the randomized drivers - this is a full re-run of the DCF logic per trial, not a shortcut sensitivity table.
A11: Simulation Results (Implied Share Price, Rs.)
A12: Mean | C12: =AVERAGE(TrialPrice) -> 724.39311
A13: Median | C13: =MEDIAN(TrialPrice) -> 708.09222
A14: Std. Deviation | C14: =STDEV(TrialPrice) -> 185.4125
A15: Minimum | C15: =MIN(TrialPrice) -> 352.94634
A16: 5th percentile | C16: =PERCENTILE(TrialPrice,0.05) -> 452.42765
A17: 25th percentile | C17: =PERCENTILE(TrialPrice,0.25) -> 583.6506
A18: 75th percentile | C18: =PERCENTILE(TrialPrice,0.75) -> 850.16146
A19: 95th percentile | C19: =PERCENTILE(TrialPrice,0.95) -> 1042.2078
A20: Maximum | C20: =MAX(TrialPrice) -> 1322.6717
A21: P(price < current market price ~Rs847) | C21: =COUNTIF(TrialPrice,"<847")/COUNT(TrialPrice) -> 0.74
A22: P(price < Downside 2 single-point estimate, Rs336) | C22: =COUNTIF(TrialPrice,"<336")/COUNT(TrialPrice) -> 0
A23: P(price > Upside single-point estimate, Rs1,335) | C23: =COUNTIF(TrialPrice,">1335")/COUNT(TrialPrice) -> 0
A26: Trial# | B26: u1 | C26: w1 (Op.) | D26: u2 | E26: w2 (Mkt.) | F26: Sales FY27 | G26: Sales FY28 | H26: Sales FY29 | I26: Sales FY30 | J26: Sales FY31 | K26: COGS% FY27 | L26: COGS% FY28 | M26: COGS% FY29 | N26: COGS% FY30 | O26: COGS% FY31 | P26: SG&A% FY27 | Q26: SG&A% FY28 | R26: SG&A% FY29 | S26: SG&A% FY30 | T26: SG&A% FY31 | U26: EBITDA FY27 | V26: EBITDA FY28 | W26: EBITDA FY29 | X26: EBITDA FY30 | Y26: EBITDA FY31 | Z26: D&A FY27 | AA26: D&A FY28 | AB26: D&A FY29 | AC26: D&A FY30 | AD26: D&A FY31 | AE26: CapEx FY27 | AF26: CapEx FY28 | AG26: CapEx FY29 | AH26: CapEx FY30 | AI26: CapEx FY31 | AJ26: Tax FY27 | AK26: Tax FY28 | AL26: Tax FY29 | AM26: Tax FY30 | AN26: Tax FY31 | AO26: ΔNWC FY27 | AP26: ΔNWC FY28 | AQ26: ΔNWC FY29 | AR26: ΔNWC FY30 | AS26: ΔNWC FY31 | AT26: FCF FY27 | AU26: FCF FY28 | AV26: FCF FY29 | AW26: FCF FY30 | AX26: FCF FY31 | AY26: WACC | AZ26: Exit Mult. | BA26: PV of FCF | BB26: Terminal Value | BC26: PV of TV | BD26: Enterprise Value | BE26: Equity Value | BF26: Share Price
A27: 1 | B27: =RAND() -> 0.33647521 | C27: =IF(B27<0.5,SQRT(0.5*B27),1-SQRT(0.5*(1-B27))) -> 0.41016778 | D27: =RAND() -> 0.28332894 | E27: =IF(D27<0.5,SQRT(0.5*D27),1-SQRT(0.5*(1-D27))) -> 0.37638341 | F27: =DCF!$H$7*(1+('A1'!F14+$C27*('A1'!F12-'A1'!F14))) -> 6251.6062 | G27: =F27*(1+('A1'!G14+$C27*('A1'!G12-'A1'!G14))) -> 7011.3337 | H27: =G27*(1+('A1'!H14+$C27*('A1'!H12-'A1'!H14))) -> 7735.7574 | I27: =H27*(1+('A1'!I14+$C27*('A1'!I12-'A1'!I14))) -> 8408.1115 | J27: =I27*(1+('A1'!J14+$C27*('A1'!J12-'A1'!J14))) -> 9069.9286 | K27: ='A1'!F21+$C27*('A1'!F19-'A1'!F21) -> 0.35744077 | L27: ='A1'!G21+$C27*('A1'!G19-'A1'!G21) -> 0.35423742 | M27: ='A1'!H21+$C27*('A1'!H19-'A1'!H21) -> 0.34513574 | N27: ='A1'!I21+$C27*('A1'!I19-'A1'!I21) -> 0.34013574 | O27: ='A1'!J21+$C27*('A1'!J19-'A1'!J21) -> 0.33513574 | P27: ='A1'!F28+$C27*('A1'!F26-'A1'!F28) -> 0.44974581 | Q27: ='A1'!G28+$C27*('A1'!G26-'A1'!G28) -> 0.44654245 | R27: ='A1'!H28+$C27*('A1'!H26-'A1'!H28) -> 0.44038993 | S27: ='A1'!I28+$C27*('A1'!I26-'A1'!I28) -> 0.43833909 | T27: ='A1'!J28+$C27*('A1'!J26-'A1'!J28) -> 0.43628826 | U27: =F27*(1-K27-P27) -> 1205.3936 | V27: =G27*(1-L27-Q27) -> 1396.7988 | W27: =H27*(1-M27-R27) -> 1659.1214 | X27: =I27*(1-N27-S27) -> 1862.6083 | Y27: =J27*(1-O27-T27) -> 2073.1681 | Z27: =F27*('A1'!F35+$C27*('A1'!F33-'A1'!F35)) -> 362.27533 | AA27: =G27*('A1'!G35+$C27*('A1'!G33-'A1'!G35)) -> 405.94446 | AB27: =H27*('A1'!H35+$C27*('A1'!H33-'A1'!H35)) -> 429.2429 | AC27: =I27*('A1'!I35+$C27*('A1'!I33-'A1'!I35)) -> 446.28563 | AD27: =J27*('A1'!J35+$C27*('A1'!J33-'A1'!J35)) -> 463.27369 | AE27: =F27*('A1'!F43+$C27*('A1'!F41-'A1'!F43)) -> 636.39253 | AF27: =G27*('A1'!G43+$C27*('A1'!G41-'A1'!G43)) -> 705.64956 | AG27: =H27*('A1'!H43+$C27*('A1'!H41-'A1'!H43)) -> 701.20098 | AH27: =I27*('A1'!I43+$C27*('A1'!I41-'A1'!I43)) -> 678.06482 | AI27: =J27*('A1'!J43+$C27*('A1'!J41-'A1'!J43)) -> 686.08684 | AJ27: =(U27-Z27)*DCF!$H$40 -> 204.03462 | AK27: =(V27-AA27)*DCF!$H$40 -> 239.78676 | AL27: =(W27-AB27)*DCF!$H$40 -> 297.63059 | AM27: =(X27-AC27)*DCF!$H$40 -> 342.75009 | AN27: =(Y27-AD27)*DCF!$H$40 -> 389.59444 | AO27: =(F27-DCF!$H$7)*DCF!$H$41 -> 293.99671 | AP27: =(G27-F27)*DCF!$H$41 -> 252.10599 | AQ27: =(H27-G27)*DCF!$H$41 -> 240.39087 | AR27: =(I27-H27)*DCF!$H$41 -> 223.11224 | AS27: =(J27-I27)*DCF!$H$41 -> 219.61567 | AT27: =(U27-Z27)*(1-DCF!$H$40)+Z27-AE27-AO27 -> 70.969722 | AU27: =(V27-AA27)*(1-DCF!$H$40)+AA27-AF27-AP27 -> 199.25652 | AV27: =(W27-AB27)*(1-DCF!$H$40)+AB27-AG27-AQ27 -> 419.89892 | AW27: =(X27-AC27)*(1-DCF!$H$40)+AC27-AH27-AR27 -> 618.68115 | AX27: =(Y27-AD27)*(1-DCF!$H$40)+AD27-AI27-AS27 -> 777.87111 | AY27: =0.0925+$E27*(0.1125-0.0925) -> 0.10002767 | AZ27: =10+$E27*(14-10) -> 11.505534 | BA27: =SUMPRODUCT(AT27:AX27,(1+$AY27)^(-{1,2,3,4,5})) -> 1450.0964 | BB27: =Y27*$AZ27 -> 23852.905 | BC27: =BB27*(1+$AY27)^(-5) -> 14808.915 | BD27: =BA27+BC27 -> 16259.011 | BE27: =BD27-(DCF!$J$48-DCF!$J$51) -> 15696.871 | BF27: =BE27/DCF!$J$55 -> 633.45707
A28: 2 | B28: =RAND() -> 0.37503102 | C28: =IF(B28<0.5,SQRT(0.5*B28),1-SQRT(0.5*(1-B28))) -> 0.43303061 | D28: =RAND() -> 0.093130366 | E28: =IF(D28<0.5,SQRT(0.5*D28),1-SQRT(0.5*(1-D28))) -> 0.21578967 | F28: =DCF!$H$7*(1+('A1'!F14+$C28*('A1'!F12-'A1'!F14))) -> 6265.1003 | G28: =F28*(1+('A1'!G14+$C28*('A1'!G12-'A1'!G14))) -> 7047.9533 | H28: =G28*(1+('A1'!H14+$C28*('A1'!H12-'A1'!H14))) -> 7797.1084 | I28: =H28*(1+('A1'!I14+$C28*('A1'!I12-'A1'!I14))) -> 8490.8386 | J28: =I28*(1+('A1'!J14+$C28*('A1'!J12-'A1'!J14))) -> 9172.756 | K28: ='A1'!F21+$C28*('A1'!F19-'A1'!F21) -> 0.35618332 | L28: ='A1'!G21+$C28*('A1'!G19-'A1'!G21) -> 0.3525227 | M28: ='A1'!H21+$C28*('A1'!H19-'A1'!H21) -> 0.3431924 | N28: ='A1'!I21+$C28*('A1'!I19-'A1'!I21) -> 0.3381924 | O28: ='A1'!J21+$C28*('A1'!J19-'A1'!J21) -> 0.3331924 | P28: ='A1'!F28+$C28*('A1'!F26-'A1'!F28) -> 0.44917423 | Q28: ='A1'!G28+$C28*('A1'!G26-'A1'!G28) -> 0.44551362 | R28: ='A1'!H28+$C28*('A1'!H26-'A1'!H28) -> 0.43901816 | S28: ='A1'!I28+$C28*('A1'!I26-'A1'!I28) -> 0.43685301 | T28: ='A1'!J28+$C28*('A1'!J26-'A1'!J28) -> 0.43468786 | U28: =F28*(1-K28-P28) -> 1219.4545 | V28: =G28*(1-L28-Q28) -> 1423.4305 | W28: =H28*(1-M28-R28) -> 1698.1278 | X28: =I28*(1-N28-S28) -> 1910.0531 | Y28: =J28*(1-O28-T28) -> 2129.1778 | Z28: =F28*('A1'!F35+$C28*('A1'!F33-'A1'!F35)) -> 362.34112 | AA28: =G28*('A1'!G35+$C28*('A1'!G33-'A1'!G35)) -> 406.45331 | AB28: =H28*('A1'!H35+$C28*('A1'!H33-'A1'!H35)) -> 430.68625 | AC28: =I28*('A1'!I35+$C28*('A1'!I33-'A1'!I35)) -> 448.34712 | AD28: =J28*('A1'!J35+$C28*('A1'!J33-'A1'!J35)) -> 466.00933 | AE28: =F28*('A1'!F43+$C28*('A1'!F41-'A1'!F43)) -> 634.90143 | AF28: =G28*('A1'!G43+$C28*('A1'!G41-'A1'!G43)) -> 703.69535 | AG28: =H28*('A1'!H43+$C28*('A1'!H41-'A1'!H43)) -> 700.52285 | AH28: =I28*('A1'!I43+$C28*('A1'!I41-'A1'!I43)) -> 677.94191 | AI28: =J28*('A1'!J43+$C28*('A1'!J41-'A1'!J43)) -> 686.5251 | AJ28: =(U28-Z28)*DCF!$H$40 -> 207.42143 | AK28: =(V28-AA28)*DCF!$H$40 -> 246.10849 | AL28: =(W28-AB28)*DCF!$H$40 -> 306.72087 | AM28: =(X28-AC28)*DCF!$H$40 -> 353.73285 | AN28: =(Y28-AD28)*DCF!$H$40 -> 402.48677 | AO28: =(F28-DCF!$H$7)*DCF!$H$41 -> 298.47456 | AP28: =(G28-F28)*DCF!$H$41 -> 259.77992 | AQ28: =(H28-G28)*DCF!$H$41 -> 248.59765 | AR28: =(I28-H28)*DCF!$H$41 -> 230.20563 | AS28: =(J28-I28)*DCF!$H$41 -> 226.28571 | AT28: =(U28-Z28)*(1-DCF!$H$40)+Z28-AE28-AO28 -> 78.657043 | AU28: =(V28-AA28)*(1-DCF!$H$40)+AA28-AF28-AP28 -> 213.84679 | AV28: =(W28-AB28)*(1-DCF!$H$40)+AB28-AG28-AQ28 -> 442.28649 | AW28: =(X28-AC28)*(1-DCF!$H$40)+AC28-AH28-AR28 -> 648.17273 | AX28: =(Y28-AD28)*(1-DCF!$H$40)+AD28-AI28-AS28 -> 813.88021 | AY28: =0.0925+$E28*(0.1125-0.0925) -> 0.096815793 | AZ28: =10+$E28*(14-10) -> 10.863159 | BA28: =SUMPRODUCT(AT28:AX28,(1+$AY28)^(-{1,2,3,4,5})) -> 1545.2814 | BB28: =Y28*$AZ28 -> 23129.596 | BC28: =BB28*(1+$AY28)^(-5) -> 14571.343 | BD28: =BA28+BC28 -> 16116.624 | BE28: =BD28-(DCF!$J$48-DCF!$J$51) -> 15554.484 | BF28: =BE28/DCF!$J$55 -> 627.71095
A29: 3 | B29: =RAND() -> 0.4961647 | C29: =IF(B29<0.5,SQRT(0.5*B29),1-SQRT(0.5*(1-B29))) -> 0.49807866 | D29: =RAND() -> 0.0083040635 | E29: =IF(D29<0.5,SQRT(0.5*D29),1-SQRT(0.5*(1-D29))) -> 0.064436261 | F29: =DCF!$H$7*(1+('A1'!F14+$C29*('A1'!F12-'A1'!F14))) -> 6303.493 | G29: =F29*(1+('A1'!G14+$C29*('A1'!G12-'A1'!G14))) -> 7152.6479 | H29: =G29*(1+('A1'!H14+$C29*('A1'!H12-'A1'!H14))) -> 7973.4158 | I29: =H29*(1+('A1'!I14+$C29*('A1'!I12-'A1'!I14))) -> 8729.5116 | J29: =I29*(1+('A1'!J14+$C29*('A1'!J12-'A1'!J14))) -> 9470.346 | K29: ='A1'!F21+$C29*('A1'!F19-'A1'!F21) -> 0.35260567 | L29: ='A1'!G21+$C29*('A1'!G19-'A1'!G21) -> 0.3476441 | M29: ='A1'!H21+$C29*('A1'!H19-'A1'!H21) -> 0.33766331 | N29: ='A1'!I21+$C29*('A1'!I19-'A1'!I21) -> 0.33266331 | O29: ='A1'!J21+$C29*('A1'!J19-'A1'!J21) -> 0.32766331 | P29: ='A1'!F28+$C29*('A1'!F26-'A1'!F28) -> 0.44754803 | Q29: ='A1'!G28+$C29*('A1'!G26-'A1'!G28) -> 0.44258646 | R29: ='A1'!H28+$C29*('A1'!H26-'A1'!H28) -> 0.43511528 | S29: ='A1'!I28+$C29*('A1'!I26-'A1'!I28) -> 0.43262489 | T29: ='A1'!J28+$C29*('A1'!J26-'A1'!J28) -> 0.43013449 | U29: =F29*(1-K29-P29) -> 1259.7297 | V29: =G29*(1-L29-Q29) -> 1500.4069 | W29: =H29*(1-M29-R29) -> 1811.7308 | X29: =I29*(1-N29-S29) -> 2048.9194 | Y29: =J29*(1-O29-T29) -> 2293.7386 | Z29: =F29*('A1'!F35+$C29*('A1'!F33-'A1'!F35)) -> 362.5114 | AA29: =G29*('A1'!G35+$C29*('A1'!G33-'A1'!G35)) -> 407.83836 | AB29: =H29*('A1'!H35+$C29*('A1'!H33-'A1'!H35)) -> 434.71968 | AC29: =I29*('A1'!I35+$C29*('A1'!I33-'A1'!I35)) -> 454.13587 | AD29: =J29*('A1'!J35+$C29*('A1'!J33-'A1'!J35)) -> 473.73565 | AE29: =F29*('A1'!F43+$C29*('A1'!F41-'A1'!F43)) -> 630.59152 | AF29: =G29*('A1'!G43+$C29*('A1'!G41-'A1'!G43)) -> 697.86416 | AG29: =H29*('A1'!H43+$C29*('A1'!H41-'A1'!H43)) -> 698.21007 | AH29: =I29*('A1'!I43+$C29*('A1'!I41-'A1'!I43)) -> 677.12418 | AI29: =J29*('A1'!J43+$C29*('A1'!J41-'A1'!J43)) -> 687.23693 | AJ29: =(U29-Z29)*DCF!$H$40 -> 217.12683 | AK29: =(V29-AA29)*DCF!$H$40 -> 264.4016 | AL29: =(W29-AB29)*DCF!$H$40 -> 333.23668 | AM29: =(X29-AC29)*DCF!$H$40 -> 385.93761 | AN29: =(Y29-AD29)*DCF!$H$40 -> 440.4407 | AO29: =(F29-DCF!$H$7)*DCF!$H$41 -> 311.21469 | AP29: =(G29-F29)*DCF!$H$41 -> 281.78134 | AQ29: =(H29-G29)*DCF!$H$41 -> 272.3615 | AR29: =(I29-H29)*DCF!$H$41 -> 250.90084 | AS29: =(J29-I29)*DCF!$H$41 -> 245.83656 | AT29: =(U29-Z29)*(1-DCF!$H$40)+Z29-AE29-AO29 -> 100.79666 | AU29: =(V29-AA29)*(1-DCF!$H$40)+AA29-AF29-AP29 -> 256.35983 | AV29: =(W29-AB29)*(1-DCF!$H$40)+AB29-AG29-AQ29 -> 507.9225 | AW29: =(X29-AC29)*(1-DCF!$H$40)+AC29-AH29-AR29 -> 734.95674 | AX29: =(Y29-AD29)*(1-DCF!$H$40)+AD29-AI29-AS29 -> 920.22436 | AY29: =0.0925+$E29*(0.1125-0.0925) -> 0.093788725 | AZ29: =10+$E29*(14-10) -> 10.257745 | BA29: =SUMPRODUCT(AT29:AX29,(1+$AY29)^(-{1,2,3,4,5})) -> 1795.8633 | BB29: =Y29*$AZ29 -> 23528.585 | BC29: =BB29*(1+$AY29)^(-5) -> 15028.949 | BD29: =BA29+BC29 -> 16824.812 | BE29: =BD29-(DCF!$J$48-DCF!$J$51) -> 16262.672 | BF29: =BE29/DCF!$J$55 -> 656.29032
A30: 4 | B30: =RAND() -> 0.87237964 | C30: =IF(B30<0.5,SQRT(0.5*B30),1-SQRT(0.5*(1-B30))) -> 0.74739323 | D30: =RAND() -> 0.39538373 | E30: =IF(D30<0.5,SQRT(0.5*D30),1-SQRT(0.5*(1-D30))) -> 0.44462553 | F30: =DCF!$H$7*(1+('A1'!F14+$C30*('A1'!F12-'A1'!F14))) -> 6450.6435 | G30: =F30*(1+('A1'!G14+$C30*('A1'!G12-'A1'!G14))) -> 7560.8572 | H30: =G30*(1+('A1'!H14+$C30*('A1'!H12-'A1'!H14))) -> 8673.5215 | I30: =H30*(1+('A1'!I14+$C30*('A1'!I12-'A1'!I14))) -> 9690.6254 | J30: =I30*(1+('A1'!J14+$C30*('A1'!J12-'A1'!J14))) -> 10682.146 | K30: ='A1'!F21+$C30*('A1'!F19-'A1'!F21) -> 0.33889337 | L30: ='A1'!G21+$C30*('A1'!G19-'A1'!G21) -> 0.32894551 | M30: ='A1'!H21+$C30*('A1'!H19-'A1'!H21) -> 0.31647158 | N30: ='A1'!I21+$C30*('A1'!I19-'A1'!I21) -> 0.31147158 | O30: ='A1'!J21+$C30*('A1'!J19-'A1'!J21) -> 0.30647158 | P30: ='A1'!F28+$C30*('A1'!F26-'A1'!F28) -> 0.44131517 | Q30: ='A1'!G28+$C30*('A1'!G26-'A1'!G28) -> 0.4313673 | R30: ='A1'!H28+$C30*('A1'!H26-'A1'!H28) -> 0.42015641 | S30: ='A1'!I28+$C30*('A1'!I26-'A1'!I28) -> 0.41641944 | T30: ='A1'!J28+$C30*('A1'!J26-'A1'!J28) -> 0.41268247 | U30: =F30*(1-K30-P30) -> 1417.7964 | V30: =G30*(1-L30-Q30) -> 1812.2406 | W30: =H30*(1-M30-R30) -> 2284.3629 | X30: =I30*(1-N30-S30) -> 2636.9062 | Y30: =J30*(1-O30-T30) -> 3000.0375 | Z30: =F30*('A1'!F35+$C30*('A1'!F33-'A1'!F35)) -> 362.93278 | AA30: =G30*('A1'!G35+$C30*('A1'!G33-'A1'!G35)) -> 412.26381 | AB30: =H30*('A1'!H35+$C30*('A1'!H33-'A1'!H35)) -> 449.10344 | AC30: =I30*('A1'!I35+$C30*('A1'!I33-'A1'!I35)) -> 475.14378 | AD30: =J30*('A1'!J35+$C30*('A1'!J33-'A1'!J35)) -> 502.39502 | AE30: =F30*('A1'!F43+$C30*('A1'!F41-'A1'!F43)) -> 613.14744 | AF30: =G30*('A1'!G43+$C30*('A1'!G41-'A1'!G43)) -> 671.71591 | AG30: =H30*('A1'!H43+$C30*('A1'!H41-'A1'!H43)) -> 683.83116 | AH30: =I30*('A1'!I43+$C30*('A1'!I41-'A1'!I43)) -> 667.11463 | AI30: =J30*('A1'!J43+$C30*('A1'!J41-'A1'!J43)) -> 681.96142 | AJ30: =(U30-Z30)*DCF!$H$40 -> 255.27699 | AK30: =(V30-AA30)*DCF!$H$40 -> 338.79439 | AL30: =(W30-AB30)*DCF!$H$40 -> 444.13278 | AM30: =(X30-AC30)*DCF!$H$40 -> 523.14651 | AN30: =(Y30-AD30)*DCF!$H$40 -> 604.42948 | AO30: =(F30-DCF!$H$7)*DCF!$H$41 -> 360.04475 | AP30: =(G30-F30)*DCF!$H$41 -> 368.41043 | AQ30: =(H30-G30)*DCF!$H$41 -> 369.2236 | AR30: =(I30-H30)*DCF!$H$41 -> 337.5131 | AS30: =(J30-I30)*DCF!$H$41 -> 329.02368 | AT30: =(U30-Z30)*(1-DCF!$H$40)+Z30-AE30-AO30 -> 189.32718 | AU30: =(V30-AA30)*(1-DCF!$H$40)+AA30-AF30-AP30 -> 433.31989 | AV30: =(W30-AB30)*(1-DCF!$H$40)+AB30-AG30-AQ30 -> 787.17532 | AW30: =(X30-AC30)*(1-DCF!$H$40)+AC30-AH30-AR30 -> 1109.132 | AX30: =(Y30-AD30)*(1-DCF!$H$40)+AD30-AI30-AS30 -> 1384.6229 | AY30: =0.0925+$E30*(0.1125-0.0925) -> 0.10139251 | AZ30: =10+$E30*(14-10) -> 11.778502 | BA30: =SUMPRODUCT(AT30:AX30,(1+$AY30)^(-{1,2,3,4,5})) -> 2726.3336 | BB30: =Y30*$AZ30 -> 35335.948 | BC30: =BB30*(1+$AY30)^(-5) -> 21802.493 | BD30: =BA30+BC30 -> 24528.826 | BE30: =BD30-(DCF!$J$48-DCF!$J$51) -> 23966.686 | BF30: =BE30/DCF!$J$55 -> 967.19065
A31: 5 | B31: =RAND() -> 0.16906025 | C31: =IF(B31<0.5,SQRT(0.5*B31),1-SQRT(0.5*(1-B31))) -> 0.29074065 | D31: =RAND() -> 0.11844042 | E31: =IF(D31<0.5,SQRT(0.5*D31),1-SQRT(0.5*(1-D31))) -> 0.24335203 | F31: =DCF!$H$7*(1+('A1'!F14+$C31*('A1'!F12-'A1'!F14))) -> 6181.1179 | G31: =F31*(1+('A1'!G14+$C31*('A1'!G12-'A1'!G14))) -> 6821.5503 | H31: =G31*(1+('A1'!H14+$C31*('A1'!H12-'A1'!H14))) -> 7420.457 | I31: =H31*(1+('A1'!I14+$C31*('A1'!I12-'A1'!I14))) -> 7985.6485 | J31: =I31*(1+('A1'!J14+$C31*('A1'!J12-'A1'!J14))) -> 8547.4536 | K31: ='A1'!F21+$C31*('A1'!F19-'A1'!F21) -> 0.36400926 | L31: ='A1'!G21+$C31*('A1'!G19-'A1'!G21) -> 0.36319445 | M31: ='A1'!H21+$C31*('A1'!H19-'A1'!H21) -> 0.35528704 | N31: ='A1'!I21+$C31*('A1'!I19-'A1'!I21) -> 0.35028704 | O31: ='A1'!J21+$C31*('A1'!J19-'A1'!J21) -> 0.34528704 | P31: ='A1'!F28+$C31*('A1'!F26-'A1'!F28) -> 0.45273148 | Q31: ='A1'!G28+$C31*('A1'!G26-'A1'!G28) -> 0.45191667 | R31: ='A1'!H28+$C31*('A1'!H26-'A1'!H28) -> 0.44755556 | S31: ='A1'!I28+$C31*('A1'!I26-'A1'!I28) -> 0.44610186 | T31: ='A1'!J28+$C31*('A1'!J26-'A1'!J28) -> 0.44464815 | U31: =F31*(1-K31-P31) -> 1132.747 | V31: =G31*(1-L31-Q31) -> 1261.2288 | W31: =H31*(1-M31-R31) -> 1462.998 | X31: =I31*(1-N31-S31) -> 1625.9666 | Y31: =J31*(1-O31-T31) -> 1795.5191 | Z31: =F31*('A1'!F35+$C31*('A1'!F33-'A1'!F35)) -> 361.88156 | AA31: =G31*('A1'!G35+$C31*('A1'!G33-'A1'!G35)) -> 403.1031 | AB31: =H31*('A1'!H35+$C31*('A1'!H33-'A1'!H35)) -> 421.49571 | AC31: =I31*('A1'!I35+$C31*('A1'!I33-'A1'!I35)) -> 435.30658 | AD31: =J31*('A1'!J35+$C31*('A1'!J33-'A1'!J35)) -> 448.83629 | AE31: =F31*('A1'!F43+$C31*('A1'!F41-'A1'!F43)) -> 643.98092 | AF31: =G31*('A1'!G43+$C31*('A1'!G41-'A1'!G43)) -> 715.06271 | AG31: =H31*('A1'!H43+$C31*('A1'!H41-'A1'!H43)) -> 703.63799 | AH31: =I31*('A1'!I43+$C31*('A1'!I41-'A1'!I43)) -> 677.37526 | AI31: =J31*('A1'!J43+$C31*('A1'!J41-'A1'!J43)) -> 682.29259 | AJ31: =(U31-Z31)*DCF!$H$40 -> 186.54945 | AK31: =(V31-AA31)*DCF!$H$40 -> 207.66641 | AL31: =(W31-AB31)*DCF!$H$40 -> 252.04355 | AM31: =(X31-AC31)*DCF!$H$40 -> 288.13974 | AN31: =(Y31-AD31)*DCF!$H$40 -> 325.89725 | AO31: =(F31-DCF!$H$7)*DCF!$H$41 -> 270.60605 | AP31: =(G31-F31)*DCF!$H$41 -> 212.51942 | AQ31: =(H31-G31)*DCF!$H$41 -> 198.73966 | AR31: =(I31-H31)*DCF!$H$41 -> 187.55165 | AS31: =(J31-I31)*DCF!$H$41 -> 186.42794 | AT31: =(U31-Z31)*(1-DCF!$H$40)+Z31-AE31-AO31 -> 31.610621 | AU31: =(V31-AA31)*(1-DCF!$H$40)+AA31-AF31-AP31 -> 125.98023 | AV31: =(W31-AB31)*(1-DCF!$H$40)+AB31-AG31-AQ31 -> 308.57677 | AW31: =(X31-AC31)*(1-DCF!$H$40)+AC31-AH31-AR31 -> 472.9 | AX31: =(Y31-AD31)*(1-DCF!$H$40)+AD31-AI31-AS31 -> 600.90135 | AY31: =0.0925+$E31*(0.1125-0.0925) -> 0.097367041 | AZ31: =10+$E31*(14-10) -> 10.973408 | BA31: =SUMPRODUCT(AT31:AX31,(1+$AY31)^(-{1,2,3,4,5})) -> 1070.6513 | BB31: =Y31*$AZ31 -> 19702.964 | BC31: =BB31*(1+$AY31)^(-5) -> 12381.464 | BD31: =BA31+BC31 -> 13452.116 | BE31: =BD31-(DCF!$J$48-DCF!$J$51) -> 12889.976 | BF31: =BE31/DCF!$J$55 -> 520.18304
A32: 6 | B32: =RAND() -> 0.5092443 | C32: =IF(B32<0.5,SQRT(0.5*B32),1-SQRT(0.5*(1-B32))) -> 0.50464371 | D32: =RAND() -> 0.069103085 | E32: =IF(D32<0.5,SQRT(0.5*D32),1-SQRT(0.5*(1-D32))) -> 0.18588045 | F32: =DCF!$H$7*(1+('A1'!F14+$C32*('A1'!F12-'A1'!F14))) -> 6307.3678 | G32: =F32*(1+('A1'!G14+$C32*('A1'!G12-'A1'!G14))) -> 7163.2559 | H32: =G32*(1+('A1'!H14+$C32*('A1'!H12-'A1'!H14))) -> 7991.3547 | I32: =H32*(1+('A1'!I14+$C32*('A1'!I12-'A1'!I14))) -> 8753.8732 | J32: =I32*(1+('A1'!J14+$C32*('A1'!J12-'A1'!J14))) -> 9500.798 | K32: ='A1'!F21+$C32*('A1'!F19-'A1'!F21) -> 0.3522446 | L32: ='A1'!G21+$C32*('A1'!G19-'A1'!G21) -> 0.34715172 | M32: ='A1'!H21+$C32*('A1'!H19-'A1'!H21) -> 0.33710528 | N32: ='A1'!I21+$C32*('A1'!I19-'A1'!I21) -> 0.33210528 | O32: ='A1'!J21+$C32*('A1'!J19-'A1'!J21) -> 0.32710528 | P32: ='A1'!F28+$C32*('A1'!F26-'A1'!F28) -> 0.44738391 | Q32: ='A1'!G28+$C32*('A1'!G26-'A1'!G28) -> 0.44229103 | R32: ='A1'!H28+$C32*('A1'!H26-'A1'!H28) -> 0.43472138 | S32: ='A1'!I28+$C32*('A1'!I26-'A1'!I28) -> 0.43219816 | T32: ='A1'!J28+$C32*('A1'!J26-'A1'!J28) -> 0.42967494 | U32: =F32*(1-K32-P32) -> 1263.8167 | V32: =G32*(1-L32-Q32) -> 1508.2754 | W32: =H32*(1-M32-R32) -> 1823.4141 | X32: =I32*(1-N32-S32) -> 2063.2578 | Y32: =J32*(1-O32-T32) -> 2310.782 | Z32: =F32*('A1'!F35+$C32*('A1'!F33-'A1'!F35)) -> 362.5272 | AA32: =G32*('A1'!G35+$C32*('A1'!G33-'A1'!G35)) -> 407.97295 | AB32: =H32*('A1'!H35+$C32*('A1'!H33-'A1'!H35)) -> 435.12062 | AC32: =I32*('A1'!I35+$C32*('A1'!I33-'A1'!I35)) -> 454.7136 | AD32: =J32*('A1'!J35+$C32*('A1'!J33-'A1'!J35)) -> 474.51047 | AE32: =F32*('A1'!F43+$C32*('A1'!F41-'A1'!F43)) -> 630.15099 | AF32: =G32*('A1'!G43+$C32*('A1'!G41-'A1'!G43)) -> 697.25321 | AG32: =H32*('A1'!H43+$C32*('A1'!H41-'A1'!H43)) -> 697.9447 | AH32: =I32*('A1'!I43+$C32*('A1'!I41-'A1'!I43)) -> 677.00241 | AI32: =J32*('A1'!J43+$C32*('A1'!J41-'A1'!J43)) -> 687.26369 | AJ32: =(U32-Z32)*DCF!$H$40 -> 218.11207 | AK32: =(V32-AA32)*DCF!$H$40 -> 266.2732 | AL32: =(W32-AB32)*DCF!$H$40 -> 335.96702 | AM32: =(X32-AC32)*DCF!$H$40 -> 389.26769 | AN32: =(Y32-AD32)*DCF!$H$40 -> 444.3777 | AO32: =(F32-DCF!$H$7)*DCF!$H$41 -> 312.5005 | AP32: =(G32-F32)*DCF!$H$41 -> 284.01568 | AQ32: =(H32-G32)*DCF!$H$41 -> 274.79414 | AR32: =(I32-H32)*DCF!$H$41 -> 253.03217 | AS32: =(J32-I32)*DCF!$H$41 -> 247.85757 | AT32: =(U32-Z32)*(1-DCF!$H$40)+Z32-AE32-AO32 -> 103.05317 | AU32: =(V32-AA32)*(1-DCF!$H$40)+AA32-AF32-AP32 -> 260.73335 | AV32: =(W32-AB32)*(1-DCF!$H$40)+AB32-AG32-AQ32 -> 514.70823 | AW32: =(X32-AC32)*(1-DCF!$H$40)+AC32-AH32-AR32 -> 743.95551 | AX32: =(Y32-AD32)*(1-DCF!$H$40)+AD32-AI32-AS32 -> 931.283 | AY32: =0.0925+$E32*(0.1125-0.0925) -> 0.096217609 | AZ32: =10+$E32*(14-10) -> 10.743522 | BA32: =SUMPRODUCT(AT32:AX32,(1+$AY32)^(-{1,2,3,4,5})) -> 1805.1839 | BB32: =Y32*$AZ32 -> 24825.936 | BC32: =BB32*(1+$AY32)^(-5) -> 15682.734 | BD32: =BA32+BC32 -> 17487.918 | BE32: =BD32-(DCF!$J$48-DCF!$J$51) -> 16925.778 | BF32: =BE32/DCF!$J$55 -> 683.05036
A33: 7 | B33: =RAND() -> 0.38739373 | C33: =IF(B33<0.5,SQRT(0.5*B33),1-SQRT(0.5*(1-B33))) -> 0.44011006 | D33: =RAND() -> 0.66336205 | E33: =IF(D33<0.5,SQRT(0.5*D33),1-SQRT(0.5*(1-D33))) -> 0.58973304 | F33: =DCF!$H$7*(1+('A1'!F14+$C33*('A1'!F12-'A1'!F14))) -> 6269.2787 | G33: =F33*(1+('A1'!G14+$C33*('A1'!G12-'A1'!G14))) -> 7059.3114 | H33: =G33*(1+('A1'!H14+$C33*('A1'!H12-'A1'!H14))) -> 7816.1705 | I33: =H33*(1+('A1'!I14+$C33*('A1'!I12-'A1'!I14))) -> 8516.5768 | J33: =I33*(1+('A1'!J14+$C33*('A1'!J12-'A1'!J14))) -> 9204.7819 | K33: ='A1'!F21+$C33*('A1'!F19-'A1'!F21) -> 0.35579395 | L33: ='A1'!G21+$C33*('A1'!G19-'A1'!G21) -> 0.35199175 | M33: ='A1'!H21+$C33*('A1'!H19-'A1'!H21) -> 0.34259064 | N33: ='A1'!I21+$C33*('A1'!I19-'A1'!I21) -> 0.33759064 | O33: ='A1'!J21+$C33*('A1'!J19-'A1'!J21) -> 0.33259064 | P33: ='A1'!F28+$C33*('A1'!F26-'A1'!F28) -> 0.44899725 | Q33: ='A1'!G28+$C33*('A1'!G26-'A1'!G28) -> 0.44519505 | R33: ='A1'!H28+$C33*('A1'!H26-'A1'!H28) -> 0.4385934 | S33: ='A1'!I28+$C33*('A1'!I26-'A1'!I28) -> 0.43639285 | T33: ='A1'!J28+$C33*('A1'!J26-'A1'!J28) -> 0.4341923 | U33: =F33*(1-K33-P33) -> 1223.8184 | V33: =G33*(1-L33-Q33) -> 1431.7216 | W33: =H33*(1-M33-R33) -> 1710.3029 | X33: =I33*(1-N33-S33) -> 1924.887 | Y33: =J33*(1-O33-T33) -> 2146.7122 | Z33: =F33*('A1'!F35+$C33*('A1'!F33-'A1'!F35)) -> 362.36086 | AA33: =G33*('A1'!G35+$C33*('A1'!G33-'A1'!G35)) -> 406.60856 | AB33: =H33*('A1'!H35+$C33*('A1'!H33-'A1'!H35)) -> 431.1305 | AC33: =I33*('A1'!I35+$C33*('A1'!I33-'A1'!I35)) -> 448.98268 | AD33: =J33*('A1'!J35+$C33*('A1'!J33-'A1'!J35)) -> 466.85438 | AE33: =F33*('A1'!F43+$C33*('A1'!F41-'A1'!F43)) -> 634.43721 | AF33: =G33*('A1'!G43+$C33*('A1'!G41-'A1'!G43)) -> 703.08022 | AG33: =H33*('A1'!H43+$C33*('A1'!H41-'A1'!H43)) -> 700.29877 | AH33: =I33*('A1'!I43+$C33*('A1'!I41-'A1'!I43)) -> 677.88671 | AI33: =J33*('A1'!J43+$C33*('A1'!J41-'A1'!J43)) -> 686.64127 | AJ33: =(U33-Z33)*DCF!$H$40 -> 208.47273 | AK33: =(V33-AA33)*DCF!$H$40 -> 248.07735 | AL33: =(W33-AB33)*DCF!$H$40 -> 309.55971 | AM33: =(X33-AC33)*DCF!$H$40 -> 357.16884 | AN33: =(Y33-AD33)*DCF!$H$40 -> 406.52558 | AO33: =(F33-DCF!$H$7)*DCF!$H$41 -> 299.86112 | AP33: =(G33-F33)*DCF!$H$41 -> 262.16237 | AQ33: =(H33-G33)*DCF!$H$41 -> 251.15418 | AR33: =(I33-H33)*DCF!$H$41 -> 232.421 | AS33: =(J33-I33)*DCF!$H$41 -> 228.37216 | AT33: =(U33-Z33)*(1-DCF!$H$40)+Z33-AE33-AO33 -> 81.047351 | AU33: =(V33-AA33)*(1-DCF!$H$40)+AA33-AF33-AP33 -> 218.40164 | AV33: =(W33-AB33)*(1-DCF!$H$40)+AB33-AG33-AQ33 -> 449.29019 | AW33: =(X33-AC33)*(1-DCF!$H$40)+AC33-AH33-AR33 -> 657.41042 | AX33: =(Y33-AD33)*(1-DCF!$H$40)+AD33-AI33-AS33 -> 825.17315 | AY33: =0.0925+$E33*(0.1125-0.0925) -> 0.10429466 | AZ33: =10+$E33*(14-10) -> 12.358932 | BA33: =SUMPRODUCT(AT33:AX33,(1+$AY33)^(-{1,2,3,4,5})) -> 1530.6816 | BB33: =Y33*$AZ33 -> 26531.07 | BC33: =BB33*(1+$AY33)^(-5) -> 16155.853 | BD33: =BA33+BC33 -> 17686.535 | BE33: =BD33-(DCF!$J$48-DCF!$J$51) -> 17124.395 | BF33: =BE33/DCF!$J$55 -> 691.06569
