Workbook

Sheet Economic & Industry Inputs
A1: Economic & Industry Inputs
A3: 1. Macroeconomic Assumptions
A4: Parameter | B4: Value | C4: Source
A5: Risk-Free Rate (India 10Y G-Sec yield) | B5: 0.069 | C5: https://www.worldgovernmentbonds.com
A6: Expected Market Return (Nifty 50, long-run) | B6: 0.13 | C6: http://niftyindices.com/market-data/return-profile
A7: Equity Risk Premium (ERP) | B7: =B6-B5 -> 0.061
A8: Corporate Tax Rate (domestic co., concessional 115BAA + cess) | B8: 0.2517 | C8: 25.17% concessional corporate tax rate for Indian domestic companies opting u/s 115BAA,
A9: CPI Inflation (YoY, latest) | B9: 0.0445 | C9: All-India CPI inflation, July 2026 = 4.45%
A10: Long-Term Nominal GDP Growth (proxy for terminal growth 'g') | B10: 0.06 | C10: Conservative, FY 2025-26 is estimated at 7.6%
A11: RBI Repo Rate | B11: 0.0525 | C11: RBI policy repo rate, Aug 2026 review = 5.25%.
A13: 2. Economy & Industry Analysis
A14: Sector | B14: Analysis Category | C14: Factors
A15: Automobile (M&M) | B15: Macroeconomic Factors | C15: GDP growth outlook, interest rate cycle, rural income & monsoon (affects tractor demand), fuel prices, consumer sentiment.
B16: Industry-Specific Dynamics | C16: domestic PV/SUV/tractor demand outlook, EV transition & charging infrastructure, competitive intensity, export markets, input costs (steel/commodities).
B17: Regulatory & Competitive Landscape | C17: emission norms (BS-VII/CAFE), EV policy & PLI incentives, import duties, safety regulations (Bharat NCAP), key competitors' market share moves.
A18: IT Services (Coforge) | B18: Macroeconomic Factors | C18: US/Europe GDP growth & recession risk, USD/INR currency movement, global IT/BPM spending cycle.
B19: Industry-Specific Dynamics | C19: deal pipeline & TCV wins, GenAI disruption to services pricing, attrition & wage inflation, vertical mix (BFSI, travel, insurance, manufacturing).
B20: Regulatory & Competitive Landscape | C20: US H-1B visa policy & immigration rules, data privacy regulations (GDPR), outsourcing/onshoring policy shifts, competitor pricing pressure.
A21: Pharmaceuticals (Dr. Reddy's) | B21: Macroeconomic Factors | C21: US healthcare policy direction, USD/INR currency, global generic drug pricing trends.
B22: Industry-Specific Dynamics | C22: US generics pricing pressure & Para IV pipeline, biosimilars launches, domestic formulations growth, R&D pipeline & new launches.
B23: Regulatory & Competitive Landscape | C23: USFDA plant inspections/warning letters, patent cliffs & exclusivity windows, India drug pricing controls (NPPA/DPCO).
A24: FMCG (Britannia) | B24: Macroeconomic Factors | C24: rural vs urban demand recovery, CPI/input cost inflation, consumer disposable income trends.
B25: Industry-Specific Dynamics | C25: premiumisation trend, rural distribution reach, private-label competition, e-commerce/quick-commerce channel shift, input costs (wheat/palm oil/sugar).
B26: Regulatory & Competitive Landscape | C26: GST rate changes on packaged food, FSSAI labeling norms, agri-commodity price regulation, competitor pricing moves.

Sheet M&M
A1: Mahindra & Mahindra Ltd. (Automobile) - Fundamental Analysis & Valuation
A3: 1. Company Background
A4: Sector / Industry | B4: Automobile - Passenger Vehicles, SUVs, Commercial Vehicles, Tractors & Farm Equipment
A5: Business Description | B5: Mahindra & Mahindra Limited operates in nine segments. The automotive segment includes sales of automobiles, spare parts and related services. Farm equipment segment includes sales of tractors, spare parts and related services; information technology (IT) services, which consists of services rendered for IT and telecom; financial services includes services relating to financing, leasing and hire purchase of automobiles and tractors; steel trading and processing includes trading and processing of steel; infrastructure includes operating of commercial complexes, project management and development; hospitality segment includes sale of timeshare; Systech segment includes automotive components and other related products and services, and its others segment includes logistics, after-market, two wheelers and investment.
A6: Year of Incorporation | B6: 1945 (incorporated as Mahindra & Mohammed; renamed Mahindra & Mahindra in 1948)
A7: Stock Exchange / Ticker (NSE/BSE) | B7: NSE: M&M | BSE: 500520
A8: Key Business Segments / Products | B8: Automotive (SUVs, LCVs, EVs), Farm Equipment (tractors), Financial Services (Mahindra Finance), IT Services (Tech Mahindra), plus Growth Gems (real estate, hospitality, logistics, aerospace)
A9: Promoter Holding % (latest) | B9: 18.4% (as of Jun 2026)
A11: 2. Historical Financial Analysis (₹ in Crore, unless noted)
A13: Particulars | B13: FY22 | C13: FY23 | D13: FY24 | E13: FY25 | F13: FY26
A14: Net Revenue / Sales | B14: 90171 | C14: 121362 | D14: 139078 | E14: 159211 | F14: 198639
A15: Revenue Growth % (YoY) | C15: =IFERROR(C14/B14-1,"") -> 0.34590944 | D15: =IFERROR(D14/C14-1,"") -> 0.1459765 | E15: =IFERROR(E14/D14-1,"") -> 0.14476049 | F15: =IFERROR(F14/E14-1,"") -> 0.24764621
A16: EBITDA | B16: 14683 | C16: 20325 | D16: 24892 | E16: 30518 | F16: 36980
A17: EBITDA Margin % | B17: =IFERROR(B16/B14,"") -> 0.16283506 | C17: =IFERROR(C16/C14,"") -> 0.16747417 | D17: =IFERROR(D16/D14,"") -> 0.1789787 | E17: =IFERROR(E16/E14,"") -> 0.19168274 | F17: =IFERROR(F16/F14,"") -> 0.18616687
A18: EBIT / Operating Profit | B18: 11175 | C18: 15968 | D18: 20168 | E18: 24444 | F18: 29658
A19: EBIT Margin % | B19: =IFERROR(B18/B14,"") -> 0.1239312 | C19: =IFERROR(C18/C14,"") -> 0.13157331 | D19: =IFERROR(D18/D14,"") -> 0.14501215 | E19: =IFERROR(E18/E14,"") -> 0.15353211 | F19: =IFERROR(F18/F14,"") -> 0.14930603
A20: Net Profit / PAT | B20: 7253 | C20: 11374 | D20: 12270 | E20: 14073 | F20: 18622
A21: Net Profit Margin % | B21: =IFERROR(B20/B14,"") -> 0.08043606 | C21: =IFERROR(C20/C14,"") -> 0.093719616 | D21: =IFERROR(D20/D14,"") -> 0.088223874 | E21: =IFERROR(E20/E14,"") -> 0.088392134 | F21: =IFERROR(F20/F14,"") -> 0.093747955
A22: EPS (₹) | B22: 52.91 | C22: 82.68 | D22: 90.62 | E22: 103.97 | F22: 137.5
A23: CapEx | B23: 6976 | C23: 2745 | D23: 9783 | E23: 12840 | F23: 10587
A24: CapEx as a % of Revenue | B24: =B23/B14 -> 0.077364119 | C24: =C23/C14 -> 0.022618282 | D24: =D23/D14 -> 0.070341823 | E24: =E23/E14 -> 0.080647694 | F24: =F23/F14 -> 0.053297691
A25: Depreciation & Amortisation | B25: 3508 | C25: 4357 | D25: 4724 | E25: 6074 | F25: 7322
A26: Depreciation as a % of Revenue | B26: =B25/B14 -> 0.03890386 | C26: =C25/C14 -> 0.035900859 | D26: =D25/D14 -> 0.033966551 | E26: =E25/E14 -> 0.03815063 | F26: =F25/F14 -> 0.036860838
A27: Finance Cost | B27: 5018 | C27: 5830 | D27: 7488 | E27: 9083 | F27: 9591
A28: Total Debt | B28: 77605 | C28: 92647 | D28: 108647 | E28: 129025 | F28: 136936
A29: Net Working Capital | B29: 61946 | C29: 82632 | D29: 103461 | E29: 121821 | F29: 143510
A30: Δ NWC | C30: =C29-B29 -> 20686 | D30: =D29-C29 -> 20829 | E30: =E29-D29 -> 18360 | F30: =F29-E29 -> 21689
A31: Δ NWC as % of Revenue | C31: =C30/C14 -> 0.17044874 | D31: =D30/D14 -> 0.14976488 | E31: =E30/E14 -> 0.11531867 | F31: =F30/F14 -> 0.10918802
A32: Cash & Cash Equivalents | B32: 30060 | C32: 35272 | D32: 35208 | E32: 41309 | F32: 40324
A33: Net Worth / Shareholders' Equity | B33: 47123 | C33: 56366 | D33: 66190 | E33: 77039 | F33: 93097
A34: Shares Outstanding (Crore) | B34: 124.3 | C34: 124.3 | D34: 124.3 | E34: 124.3 | F34: 124.3
A35: Market Price per Share (31-Aug-2026) | F35: 3282
A37: 3. Valuation Assumptions (WACC build-up)
A38: Risk-Free Rate (Rf) | B38: ='Economic & Industry Inputs'!$B$5 -> 0.069
A39: Beta (5Y) | B39: ='Portfolio Construction'!B2511 -> 1.1855035
A40: Equity Risk Premium (ERP) | B40: ='Economic & Industry Inputs'!$B$7 -> 0.061
A41: Cost of Equity | B41: =B38+B39*B40 -> 0.14131571
A42: Pre-tax Cost of Debt (Kd) | B42: =AVERAGE((B27/B28),(C27/C28),(D27/D28),(E27/E28),(F27/F28)) -> 0.067389097
A43: Tax Rate (t) | B43: ='Economic & Industry Inputs'!$B$8 -> 0.2517
A44: After-tax Cost of Debt | B44: =B42*(1-B43) -> 0.050427261
...

Sheet Coforge
A1: Coforge Ltd. (IT Services) - Fundamental Analysis & Valuation
A3: 1. Company Background
A4: Sector / Industry | B4: IT Services - Digital Transformation, Cloud, Cybersecurity, Analytics, Enterprise Applications
A5: Business Description | B5: Coforge (NIIT Technologies Limited) is an information technology (IT) solutions organization engaged in application development and maintenance, managed services, cloud computing and business process outsourcing to organizations in the financial services, insurance, travel, transportation and logistics, manufacturing and distribution and government sectors. The Company delivers services across continents directly and through its network of subsidiaries. It is servicing customers in North & South America, Europe, the Middle East, Asia and Australia. The Companys service offerings include application development and management, package implementation, managed services, platform based services, business process outsourcing and cloud computing.
A6: Year of Incorporation | B6: 1992 (as NIIT Technologies; renamed Coforge in 2020)
A7: Stock Exchange / Ticker (NSE/BSE) | B7: NSE: COFORGE | BSE: 532541
A8: Key Business Segments / Products | B8: Banking & Financial Services (BFS), Insurance, Travel, Retail & Logistics - cloud, digital engineering, cybersecurity, analytics
A9: Promoter Holding % (latest) | B9: No promoter holding (widely held; largest shareholders are institutional - DIIs ~56%, FIIs ~24% as of Jun 2026; the company has had no classified 'promoter' since a 2024 shareholding reclassification)
A11: 2. Historical Financial Analysis (₹ in Crore, unless noted)
A13: Particulars | B13: FY22 | C13: FY23 | D13: FY24 | E13: FY25 | F13: FY26
A14: Net Revenue / Sales | B14: 6432 | C14: 8015 | D14: 9009 | E14: 12073 | F14: 16403
A15: Revenue Growth % (YoY) | C15: =IFERROR(C14/B14-1,"") -> 0.24611318 | D15: =IFERROR(D14/C14-1,"") -> 0.12401747 | E15: =IFERROR(E14/D14-1,"") -> 0.34010434 | F15: =IFERROR(F14/E14-1,"") -> 0.35865154
A16: EBITDA | B16: 1102 | C16: 1282 | D16: 1447 | E16: 1694 | F16: 2936
A17: EBITDA Margin % | B17: =IFERROR(B16/B14,"") -> 0.17133085 | C17: =IFERROR(C16/C14,"") -> 0.15995009 | D17: =IFERROR(D16/D14,"") -> 0.16061716 | E17: =IFERROR(E16/E14,"") -> 0.1403131 | F17: =IFERROR(F16/F14,"") -> 0.17899165
A18: EBIT / Operating Profit | B18: 875 | C18: 1024 | D18: 1150 | E18: 1266 | F18: 2254
A19: EBIT Margin % | B19: =IFERROR(B18/B14,"") -> 0.13603856 | C19: =IFERROR(C18/C14,"") -> 0.12776045 | D19: =IFERROR(D18/D14,"") -> 0.12765013 | E19: =IFERROR(E18/E14,"") -> 0.10486209 | F19: =IFERROR(F18/F14,"") -> 0.13741389
A20: Net Profit / PAT | B20: 715 | C20: 745 | D20: 836 | E20: 936 | F20: 1745
A21: Net Profit Margin % | B21: =IFERROR(B20/B14,"") -> 0.11116294 | C21: =IFERROR(C20/C14,"") -> 0.092950717 | D21: =IFERROR(D20/D14,"") -> 0.092796093 | E21: =IFERROR(E20/E14,"") -> 0.077528369 | F21: =IFERROR(F20/F14,"") -> 0.10638298
A22: EPS (₹) | B22: 21.73 | C22: 22.72 | D22: 26.14 | E22: 24.29 | F22: 46.33
A23: CapEx | B23: 1290 | C23: 491 | D23: 356 | E23: 650 | F23: 1347
A24: CapEx as a % of Revenue | B24: =B23/B14 -> 0.2005597 | C24: =C23/C14 -> 0.061260137 | D24: =D23/D14 -> 0.03951604 | E24: =E23/E14 -> 0.053839145 | F24: =F23/F14 -> 0.082119125
A25: Depreciation & Amortisation | B25: 227 | C25: 258 | D25: 297 | E25: 428 | F25: 682
A26: Depreciation as a % of Revenue | B26: =B25/B14 -> 0.035292289 | C26: =C25/C14 -> 0.032189644 | D26: =D25/D14 -> 0.032967033 | E26: =E25/E14 -> 0.035451006 | F26: =F25/F14 -> 0.04157776
A27: Finance Cost | B27: 65 | C27: 81 | D27: 126 | E27: 135 | F27: 169
A28: Total Debt | B28: 490 | C28: 562 | D28: 726 | E28: 1070 | F28: 728
A29: Net Working Capital | B29: 1139 | C29: 1329 | D29: 1977 | E29: 1205 | F29: 3502
A30: Δ NWC | C30: =C29-B29 -> 190 | D30: =D29-C29 -> 648 | E30: =E29-D29 -> -772 | F30: =F29-E29 -> 2297
A31: Δ NWC as % of Revenue | C31: =C30/C14 -> 0.023705552 | D31: =D30/D14 -> 0.071928072 | E31: =E30/E14 -> -0.063944339 | F31: =F30/F14 -> 0.14003536
A32: Cash & Cash Equivalents | B32: 197 | C32: 234 | D32: 260 | E32: 426 | F32: 571
A33: Net Worth / Shareholders' Equity | B33: 2733 | C33: 3082 | D33: 3627 | E33: 6379 | F33: 9537
A34: Shares Outstanding (Crore) | B34: 44.3 | C34: 44.3 | D34: 44.3 | E34: 44.3 | F34: 44.3
A35: Market Price per Share (31-Aug-2026) | F35: 1985.3
A37: 3. Valuation Assumptions (WACC build-up)
A38: Risk-Free Rate (Rf) | B38: ='Economic & Industry Inputs'!$B$5 -> 0.069
A39: Beta (5Y) | B39: ='Portfolio Construction'!B2512 -> 1.1245597
A40: Equity Risk Premium (ERP) | B40: ='Economic & Industry Inputs'!$B$7 -> 0.061
A41: Cost of Equity | B41: =B38+B39*B40 -> 0.13759814
A42: Pre-tax Cost of Debt (Kd) | B42: =AVERAGE((B27/B28),(C27/C28),(D27/D28),(E27/E28),(F27/F28)) -> 0.1617292
A43: Tax Rate (t) | B43: ='Economic & Industry Inputs'!$B$8 -> 0.2517
A44: After-tax Cost of Debt | B44: =B42*(1-B43) -> 0.12102196
...

Sheet Dr Reddy
A1: Dr. Reddy's Laboratories Ltd. (Pharmaceuticals) - Fundamental Analysis & Valuation
A3: 1. Company Background
A4: Sector / Industry | B4: Pharmaceuticals - Generics, Active Pharmaceutical Ingredients (APIs), Biosimilars, Custom Pharmaceutical Services (CPS), Differentiated Formulations
A5: Business Description | B5: Dr Reddy`s Laboratories has been cateringto the needs ofthe pharmaceutical sector for over two decades. Active Pharmaceutical Ingredients (API) are their core strength, having a wide range of portfolio.The company also manufactures generic medicines with business spread across India, Russia, US and Germany as well as Proprietary Products which inlcudes NCE research, biologics business and differentiated formulations conducted in the US. Under this the company has launched Grafeel(Filgrastim) and Reditux(Rituximab).
A6: Year of Incorporation | B6: 1984
A7: Stock Exchange / Ticker (NSE/BSE) | B7: NSE: DRREDDY | BSE: 500124
A8: Key Business Segments / Products | B8: Global Generics (US, India, Emerging Markets, Europe), Pharmaceutical Services & Active Ingredients (PSAI), Biosimilars
A9: Promoter Holding % (latest) | B9: 26.6% (as of Jun 2026)
A11: 2. Historical Financial Analysis (₹ in Crore, unless noted)
A13: Particulars | B13: FY22 | C13: FY23 | D13: FY24 | E13: FY25 | F13: FY26
A14: Net Revenue / Sales | B14: 21545 | C14: 24670 | D14: 28011 | E14: 32644 | F14: 33700
A15: Revenue Growth % (YoY) | C15: =IFERROR(C14/B14-1,"") -> 0.14504525 | D15: =IFERROR(D14/C14-1,"") -> 0.13542764 | E15: =IFERROR(E14/D14-1,"") -> 0.16539931 | F15: =IFERROR(F14/E14-1,"") -> 0.032348977
A16: EBITDA | B16: 3768 | C16: 6470 | D16: 7933 | E16: 8547 | F16: 6454
A17: EBITDA Margin % | B17: =IFERROR(B16/B14,"") -> 0.17488977 | C17: =IFERROR(C16/C14,"") -> 0.26226186 | D17: =IFERROR(D16/D14,"") -> 0.28321017 | E17: =IFERROR(E16/E14,"") -> 0.26182453 | F17: =IFERROR(F16/F14,"") -> 0.19151335
A18: EBIT / Operating Profit | B18: 2603 | C18: 5220 | D18: 6463 | E18: 6843 | F18: 4395
A19: EBIT Margin % | B19: =IFERROR(B18/B14,"") -> 0.12081689 | C19: =IFERROR(C18/C14,"") -> 0.21159303 | D19: =IFERROR(D18/D14,"") -> 0.23073078 | E19: =IFERROR(E18/E14,"") -> 0.20962505 | F19: =IFERROR(F18/F14,"") -> 0.13041543
A20: Net Profit / PAT | B20: 2182 | C20: 4507 | D20: 5578 | E20: 5725 | F20: 4158
A21: Net Profit Margin % | B21: =IFERROR(B20/B14,"") -> 0.1012764 | C21: =IFERROR(C20/C14,"") -> 0.18269153 | D21: =IFERROR(D20/D14,"") -> 0.19913605 | E21: =IFERROR(E20/E14,"") -> 0.17537679 | F21: =IFERROR(F20/F14,"") -> 0.12338279
A22: EPS (₹) | B22: 26.23 | C22: 54.14 | D22: 66.87 | E22: 67.77 | F22: 50.27
A23: CapEx | B23: 809 | C23: 2084 | D23: 3066 | E23: 10551 | F23: 4890
A24: CapEx as a % of Revenue | B24: =B23/B14 -> 0.037549315 | C24: =C23/C14 -> 0.084475071 | D24: =D23/D14 -> 0.109457 | E24: =E23/E14 -> 0.32321407 | F24: =F23/F14 -> 0.14510386
A25: Depreciation & Amortisation | B25: 1165 | C25: 1250 | D25: 1470 | E25: 1704 | F25: 2059
A26: Depreciation as a % of Revenue | B26: =B25/B14 -> 0.054072871 | C26: =C25/C14 -> 0.050668829 | D26: =D25/D14 -> 0.052479383 | E26: =E25/E14 -> 0.052199485 | F26: =F25/F14 -> 0.061097923
A27: Finance Cost | B27: 96 | C27: 143 | D27: 171 | E27: 283 | F27: 374
A28: Total Debt | B28: 3384 | C28: 1347 | D28: 2002 | E28: 4677 | F28: 7734
A29: Net Working Capital | B29: 10566 | C29: 9398 | D29: 13481 | E29: 13483 | F29: 16817
A30: Δ NWC | C30: =C29-B29 -> -1168 | D30: =D29-C29 -> 4083 | E30: =E29-D29 -> 2 | F30: =F29-E29 -> 3334
A31: Δ NWC as % of Revenue | C31: =C30/C14 -> -0.047344953 | D31: =D30/D14 -> 0.14576416 | E31: =E30/E14 -> 6.1267002e-05 | F31: =F30/F14 -> 0.098931751
A32: Cash & Cash Equivalents | B32: 2616 | C32: 4986 | D32: 4930 | E32: 4051 | F32: 5285
A33: Net Worth / Shareholders' Equity | B33: 19212 | C33: 23286 | D33: 28254 | E33: 33549 | F33: 37892
A34: Shares Outstanding (Crore) | B34: 83.5 | C34: 83.5 | D34: 83.5 | E34: 83.5 | F34: 83.5
A35: Market Price per Share (31-Aug-2026) | F35: 1154.4
A37: 3. Valuation Assumptions (WACC build-up)
A38: Risk-Free Rate (Rf) | B38: ='Economic & Industry Inputs'!$B$5 -> 0.069
A39: Beta (5Y) | B39: ='Portfolio Construction'!B2513 -> 0.52899745
A40: Equity Risk Premium (ERP) | B40: ='Economic & Industry Inputs'!$B$7 -> 0.061
A41: Cost of Equity | B41: =B38+B39*B40 -> 0.10126884
A42: Pre-tax Cost of Debt (Kd) | B42: =AVERAGE((B27/B28),(C27/C28),(D27/D28),(E27/E28),(F27/F28)) -> 0.065762399
A43: Tax Rate (t) | B43: ='Economic & Industry Inputs'!$B$8 -> 0.2517
A44: After-tax Cost of Debt | B44: =B42*(1-B43) -> 0.049210003
...

Sheet Britannia
A1: Britannia Industries Ltd. (FMCG) - Fundamental Analysis & Valuation
A3: 1. Company Background
A4: Sector / Industry | B4: FMCG - Packaged Foods (Biscuits, Bread, Cakes, Rusk, Dairy)
A5: Business Description | B5: Britannia Industries, part of the Wadia Group, is one of India's leading food companies with a 100-year legacy and annual revenues in excess of Rs.16,000cr. Iconic brands include Good Day, Tiger, NutriChoice, Milk Bikis, and Marie Gold. Product range spans biscuits, bread, cakes, rusk, and dairy (cheese, beverages, milk, yoghurt).
A6: Year of Incorporation | B6: 1918 (as Britannia Biscuit Company)
A7: Stock Exchange / Ticker (NSE/BSE) | B7: NSE: BRITANNIA | BSE: 500825
A8: Key Business Segments / Products | B8: Biscuits (core), Bread & Cakes, Rusk, Dairy (Cheese, Beverages, Milk, Yoghurt), adjacencies (Croissants, Cakes)
A9: Promoter Holding % (latest) | B9: 50.55% (as of Jun 2026, Wadia Group)
A11: 2. Historical Financial Analysis (₹ in Crore, unless noted)
A13: Particulars | B13: FY22 | C13: FY23 | D13: FY24 | E13: FY25 | F13: FY26
A14: Net Revenue / Sales | B14: 14136 | C14: 16301 | D14: 16769 | E14: 17943 | F14: 19152
A15: Revenue Growth % (YoY) | C15: =IFERROR(C14/B14-1,"") -> 0.15315507 | D15: =IFERROR(D14/C14-1,"") -> 0.028709895 | E15: =IFERROR(E14/D14-1,"") -> 0.070010138 | F15: =IFERROR(F14/E14-1,"") -> 0.067380037
A16: EBITDA | B16: 2201 | C16: 2831 | D16: 3167 | E16: 3176 | F16: 3514
A17: EBITDA Margin % | B17: =IFERROR(B16/B14,"") -> 0.15570175 | C17: =IFERROR(C16/C14,"") -> 0.17367033 | D17: =IFERROR(D16/D14,"") -> 0.1888604 | E17: =IFERROR(E16/E14,"") -> 0.17700496 | F17: =IFERROR(F16/F14,"") -> 0.18347953
A18: EBIT / Operating Profit | B18: 2000 | C18: 2605 | D18: 2867 | E18: 2863 | F18: 3177
A19: EBIT Margin % | B19: =IFERROR(B18/B14,"") -> 0.14148274 | C19: =IFERROR(C18/C14,"") -> 0.15980615 | D19: =IFERROR(D18/D14,"") -> 0.17097024 | E19: =IFERROR(E18/E14,"") -> 0.15956083 | F19: =IFERROR(F18/F14,"") -> 0.16588346
A20: Net Profit / PAT | B20: 1516 | C20: 2316 | D20: 2134 | E20: 2178 | F20: 2537
A21: Net Profit Margin % | B21: =IFERROR(B20/B14,"") -> 0.10724392 | C21: =IFERROR(C20/C14,"") -> 0.14207717 | D21: =IFERROR(D20/D14,"") -> 0.12725863 | E21: =IFERROR(E20/E14,"") -> 0.12138438 | F21: =IFERROR(F20/F14,"") -> 0.13246658
A22: EPS (₹) | B22: 63.31 | C22: 96.39 | D22: 88.84 | E22: 90.45 | F22: 105.18
A23: CapEx | B23: 580 | C23: 697 | D23: 499 | E23: 347 | F23: 233
A24: CapEx as a % of Revenue | B24: =B23/B14 -> 0.041029994 | C24: =C23/C14 -> 0.042758113 | D24: =D23/D14 -> 0.02975729 | E24: =E23/E14 -> 0.019339018 | F24: =F23/F14 -> 0.012165831
A25: Depreciation & Amortisation | B25: 201 | C25: 226 | D25: 300 | E25: 313 | F25: 337
A26: Depreciation as a % of Revenue | B26: =B25/B14 -> 0.014219015 | C26: =C25/C14 -> 0.01386418 | D26: =D25/D14 -> 0.017890154 | E26: =E25/E14 -> 0.017444129 | F26: =F25/F14 -> 0.017596074
A27: Finance Cost | B27: 144 | C27: 169 | D27: 164 | E27: 139 | F27: 113
A28: Total Debt | B28: 2481 | C28: 2997 | D28: 2065 | E28: 1247 | F28: 1380
A29: Net Working Capital | B29: 988 | C29: 447 | D29: 281 | E29: -257 | F29: -11
A30: Δ NWC | C30: =C29-B29 -> -541 | D30: =D29-C29 -> -166 | E30: =E29-D29 -> -538 | F30: =F29-E29 -> 246
A31: Δ NWC as % of Revenue | C31: =C30/C14 -> -0.033188148 | D31: =D30/D14 -> -0.0098992188 | E31: =E30/E14 -> -0.029983838 | F31: =F30/F14 -> 0.012844612
A32: Cash & Cash Equivalents | B32: 1762 | C32: 3324 | D32: 2767 | E32: 2865 | F32: 3610
A33: Net Worth / Shareholders' Equity | B33: 2558 | C33: 3534 | D33: 3941 | E33: 4356 | F33: 5106
A34: Shares Outstanding (Crore) | B34: 24.1 | C34: 24.1 | D34: 24.1 | E34: 24.1 | F34: 24.1
A35: Market Price per Share (31-Aug-2026) | F35: 5250
A37: 3. Valuation Assumptions (WACC build-up)
A38: Risk-Free Rate (Rf) | B38: ='Economic & Industry Inputs'!$B$5 -> 0.069
A39: Beta (5Y) | B39: ='Portfolio Construction'!B2514 -> 0.50853001
A40: Equity Risk Premium (ERP) | B40: ='Economic & Industry Inputs'!$B$7 -> 0.061
A41: Cost of Equity | B41: =B38+B39*B40 -> 0.10002033
A42: Pre-tax Cost of Debt (Kd) | B42: =AVERAGE((B27/B28),(C27/C28),(D27/D28),(E27/E28),(F27/F28)) -> 0.07744026
A43: Tax Rate (t) | B43: ='Economic & Industry Inputs'!$B$8 -> 0.2517
A44: After-tax Cost of Debt | B44: =B42*(1-B43) -> 0.057948547
...

Sheet Portfolio Construction
A1: Optimal Portfolio Construction (Markowitz Mean-Variance)
A2: 1. Daily Closing Price Data
A3: Date | B3: M&M | C3: Coforge | D3: Dr Reddy | E3: Britannia | F3: NIFTY 50
A4: 44440 | B4: 769.9 | C4: 1033.51 | D4: 952.69 | E4: 4015.35 | F4: 17076.25
A5: 44441 | B5: 752.45 | C5: 1031.59 | D5: 971.94 | E5: 4086.1 | F5: 17234.15
A6: 44442 | B6: 749.9 | C6: 1048.65 | D6: 979.71 | E6: 4124.2 | F6: 17323.6
A7: 44445 | B7: 754.75 | C7: 1056.2 | D7: 983.19 | E7: 4079.05 | F7: 17377.8
A8: 44446 | B8: 753.1 | C8: 1035.91 | D8: 979.49 | E8: 4095.45 | F8: 17362.1
A9: 44447 | B9: 754.75 | C9: 1027.22 | D9: 982.26 | E9: 4061.4 | F9: 17353.5
A10: 44448 | B10: 750.75 | C10: 1022.99 | D10: 982.41 | E10: 4070.8 | F10: 17369.25
A11: 44452 | B11: 745.55 | C11: 1035.57 | D11: 986.28 | E11: 4093.85 | F11: 17355.3
A12: 44453 | B12: 750.2 | C12: 1059.11 | D12: 986.15 | E12: 4101.5 | F12: 17380
A13: 44454 | B13: 755.1 | C13: 1073.86 | D13: 992.52 | E13: 4086.35 | F13: 17519.45
A14: 44455 | B14: 756.95 | C14: 1093.09 | D14: 986.39 | E14: 4073.05 | F14: 17629.5
A15: 44456 | B15: 754.15 | C15: 1088.94 | D15: 976.91 | E15: 4051.85 | F15: 17585.15
... A1243: 46265 | B1243: 3282 | C1243: 1985.3 | D1243: 1154.4 | E1243: 5250 | F1243: 24080.4
A1245: 2. Daily Returns
A1246: Date | B1246: M&M | C1246: Coforge | D1246: Dr Reddy | E1246: Britannia | F1246: NIFTY 50
A1247: =A5 -> 44441 | B1247: =IFERROR((B5/B4-1),"") -> -0.022665281 | C1247: =IFERROR((C5/C4-1),"") -> -0.0018577469 | D1247: =IFERROR((D5/D4-1),"") -> 0.020205943 | E1247: =IFERROR((E5/E4-1),"") -> 0.017619884 | F1247: =IFERROR((F5/F4-1),"") -> 0.0092467609
A1248: =A6 -> 44442 | B1248: =IFERROR((B6/B5-1),"") -> -0.0033889295 | C1248: =IFERROR((C6/C5-1),"") -> 0.016537578 | D1248: =IFERROR((D6/D5-1),"") -> 0.0079943206 | E1248: =IFERROR((E6/E5-1),"") -> 0.0093242946 | F1248: =IFERROR((F6/F5-1),"") -> 0.0051902763
A1249: =A7 -> 44445 | B1249: =IFERROR((B7/B6-1),"") -> 0.006467529 | C1249: =IFERROR((C7/C6-1),"") -> 0.007199733 | D1249: =IFERROR((D7/D6-1),"") -> 0.0035520715 | E1249: =IFERROR((E7/E6-1),"") -> -0.010947578 | F1249: =IFERROR((F7/F6-1),"") -> 0.00312868
A1250: =A8 -> 44446 | B1250: =IFERROR((B8/B7-1),"") -> -0.0021861544 | C1250: =IFERROR((C8/C7-1),"") -> -0.019210377 | D1250: =IFERROR((D8/D7-1),"") -> -0.0037632604 | E1250: =IFERROR((E8/E7-1),"") -> 0.004020544 | F1250: =IFERROR((F8/F7-1),"") -> -0.00090345153
A1251: =A9 -> 44447 | B1251: =IFERROR((B9/B8-1),"") -> 0.0021909441 | C1251: =IFERROR((C9/C8-1),"") -> -0.0083887596 | D1251: =IFERROR((D9/D8-1),"") -> 0.0028280023 | E1251: =IFERROR((E9/E8-1),"") -> -0.0083141047 | F1251: =IFERROR((F9/F8-1),"") -> -0.00049533179
A1252: =A10 -> 44448 | B1252: =IFERROR((B10/B9-1),"") -> -0.0052997681 | C1252: =IFERROR((C10/C9-1),"") -> -0.0041179105 | D1252: =IFERROR((D10/D9-1),"") -> 0.00015270906 | E1252: =IFERROR((E10/E9-1),"") -> 0.0023144728 | F1252: =IFERROR((F10/F9-1),"") -> 0.00090759789
A1253: =A11 -> 44452 | B1253: =IFERROR((B11/B10-1),"") -> -0.0069264069 | C1253: =IFERROR((C11/C10-1),"") -> 0.012297285 | D1253: =IFERROR((D11/D10-1),"") -> 0.0039392921 | E1253: =IFERROR((E11/E10-1),"") -> 0.0056622777 | F1253: =IFERROR((F11/F10-1),"") -> -0.00080314349
A1254: =A12 -> 44453 | B1254: =IFERROR((B12/B11-1),"") -> 0.0062370062 | C1254: =IFERROR((C12/C11-1),"") -> 0.022731443 | D1254: =IFERROR((D12/D11-1),"") -> -0.00013180841 | E1254: =IFERROR((E12/E11-1),"") -> 0.0018686566 | F1254: =IFERROR((F12/F11-1),"") -> 0.0014231964
A1255: =A13 -> 44454 | B1255: =IFERROR((B13/B12-1),"") -> 0.0065315916 | C1255: =IFERROR((C13/C12-1),"") -> 0.013926788 | D1255: =IFERROR((D13/D12-1),"") -> 0.0064594636 | E1255: =IFERROR((E13/E12-1),"") -> -0.0036937706 | F1255: =IFERROR((F13/F12-1),"") -> 0.0080235903
A1256: =A14 -> 44455 | B1256: =IFERROR((B14/B13-1),"") -> 0.0024500066 | C1256: =IFERROR((C14/C13-1),"") -> 0.017907362 | D1256: =IFERROR((D14/D13-1),"") -> -0.006176198 | E1256: =IFERROR((E14/E13-1),"") -> -0.0032547383 | F1256: =IFERROR((F14/F13-1),"") -> 0.0062815899
A1257: =A15 -> 44456 | B1257: =IFERROR((B15/B14-1),"") -> -0.0036990554 | C1257: =IFERROR((C15/C14-1),"") -> -0.0037965767 | D1257: =IFERROR((D15/D14-1),"") -> -0.009610803 | E1257: =IFERROR((E15/E14-1),"") -> -0.0052049447 | F1257: =IFERROR((F15/F14-1),"") -> -0.0025156698
A1258: =A16 -> 44459 | B1258: =IFERROR((B16/B15-1),"") -> -0.021348538 | C1258: =IFERROR((C16/C15-1),"") -> -0.017273679 | D1258: =IFERROR((D16/D15-1),"") -> -0.022438096 | E1258: =IFERROR((E16/E15-1),"") -> 0.0080580476 | F1258: =IFERROR((F16/F15-1),"") -> -0.010705055
... A2485: =A1243 -> 46265 | B2485: =IFERROR((B1243/B1242-1),"") -> -0.015596881 | C2485: =IFERROR((C1243/C1242-1),"") -> -0.01454383 | D2485: =IFERROR((D1243/D1242-1),"") -> -0.020033956 | E2485: =IFERROR((E1243/E1242-1),"") -> -0.011020062 | F2485: =IFERROR((F1243/F1242-1),"") -> -0.0039399147
A2487: 3. Risk-Return Summary
A2488: Metric | B2488: M&M | C2488: Coforge | D2488: Dr Reddy | E2488: Britannia | F2488: NIFTY 50
A2489: Average Daily Return | B2489: =IFERROR(AVERAGE(B1247:B2485),0) -> 0.001326643 | C2489: =IFERROR(AVERAGE(C1247:C2485),0) -> 0.00079145309 | D2489: =IFERROR(AVERAGE(D1247:D2485),0) -> 0.00024677926 | E2489: =IFERROR(AVERAGE(E1247:E2485),0) -> 0.00029820802 | F2489: =IFERROR(AVERAGE(F1247:F2485),0) -> 0.00031534608
A2490: Annualised Expected Return | B2490: =B2489*252 -> 0.33431403 | C2490: =C2489*252 -> 0.19944618 | D2490: =D2489*252 -> 0.062188373 | E2490: =E2489*252 -> 0.07514842 | F2490: =F2489*252 -> 0.079467212
A2491: Daily Std. Deviation | B2491: =IFERROR(STDEV(B1247:B2485),0) -> 0.017675332 | C2491: =IFERROR(STDEV(C1247:C2485),0) -> 0.023020565 | D2491: =IFERROR(STDEV(D1247:D2485),0) -> 0.013565405 | E2491: =IFERROR(STDEV(E1247:E2485),0) -> 0.012799072 | F2491: =IFERROR(STDEV(F1247:F2485),0) -> 0.008700389
A2492: Annualised Std. Deviation (Risk) | B2492: =B2491*SQRT(252) -> 0.28058719 | C2492: =C2491*SQRT(252) -> 0.36544014 | D2492: =D2491*SQRT(252) -> 0.21534413 | E2492: =E2491*SQRT(252) -> 0.20317896 | F2492: =F2491*SQRT(252) -> 0.13811439
A2494: 4. Covariance Matrix (annualised)
B2495: M&M | C2495: Coforge | D2495: Dr Reddy | E2495: Britannia
A2496: M&M | B2496: =IFERROR(COVAR(B1247:B2485,B1247:B2485)*252,0) -> 0.078665631 | C2496: =IFERROR(COVAR(B1247:B2485,C1247:C2485)*252,0) -> 0.021232459 | D2496: =IFERROR(COVAR(B1247:B2485,D1247:D2485)*252,0) -> 0.013609933 | E2496: =IFERROR(COVAR(B1247:B2485,E1247:E2485)*252,0) -> 0.013300926
...

Sheet AI-Assisted Recommendation
A1: AI-Assisted Investment Recommendation
A3: 1. AI Prompt(s) Used
A5: Prompt 1 (typed into ChatGPT) | B5: You are a financial analyst. Based on this data for four listed Indian companies - Mahindra & Mahindra (Auto), Coforge (IT Services), Dr. Reddy's Laboratories (Pharma), Britannia Industries (FMCG): 5-year revenue/EBITDA/PAT growth and margins, WACC, Beta, DCF value per share, and Relative valuation (P/E, EV/EBITDA, P/B against 4 peers each) versus CMP - give a Buy/Hold/Sell view for each with a one-paragraph rationale.
A6: AI Response 1 | B6: Based on the data you've shared, here's my read on each company: M&M - HOLD. Your blended fair value of Rs.3,078 is close to the current price of Rs.3,282 (about 6% below), so this one is roughly fairly valued rather than a clear Buy or Sell. One thing worth flagging: your DCF alone (Rs.2,952) and Relative valuation (Rs.3,205) tell a slightly different story, and the Relative number looks like it's being pulled down by Tata Motors Passenger Vehicles - that peer's P/E (1.3x) and EV/EBITDA (1.5x) are unusually low, most likely because of a one-off gain in its reported earnings rather than the market genuinely pricing it that cheap. I'd treat M&M's relative valuation with some caution because of that. Coforge - SELL. Both your DCF (Rs.230) and Relative valuation (Rs.1,353) sit well below the current price of Rs.1,985. The stock also appears to trade at a real premium versus its IT peers (Persistent, LTIMindtree, Mphasis, Tata Elxsi), so this isn't just a modelling quirk - the market does seem to be paying up for it. Dr. Reddy's - SELL. Fair value comes to about Rs.919 against a CMP of Rs.1,154, roughly 20% downside. This lines up with the margin compression you're showing in FY26, so both the numbers and the underlying business trend point the same way. Britannia - SELL. Blended value of Rs.3,693 versus CMP Rs.5,250 is about 30% downside. Britannia has historically traded at a high Price/Book, so there isn't much cushion left if growth slows further.
A7: Prompt 2 (typed into ChatGPT) | B7: Using the four companies' corrected annualised simple returns, annualised volatility, risk-free rate and the annualised covariance/correlation matrix calculated from their daily returns, suggest a portfolio allocation for a moderate-risk investor. Impose a minimum weight of 5% and maximum weight of 40% for each stock and maximise the portfolio Sharpe ratio. Provide the exact weights and explain the role of return, volatility and diversification/correlation in the allocation.
A8: AI Response 2 | B8: Given only M&M is close to fair value and the other three screen as Sells on fundamentals, a purely valuation-driven allocation would concentrate almost entirely in M&M with little else. But you asked for the Sharpe-maximising allocation based on risk and return, which is a different question - that one depends on each stock's historical volatility and how they move together (correlation), not on whether they're cheap or expensive today. Run the Solver optimisation on your Portfolio Construction tab with the 5%-40% bounds you specified, and treat that output as a risk/return-driven allocation on historical price data - it's a different lens from the fundamental Buy/Hold/Sell calls above, not a contradiction of them. It's worth explicitly noting in your presentation if the two disagree on any stock, since that's a genuinely interesting finding, not an error.
A9: Prompt 3 (typed into ChatGPT) | B9: Review the corrected portfolio optimisation based on simple daily price returns, the covariance/correlation matrix, individual risk-return metrics, and the DCF/relative valuation results for M&M, Coforge, Dr. Reddy's and Britannia. The quantitative maximum-Sharpe portfolio is approximately M&M 40.0%, Coforge 27.8%, Dr. Reddy's 9.1% and Britannia 23.0%, subject to 5%-40% constraints. Considering both the quantitative portfolio evidence and our fundamental/valuation analysis, recommend whether these weights should be retained or adjusted. Give exact final weights and explain each change.
A10: AI Response 3 | B10: The portfolio construction is directionally good, but I would make a few important changes before presenting it as the “optimal portfolio.”
A11: Stock | B11: Exact reason for the weight | C11: Weight
A12: M&M | B12: Maximum allocation because it has the strongest historical risk-adjusted performance: 33.4% return, 28.1% volatility and 0.95 Sharpe. It also has the strongest revenue growth (21.8% CAGR) and is the company closest to fair value in your valuation analysis. Hence, both the quantitative and fundamental analyses support the highest weight. | C12: 0.4
A13: Coforge | B13: Retained as a growth/diversification allocation because it has the highest revenue growth (26.4% CAGR) and a positive Sharpe (0.36). However, its 36.5% volatility is the highest among the four and its valuation indicates significant downside. Therefore, its weight is moderated to 25% in the final recommendation rather than retaining its higher quantitative weight. | C13: 0.25
A14: Dr. Reddy’s | B14: Increased modestly from the Solver allocation because it provides defensive diversification: 21.5% volatility and 0.53 beta, substantially below M&M and Coforge. Its return (6.2%) and Sharpe (-0.03) are weak, so it should not receive a large allocation; 10% provides defensive exposure without making it a major return driver. | C14: 0.1
A15: Britannia | B15: Retained at a meaningful weight because it has low volatility (20.3%), low beta (0.51) and provides diversification, with correlations below 0.25 across the portfolio. Its historical Sharpe is only 0.03, indicating limited risk-adjusted return, while valuation concerns justify avoiding an excessive allocation. | C15: 0.25
A18: 2. Critical Evaluation - AI vs. Our Own Analysis
A19: Company | B19: Critical Evaluation
A20: M&M | B20: AI agrees with our HOLD view. Both the valuation and quantitative analysis support the highest portfolio weight. M&M has the strongest corrected historical risk-adjusted performance and is closest to fair value. AI also correctly identified the potential distortion in the peer-based valuation.
A21: Coforge | B21: AI agrees on SELL fundamentally but the portfolio analysis gives it a meaningful weight. Its strong historical return and diversification benefit justify retaining exposure, while its high volatility and substantial valuation downside justify reducing its weight from the quantitative optimum of 27.8% to 25%.
A22: Dr. Reddy's | B22: AI agrees on SELL fundamentally, while our portfolio analysis gives it a limited diversification role. Its low beta and volatility provide defensive characteristics despite weak historical risk-adjusted returns. We therefore increase the weight modestly to 10%, without treating it as a high-conviction investment.
A23: Britannia | B23: AI agrees on SELL fundamentally, but the portfolio analysis supports retaining exposure for diversification. Its low beta, low volatility and relatively low correlations help reduce portfolio risk. We therefore retain a 25% allocation while avoiding an excessive weight given its valuation concerns.
A25: The AI recommendations broadly agree with our fundamental assessment: M&M is relatively fairly valued, while Coforge, Dr. Reddy's and Britannia present valuation concerns. However, AI's fundamental recommendations do not directly determine portfolio weights because portfolio construction depends on expected returns, volatility and covariance. The AI was useful in interpreting valuation outputs and challenging assumptions, but our Excel Solver remains the quantitative basis for portfolio optimisation. We therefore use AI as a decision-support tool rather than as a substitute for our independent analysis.
A30: Our final allocation of M&M 40%, Coforge 25%, Dr. Reddy's 10% and Britannia 25% represents a fundamental and risk-based overlay on the quantitative maximum-Sharpe portfolio. The adjustment moderates exposure to Coforge given its high volatility and valuation concerns, while modestly increasing the defensive allocations to Dr. Reddy's and Britannia.

Sheet Risks & Conclusion
A1: Risk & Portfolio Implication
A2: Company | B2: Key Investment Risk | C2: Portfolio Implication
A3: M&M | B3: EV transition/execution, cyclical auto demand, commodity costs and high beta | C3: Largest allocation, but capped at 40% because of higher systematic risk
A4: Coforge | B4: High valuation, high volatility, IT spending slowdown, GenAI pricing pressure and currency exposure | C4: Retained at 25%, below quantitative optimum because valuation risk is significant
A5: Dr. Reddy's | B5: US generics pricing pressure, USFDA/regulatory risk and weaker growth | C5: 10% defensive allocation due to low beta/volatility
A6: Britannia | B6: Input-cost inflation, volume growth slowdown and rich valuation | C6: 25% allocation for diversification despite weak standalone return
A8: Portfolio-Level Risks
A9: Risk | B9: Description | C9: Portfolio Impact
A10: Historical Data Dependence | B10: The portfolio weights are based on historical returns, volatility and correlations, which may not persist in the future. | C10: Actual future risk-adjusted returns may differ from the optimisation results.
A11: Estimation Risk | B11: Expected returns, volatility and covariance are estimates and are sensitive to the selected sample period and methodology. | C11: Small changes in inputs can lead to different optimal weights.
A12: Concentration Risk | B12: M&M has the maximum permitted allocation of 40%, making the portfolio relatively dependent on its performance. | C12: A significant decline in M&M could materially affect overall portfolio returns.
A13: Valuation Risk | B13: DCF and comparable-multiple valuations depend on assumptions such as growth, WACC, terminal value and peer selection. | C13: Changes in assumptions may materially alter intrinsic value estimates and investment attractiveness.
A14: Market & Systematic Risk | B14: All four stocks remain exposed to broad Indian equity-market movements despite operating across different sectors. | C14: A broad market downturn can adversely affect the entire portfolio.
A15: Sector-Specific Risk | B15: The portfolio is diversified across Auto, IT Services, Pharmaceuticals and FMCG, but each sector remains exposed to its own economic and regulatory risks. | C15: Sector-specific shocks may negatively affect individual holdings and portfolio performance.
A16: Model & Optimisation Risk | B16: Solver identifies the allocation that maximises historical Sharpe ratio under the specified 5%–40% constraints. | C16: The mathematical optimum may not remain optimal as market conditions and correlations change.
A17: No Guarantee of Future Performance | B17: Historical Sharpe, Treynor and Jensen's Alpha reflect past performance and do not guarantee future excess returns. | C17: Portfolio performance may differ materially from historical results.
A19: The portfolio provides cross-sector diversification and a balanced risk–return profile, but remains exposed to estimation, valuation, concentration, sector and market risks. Historical performance may not persist under changing market conditions.

Sheet Final Output
A1: Final Output - Consolidated Summary
A3: 1. Company Snapshot
A4: Company | B4: Sector | C4: CMP (Rs.)
A5: M&M | B5: Automobile | C5: ='M&M'!F35 -> 3282
A6: Coforge | B6: IT Services | C6: =Coforge!F35 -> 1985.3
A7: Dr Reddy | B7: Pharmaceuticals | C7: ='Dr Reddy'!F35 -> 1154.4
A8: Britannia | B8: FMCG | C8: =Britannia!F35 -> 5250
A10: 2. Valuation Summary - Fundamental Analysis Output
A11: Company | B11: WACC | C11: Beta | D11: DCF Value/Share | E11: Relative Value/Share | F11: Blended Fair Value | G11: CMP | H11: Upside/(Downside) | I11: Recommendation
A12: M&M | B12: ='M&M'!B49 -> 0.11847453 | C12: ='M&M'!B39 -> 1.1855035 | D12: ='M&M'!B103 -> 2945.2006 | E12: ='M&M'!B104 -> 3204.6247 | F12: ='M&M'!B105 -> 3074.9127 | G12: ='M&M'!B106 -> 3282 | H12: ='M&M'!B107 -> -0.063097909 | I12: ='M&M'!B108 -> HOLD
A13: Coforge | B13: =Coforge!B49 -> 0.13746206 | C13: =Coforge!B39 -> 1.1245597 | D13: =Coforge!B103 -> 229.78719 | E13: =Coforge!B104 -> 1352.6652 | F13: =Coforge!B105 -> 791.22617 | G13: =Coforge!B106 -> 1985.3 | H13: =Coforge!B107 -> -0.60145763 | I13: =Coforge!B108 -> SELL
A14: Dr Reddy | B14: ='Dr Reddy'!B49 -> 0.097402168 | C14: ='Dr Reddy'!B39 -> 0.52899745 | D14: ='Dr Reddy'!B103 -> 433.30227 | E14: ='Dr Reddy'!B104 -> 1403.5335 | F14: ='Dr Reddy'!B105 -> 918.41791 | G14: ='Dr Reddy'!B106 -> 1154.4 | H14: ='Dr Reddy'!B107 -> -0.20441969 | I14: ='Dr Reddy'!B108 -> SELL
A15: Britannia | B15: =Britannia!B49 -> 0.099566407 | C15: =Britannia!B39 -> 0.50853001 | D15: =Britannia!B102 -> 3199.5051 | E15: =Britannia!B103 -> 4186.2976 | F15: =Britannia!B104 -> 3692.9013 | G15: =Britannia!B105 -> 5250 | H15: =Britannia!B106 -> -0.29659022 | I15: =Britannia!B107 -> SELL
A18: 3.Stock Risk & Return
A19: Company | B19: Annualised Return | C19: Annualised Std. Dev | D19: Beta vs Nifty | E19: Sharpe Ratio
A20: M&M | B20: ='Portfolio Construction'!B2518 -> 0.33431403 | C20: ='Portfolio Construction'!C2518 -> 0.28058719 | D20: ='Portfolio Construction'!B2511 -> 1.1855035 | E20: ='Portfolio Construction'!D2518 -> 0.94556715
A21: Coforge | B21: ='Portfolio Construction'!B2519 -> 0.19944618 | C21: ='Portfolio Construction'!C2519 -> 0.36544014 | D21: ='Portfolio Construction'!B2512 -> 1.1245597 | E21: ='Portfolio Construction'!D2519 -> 0.35695635
A22: Dr Reddy | B22: ='Portfolio Construction'!B2520 -> 0.062188373 | C22: ='Portfolio Construction'!C2520 -> 0.21534413 | D22: ='Portfolio Construction'!B2513 -> 0.52899745 | E22: ='Portfolio Construction'!D2520 -> -0.031631356
A23: Britannia | B23: ='Portfolio Construction'!B2521 -> 0.07514842 | C23: ='Portfolio Construction'!C2521 -> 0.20317896 | D23: ='Portfolio Construction'!B2514 -> 0.50853001 | E23: ='Portfolio Construction'!D2521 -> 0.030261105
A25: 4. Quantitative Optimisation
A26: Metric | B26: M&M | C26: Coforge | D26: Dr Reddy | E26: Britannia
A27: Portfolio Weight (Max Sharpe, 5%-40% bounds) | B27: ='Portfolio Construction'!B2525 -> 0.4 | C27: ='Portfolio Construction'!C2525 -> 0.27839848 | D27: ='Portfolio Construction'!D2525 -> 0.091437015 | E27: ='Portfolio Construction'!E2525 -> 0.2301645
A28: Sum of Weights | B28: ='Portfolio Construction'!B2526 -> 1
A30: Portfolio Expected Return (annualised) | B30: ='Portfolio Construction'!B2528 -> 0.21223394
A31: Portfolio Std. Deviation (Risk) | B31: ='Portfolio Construction'!B2530 -> 0.18897994
A32: Risk-Free Rate | B32: ='Portfolio Construction'!B2531 -> 0.069
A33: Portfolio Sharpe Ratio | B33: ='Portfolio Construction'!B2532 -> 0.75793199
A34: Portfolio Beta (weighted avg.) | B34: ='Portfolio Construction'!B2533 -> 0.95269258
A35: Market Return (Nifty 50, annualised) | B35: ='Portfolio Construction'!B2534 -> 0.079467212
A36: Treynor Ratio | B36: ='Portfolio Construction'!B2535 -> 0.15034645
A37: Jensen's Alpha | B37: ='Portfolio Construction'!B2536 -> 0.13326191
A39: 5. Final Recommendation
A40: Stock | B40: Final Weight
A41: M&M | B41: 0.4
A42: Coforge | B42: 0.25
A43: Dr. Reddy's | B43: 0.1
A44: Britannia | B44: 0.25
A46: The final recommendation applies a fundamental overlay to the quantitative maximum-Sharpe portfolio. The allocation modestly reduces Coforge due to its valuation and volatility concerns while increasing the defensive allocations to Dr. Reddy's and Britannia. The resulting portfolio remains very close to the historical maximum-Sharpe solution.
