Workbook

Sheet Relative Valuation
A1: Peer Company | B1: Capitaline Code | C1: Company Name | D1: Net Sales | E1: Operating Profit | F1: Depreciation | G1: Extraordinary Items | H1: Earnings Per Share(Adj)-Unit Curr | I1: Book Value(Adj)-Unit Curr | J1: Minority Interest | K1: Total Debt | L1: Cash and Bank | M1: Latest No of Equity Shares | N1: 52 Week High - Unit Curr. (BSE) | O1: 52 Week Low - Unit Curr. (BSE) | P1: Market Capitalisation (BSE) | Q1: Latest Market Price - Unit Curr. (BSE) | R1: BSE Sensex | S1: Enterprise Value | T1: Adjusted EBIT | U1: Adjusted EBITDA | V1: Sector Specific parameter (If any) | X1: EV/Sales | Y1: EV/EBIT | Z1: EV/EBITDA | AA1: P/E | AB1: P/B | AC1: EV/Sector specific Ratio
A2: 1 | B2: N/A | C2: Granules India | D2: 4481.61 | E2: 988.91 | F2: 225.5 | G2: 20.45 | H2: 20.68 | I2: 153.19 | J2: 0 | K2: 1454.75 | L2: 596.38 | M2: 247796921 | N2: 910 | O2: 438.3 | P2: =M2*Q2/10000000 -> 22180.302 | Q2: 895.1 | R2: 0.8321 | S2: =P2+(K2-L2)+J2 -> 23038.672 | T2: =E2-G2 -> 968.46 | U2: =T2+F2 -> 1193.96 | X2: =S2/D2 -> 5.1407134 | Y2: =S2/T2 -> 23.788977 | Z2: =S2/U2 -> 19.296017 | AA2: =Q2/H2 -> 43.283366 | AB2: =Q2/I2 -> 5.8430707
A3: 2 | B3: N/A | C3: Strides Pharma | D3: 4565.34 | E3: 4116.14 | F3: 192.26 | G3: 69.88 | H3: 389.9 | I3: 276.88 | J3: 34.63 | K3: 1879.63 | L3: 136.78 | M3: 92172714 | N3: 1231 | O3: 768.65 | P3: =M3*Q3/10000000 -> 9872.6194 | Q3: 1071.1 | R3: 0.5601 | S3: =P3+(K3-L3)+J3 -> 11650.099 | T3: =E3-G3 -> 4046.26 | U3: =T3+F3 -> 4238.52 | X3: =S3/D3 -> 2.551858 | Y3: =S3/T3 -> 2.8792266 | Z3: =S3/U3 -> 2.7486244 | AA3: =Q3/H3 -> 2.7471146 | AB3: =Q3/I3 -> 3.8684629
A4: 3 | B4: N/A | C4: FDC | D4: 2108.12 | E4: 415.46 | F4: 53.73 | G4: 7.73 | H4: 16.39 | I4: 140.11 | J4: 0 | K4: 21.17 | L4: 52.77 | M4: 162810084 | N4: 527.8 | O4: 312.95 | P4: =M4*Q4/10000000 -> 6864.8872 | Q4: 421.65 | R4: 0.4593 | S4: =P4+(K4-L4)+J4 -> 6833.2872 | T4: =E4-G4 -> 407.73 | U4: =T4+F4 -> 461.46 | X4: =S4/D4 -> 3.2414128 | Y4: =S4/T4 -> 16.759344 | Z4: =S4/U4 -> 14.807973 | AA4: =Q4/H4 -> 25.726052 | AB4: =Q4/I4 -> 3.0094212
A5: 4 | B5: N/A | C5: Orchid Pharma | D5: 921.93 | E5: 145.04 | F5: 34.55 | G5: -0.32 | H5: 19.65 | I5: 236.35 | J5: 0 | K5: 174.61 | L5: 179.63 | M5: 50719105 | N5: 1133 | O5: 480 | P5: =M5*Q5/10000000 -> 5340.4682 | Q5: 1052.95 | R5: 1.2321 | S5: =P5+(K5-L5)+J5 -> 5335.4482 | T5: =E5-G5 -> 145.36 | U5: =T5+F5 -> 179.91 | X5: =S5/D5 -> 5.7872595 | Y5: =S5/T5 -> 36.705064 | Z5: =S5/U5 -> 29.656207 | AA5: =Q5/H5 -> 53.585242 | AB5: =Q5/I5 -> 4.4550455
A6: 5 | B6: N/A | C6: RPG Life Sciences | D6: 707.52 | E6: 177.45 | F6: 21.48 | G6: 5.5 | H6: 69.64 | I6: 366.05 | J6: 0 | K6: 20 | L6: 191.56 | M6: 16539015 | N6: 3082 | O6: 1733 | P6: =M6*Q6/10000000 -> 4532.0209 | Q6: 2740.2 | R6: 0.8112 | S6: =P6+(K6-L6)+J6 -> 4360.4609 | T6: =E6-G6 -> 171.95 | U6: =T6+F6 -> 193.43 | X6: =S6/D6 -> 6.1630214 | Y6: =S6/T6 -> 25.358889 | Z6: =S6/U6 -> 22.542837 | AA6: =Q6/H6 -> 39.348076 | AB6: =Q6/I6 -> 7.4858626
A7: 6 | B7: N/A | C7: Indoco Remedies | D7: 1664.92 | E7: 105.7 | F7: 113.84 | G7: 1.15 | H7: -7.99 | I7: 110.79 | J7: -3.62 | K7: 993.57 | L7: 17.07 | M7: 92303605 | N7: 332.2 | O7: 162.19 | P7: =M7*Q7/10000000 -> 2294.0215 | Q7: 248.53 | R7: 0.8164 | S7: =P7+(K7-L7)+J7 -> 3266.9015 | T7: =E7-G7 -> 104.55 | U7: =T7+F7 -> 218.39 | X7: =S7/D7 -> 1.9621973 | Y7: =S7/T7 -> 31.247264 | Z7: =S7/U7 -> 14.959025 | AA7: =Q7/H7 -> -31.105131 | AB7: =Q7/I7 -> 2.243253
W9: Average | X9: =AVERAGE(X2:X7) -> 4.1410771 | Y9: =AVERAGE(Y2:Y7) -> 22.789794 | Z9: =AVERAGE(Z2:Z7) -> 17.335114 | AA9: =AVERAGE(AA2:AA7) -> 22.26412 | AB9: =AVERAGE(AB2:AB7) -> 4.484186
J10: ` | W10: Median | X10: =MEDIAN(X2:X7) -> 4.1910631 | Y10: =MEDIAN(Y2:Y7) -> 24.573933 | Z10: =MEDIAN(Z2:Z7) -> 17.127521 | AA10: =MEDIAN(AA2:AA7) -> 32.537064 | AB10: =MEDIAN(AB2:AB7) -> 4.1617542
W11: 25th percentile | X11: =QUARTILE(X2:X7,1) -> 2.7242467 | Y11: =QUARTILE(Y2:Y7,1) -> 18.516752 | Z11: =QUARTILE(Z2:Z7,1) -> 14.845736 | AA11: =QUARTILE(AA2:AA7,1) -> 8.4918491 | AB11: =QUARTILE(AB2:AB7,1) -> 3.2241816
W12: 75th percentile | X12: =QUARTILE(X2:X7,3) -> 5.625623 | Y12: =QUARTILE(Y2:Y7,3) -> 29.77517 | Z12: =QUARTILE(Z2:Z7,3) -> 21.731132 | AA12: =QUARTILE(AA2:AA7,3) -> 42.299543 | AB12: =QUARTILE(AB2:AB7,3) -> 5.4960644
A13: Target company | B13: N/A | C13: Unichem Laboratories Ltd | D13: 2201.85 | E13: 449.09 | F13: 125.12 | G13: 170.95 | H13: 35.91 | I13: 386 | J13: 0 | K13: 500.15 | L13: 294.7 | M13: 70405750 | N13: 687.2 | O13: 280 | P13: =M13*Q13/10000000 -> 4093.0383 | Q13: 581.35 | R13: 1.1662 | S13: =P13+(K13-L13)+J13 -> 4298.4883 | T13: =E13-G13 -> 278.14 | U13: =T13+F13 -> 403.26
W14: Implied Enterprise value (M) | X14: =X10*$D$13 -> 9228.0923 | Y14: =Y10*$T$13 -> 6834.9936 | Z14: =Z10*$U$13 -> 6906.8441
W15: Implied Enterprise value (25th) | X15: =X11*$D$13 -> 5998.3826 | Y15: =Y11*$D$13 -> 40771.11 | Z15: =Z11*$D$13 -> 32688.084
W16: Implied Enterprise value (75th) | X16: =X12*$D$13 -> 12386.778 | Y16: =Y12*$D$13 -> 65560.459 | Z16: =Z12*$D$13 -> 47848.692
W18: Implied Eq value (M) | X18: =X14-($K$13-$L$13)-$J$13 -> 9022.6423 | Y18: =Y14-($K$13-$L$13)-$J$13 -> 6629.5436 | Z18: =Z14-($K$13-$L$13)-$J$13 -> 6701.3941
W19: Implied Eq value (25th) | X19: =X15-($K$13-$L$13)-$J$13 -> 5792.9326 | Y19: =Y15-($K$13-$L$13)-$J$13 -> 40565.66 | Z19: =Z15-($K$13-$L$13)-$J$13 -> 32482.634
W20: Implied Eq value (75th) | X20: =X16-($K$13-$L$13)-$J$13 -> 12181.328 | Y20: =Y16-($K$13-$L$13)-$J$13 -> 65355.009 | Z20: =Z16-($K$13-$L$13)-$J$13 -> 47643.242
W22: Per share value (M) | X22: =(X18/($M$13/10000000)) -> 1281.5207 | Y22: =(Y18/($M$13/10000000)) -> 941.61963 | Z22: =(Z18/($M$13/10000000)) -> 951.82483 | AA22: =AA10*$H$13 -> 1168.406 | AB22: =AB10*$I$13 -> 1606.4371
W23: Per share value (25th) | X23: =(X19/($M$13/10000000)) -> 822.79254 | Y23: =(Y19/($M$13/10000000)) -> 5761.6971 | Z23: =(Z19/($M$13/10000000)) -> 4613.6337 | AA23: =AA11*$H$13 -> 304.9423 | AB23: =AB11*$I$13 -> 1244.5341
W24: Per share value (75th) | X24: =(X20/($M$13/10000000)) -> 1730.161 | Y24: =(Y20/($M$13/10000000)) -> 9282.6238 | Z24: =(Z20/($M$13/10000000)) -> 6766.9533 | AA24: =AA12*$H$13 -> 1518.9766 | AB24: =AB12*$I$13 -> 2121.4809
W26: Current market price of Target | X26: =Q13 -> 581.35

Sheet WACC
A1: Data from Capitaline
A2: Date | B2: Unichem price | C2: Unichem Return | D2: Sensex | E2: Sensex return | G2: Adjusted Regression Beta | H2: 2 years | I2: 5 years | M2: Risk-free rate | O2: Source | R2: Source | S2: Capital | T2: Weight | U2: Cost | V2: Product
A3: 44287 | B3: 314.05 | D3: 50029.83 | G3: Levered Raw Beta | H3: 2 years | I3: 5 years | M3: 10 Yr G-Bonds | N3: 0.068 | O3: https://www.worldgovernmentbonds.com | R3: Equity (M Cap) | S3: 4093.0383 | T3: =S3/$S$7 -> 0.89111049 | U3: =N3+(K20*N12) -> 0.11094764 | V3: =T3*U3 -> 0.098866604
A4: 44295 | B4: 325 | C4: =B3/B4-1 -> -0.033692308 | D4: 49591.32 | E4: =D3/D4-1 -> 0.0088424749 | G4: Slope | H4: =SLOPE(C159:C263,E159:E263) -> 1.1572726 | I4: =SLOPE(C4:C263,E4:E263) -> 0.65283188 | R4: Debt | S4: 500.15 | T4: =S4/$S$7 -> 0.10888951 | U4: =S15 -> 0.063161052 | V4: =T4*U4 -> 0.0068775757
A5: 44302 | B5: 320.3 | C5: =B4/B5-1 -> 0.014673743 | D5: 48832.03 | E5: =D4/D5-1 -> 0.015549016 | G5: Weight | H5: 0.67 | I5: 0.67 | R5: Preference Share | S5: 0 | T5: =S5/$S$7 -> 0 | U5: 0 | V5: =T5*U5 -> 0
A6: 44309 | B6: 338.25 | C6: =B5/B6-1 -> -0.053067258 | D6: 47878.45 | E6: =D5/D6-1 -> 0.019916685 | G6: Adjusted regression Beta | H6: =(H4*H5)+(1*(1-H5)) -> 1.1053726 | I6: =(I4*I5)+(1*(1-I5)) -> 0.76739736 | R6: Non- controlling Interest | S6: 0 | T6: =S6/$S$7 -> 0 | U6: =U3 -> 0.11094764 | V6: =T6*U6 -> 0
A7: 44316 | B7: 320.5 | C7: =B6/B7-1 -> 0.055382215 | D7: 48782.36 | E7: =D6/D7-1 -> -0.018529444 | O7: Source | R7: Total | S7: 4593.1883
A8: 44323 | B8: 330.35 | C8: =B7/B8-1 -> -0.029816861 | D8: 49206.47 | E8: =D7/D8-1 -> -0.0086189885 | M8: BSE Sensex return for 10 years | N8: 0.1221 | O8: https://www.bseindices.com/Downloads/Factsheet/Factsheet_BSESENSEX_May2026.pdf | R8: WACC | V8: =SUM(V3:V6) -> 0.10574418
A9: 44330 | B9: 335.2 | C9: =B8/B9-1 -> -0.014468974 | D9: 48732.55 | E9: =D8/D9-1 -> 0.0097249169 | G9: Bottom up Beta (fundamental beta): Data from Capitaline
A10: 44337 | B10: 359.6 | C10: =B9/B10-1 -> -0.06785317 | D10: 50540.48 | E10: =D9/D10-1 -> -0.03577192 | G10: Company Name (Same business) | H10: Total Debt | I10: Market Cap | J10: Sensex beta | K10: Unlevered beta
A11: 44344 | B11: 360.95 | C11: =B10/B11-1 -> -0.0037401302 | D11: 51422.88 | E11: =D10/D11-1 -> -0.017159677 | G11: ='Relative Valuation'!C2 -> Granules India | H11: ='Relative Valuation'!K2 -> 1454.75 | I11: ='Relative Valuation'!P2 -> 22180.302 | J11: ='Relative Valuation'!R2 -> 0.8321 | K11: =J11/(1+((H11/I11)*(1-0.3))) -> 0.79557421 | O11: Source | R11: Source
A12: 44351 | B12: 325.35 | C12: =B11/B12-1 -> 0.10942062 | D12: 52100.05 | E12: =D11/D12-1 -> -0.012997492 | G12: ='Relative Valuation'!C3 -> Strides Pharma | H12: ='Relative Valuation'!K3 -> 1879.63 | I12: ='Relative Valuation'!P3 -> 9872.6194 | J12: ='Relative Valuation'!R3 -> 0.5601 | K12: =J12/(1+((H12/I12)*(1-0.3))) -> 0.49423275 | M12: Historical Risk Premiun | N12: =N8-N3 -> 0.0541 | R12: Historical Risk Premium = 10Y Sensex return - risk-free rate
A13: 44358 | B13: 329.9 | C13: =B12/B13-1 -> -0.013792058 | D13: 52474.76 | E13: =D12/D13-1 -> -0.0071407663 | G13: ='Relative Valuation'!C4 -> FDC | H13: ='Relative Valuation'!K4 -> 21.17 | I13: ='Relative Valuation'!P4 -> 6864.8872 | J13: ='Relative Valuation'!R4 -> 0.4593 | K13: =J13/(1+((H13/I13)*(1-0.3))) -> 0.45831066 | R13: The one-year LIBOR rate is currently 6.04143%
A14: 44365 | B14: 320.45 | C14: =B13/B14-1 -> 0.02948978 | D14: 52344.45 | E14: =D13/D14-1 -> 0.0024894712 | G14: ='Relative Valuation'!C5 -> Orchid Pharma | H14: ='Relative Valuation'!K5 -> 174.61 | I14: ='Relative Valuation'!P5 -> 5340.4682 | J14: ='Relative Valuation'!R5 -> 1.2321 | K14: =J14/(1+((H14/I14)*(1-0.3))) -> 1.2045319 | R14: Cost of debt = Finance cost / Total financial obligations | S14: =0.0604143+0.03 -> 0.0904143
A15: 44372 | B15: 322.35 | C15: =B14/B15-1 -> -0.0058942144 | D15: 52925.04 | E15: =D14/D15-1 -> -0.010970044 | G15: ='Relative Valuation'!C6 -> RPG Life Sciences | H15: ='Relative Valuation'!K6 -> 20 | I15: ='Relative Valuation'!P6 -> 4532.0209 | J15: ='Relative Valuation'!R6 -> 0.8112 | K15: =J15/(1+((H15/I15)*(1-0.3))) -> 0.80870182 | R15: Finance cost/Total Debt | S15: ='Reform Stat, Ratio, GROWTH'!AJ14/'Reform Stat, Ratio, GROWTH'!AJ67 -> 0.063161052
A16: 44379 | B16: 329 | C16: =B15/B16-1 -> -0.020212766 | D16: 52484.67 | E16: =D15/D16-1 -> 0.00839045 | G16: ='Relative Valuation'!C7 -> Indoco Remedies | H16: ='Relative Valuation'!K7 -> 993.57 | I16: ='Relative Valuation'!P7 -> 2294.0215 | J16: ='Relative Valuation'!R7 -> 0.8164 | K16: =J16/(1+((H16/I16)*(1-0.3))) -> 0.62646807
A17: 44386 | B17: 327.8 | C17: =B16/B17-1 -> 0.0036607688 | D17: 52386.19 | E17: =D16/D17-1 -> 0.0018798848 | G17: Av unlevered beta | K17: =AVERAGE(K11:K16) -> 0.73130324
A18: 44393 | B18: 336.15 | C18: =B17/B18-1 -> -0.024840101 | D18: 53140.06 | E18: =D17/D18-1 -> -0.014186473
A19: 44400 | B19: 334.65 | C19: =B18/B19-1 -> 0.0044822949 | D19: 52975.8 | E19: =D18/D19-1 -> 0.0031006611
A20: 44407 | B20: 332.85 | C20: =B19/B20-1 -> 0.0054078414 | D20: 52586.84 | E20: =D19/D20-1 -> 0.0073965273 | G20: Relevered beta of Unichem Laboratories Ltd | K20: =K17*(1+(H21/I21)*(1-0.3)) -> 0.79385651
A21: 44414 | B21: 299.75 | C21: =B20/B21-1 -> 0.11042535 | D21: 54277.72 | E21: =D20/D21-1 -> -0.031152377 | G21: Target company | H21: 500.15 | I21: 4093.0383
A22: 44421 | B22: 289.65 | C22: =B21/B22-1 -> 0.03486967 | D22: 55437.29 | E22: =D21/D22-1 -> -0.020916787 | G22: Regression beta (2-year adjusted) | H22: 1.1023214 | I22: Regression beta (5-year adjusted) | J22: 0.76220242
A23: 44428 | B23: 270.35 | C23: =B22/B23-1 -> 0.07138894 | D23: 55329.32 | E23: =D22/D23-1 -> 0.0019514066 | G23: WACC selection | H23: Bottom-up beta, as in professor reference model
A24: 44435 | B24: 284.2 | C24: =B23/B24-1 -> -0.048733286 | D24: 56124.72 | E24: =D23/D24-1 -> -0.014172008 | G24: Data note | H24: Capitaline weekly Unichem + Sensex data supplied; regression beta is shown, while bottom-up beta is retained as the selected WACC method to match the professor reference model. | K24: 1.16
A25: 44442 | B25: 285.5 | C25: =B24/B25-1 -> -0.0045534151 | D25: 58129.95 | E25: =D24/D25-1 -> -0.034495643
A26: 44448 | B26: 273.75 | C26: =B25/B26-1 -> 0.042922374 | D26: 58305.07 | E26: =D25/D26-1 -> -0.0030035124
A27: 44456 | B27: 274.05 | C27: =B26/B27-1 -> -0.0010946907 | D27: 59015.89 | E27: =D26/D27-1 -> -0.012044553
A28: 44463 | B28: 254.75 | C28: =B27/B28-1 -> 0.07576055 | D28: 60048.47 | E28: =D27/D28-1 -> -0.017195775
A29: 44470 | B29: 275.35 | C29: =B28/B29-1 -> -0.074813873 | D29: 58765.58 | E29: =D28/D29-1 -> 0.021830636
A30: 44477 | B30: 264.9 | C30: =B29/B30-1 -> 0.039448849 | D30: 60059.06 | E30: =D29/D30-1 -> -0.021536801
A31: 44483 | B31: 263.65 | C31: =B30/B31-1 -> 0.0047411341 | D31: 61305.95 | E31: =D30/D31-1 -> -0.020338809
A32: 44491 | B32: 245.9 | C32: =B31/B32-1 -> 0.072183815 | D32: 60821.62 | E32: =D31/D32-1 -> 0.0079631223
A33: 44498 | B33: 241.6 | C33: =B32/B33-1 -> 0.017798013 | D33: 59306.93 | E33: =D32/D33-1 -> 0.025539848
A34: 44504 | B34: 223.1 | C34: =B33/B34-1 -> 0.082922456 | D34: 60067.62 | E34: =D33/D34-1 -> -0.012663894
A35: 44512 | B35: 206.9 | C35: =B34/B35-1 -> 0.078298695 | D35: 60686.69 | E35: =D34/D35-1 -> -0.010201084
A36: 44518 | B36: 203.3 | C36: =B35/B36-1 -> 0.017707821 | D36: 59636.01 | E36: =D35/D36-1 -> 0.017618214
... A263: 46108 | B263: 283.8 | C263: =B262/B263-1 -> 0.10306554 | D263: 73583.22 | E263: =D262/D263-1 -> 0.012907019
A264: 44393 | B264: 184.05 | D264: 53140.06
A265: 44386 | B265: 182.1 | D265: 52386.19
A266: 44379 | B266: 182.35 | D266: 52484.67
...

Sheet Raw BS
A1: Finance >>Balance Sheet IND (Consolidated)>>Unichem Laboratories Ltd (Curr. in ₹ crore)
A2: Year | B2: 201703 | C2: 201803 | D2: 201903 | E2: 202003 | F2: 202103 | G2: 202203 | H2: 202303 | I2: 202403 | J2: 202503 | K2: 202603
A3: Non-Current Assets:
A4: Fixed Assets | B4: 737.19 | C4: 812.6 | D4: 898.68 | E4: 1147.21 | F4: 1447.92 | G4: 1483.85 | H4: 1404.12 | I4: 1375.11 | J4: 1330.24 | K4: 1312.72 | M4: Note:
A5: Property, Plant and Equipment | B5: 484.03 | C5: 572.44 | D5: 804.5 | E5: 815.2 | F5: 832.81 | G5: 924.49 | H5: 1196.12 | I5: 1125.2 | J5: 1211.01 | K5: 1135.9 | M5: If 2026 data is not avialble on capitaline then check the financial statements available on the website of the company
A6: Capital Work in Progress | B6: 249.98 | C6: 238.15 | D6: 92.39 | E6: 330.47 | F6: 567.5 | G6: 493.81 | H6: 147.45 | I6: 122.71 | J6: 30.67 | K6: 100.14
A7: Right-of-Use Assets | B7: 0 | C7: 0 | D7: 0 | E7: 0 | F7: 0 | G7: 64 | H7: 58.99 | I7: 69.29 | J7: 68.31 | K7: 67.8
A8: Intangible Assets | B8: 3.19 | C8: 2.01 | D8: 1.79 | E8: 1.55 | F8: 1.55 | G8: 1.55 | H8: 1.55 | I8: 57.91 | J8: 20.25 | K8: 8.88
A9: Intangible Assets under Development | B9: 0 | C9: 0 | D9: 0 | E9: 0 | F9: 0 | G9: 0 | H9: 0 | I9: 0 | J9: 0 | K9: 0
A10: Fixed Assets Held For Sale | B10: 0 | C10: 0 | D10: 0 | E10: 0 | F10: 0 | G10: 0 | H10: 0 | I10: 0 | J10: 0 | K10: 0
A11: Lease Adjustment | B11: 0 | C11: 0 | D11: 0 | E11: 0 | F11: 0 | G11: 0 | H11: 0 | I11: 0 | J11: 0 | K11: 0
A12: Biological Assets other than Bearer Plants | B12: 0 | C12: 0 | D12: 0 | E12: 0 | F12: 0 | G12: 0 | H12: 0 | I12: 0 | J12: 0 | K12: 0
A13: Non-current Investments
A14: Investment Properties | B14: 3.79 | C14: 3.72 | D14: 3.66 | E14: 3.6 | F14: 3.53 | G14: 0 | H14: 0 | I14: 0 | J14: 0 | K14: 0
A15: Investments in Subsidiaries, Associates and Joint venture | B15: 5.62 | C15: 5.4 | D15: 5.46 | E15: 6.27 | F15: 5.93 | G15: 0 | H15: 0 | I15: 0 | J15: 0 | K15: 0
A16: Financial Assets :
A17: Investments of Life Insurance Business | B17: 0 | C17: 0 | D17: 0 | E17: 0 | F17: 0 | G17: 0 | H17: 0 | I17: 0 | J17: 0 | K17: 0
A18: Investments - Long-term | B18: 0.1 | C18: 0.09 | D18: 120.08 | E18: 124.51 | F18: 149.66 | G18: 0.28 | H18: 0.16 | I18: 0.02 | J18: 0.02 | K18: 0.02
A19: Loans - Long - Term | B19: 0.09 | C19: 0.07 | D19: 0.06 | E19: 0.08 | F19: 0.07 | G19: 0.12 | H19: 0.13 | I19: 0.13 | J19: 0.14 | K19: 0.11
A20: Others Financial Assets - Long-term | B20: 12.59 | C20: 9.41 | D20: 9.74 | E20: 10.03 | F20: 10.26 | G20: 8.13 | H20: 6.32 | I20: 5.91 | J20: 8.27 | K20: 8.59
A21: Non Current Tax Assets - Long - Term | B21: 0 | C21: 0 | D21: 0 | E21: 0 | F21: 0 | G21: 0 | H21: 0 | I21: 0 | J21: 0 | K21: 0
A22: Insurance Related Assets | B22: 0 | C22: 0 | D22: 0 | E22: 0 | F22: 0 | G22: 0 | H22: 0 | I22: 0 | J22: 0 | K22: 0
A23: Other Non-current Assets | B23: 12.9 | C23: 22.31 | D23: 55.96 | E23: 114.31 | F23: 117.07 | G23: 173.65 | H23: 180.34 | I23: 140.33 | J23: 167 | K23: 184.85
A24: Deferred Tax Assets (Net) | B24: 5.91 | C24: 3.61 | D24: 16.68 | E24: 2.94 | F24: 13.95 | G24: 4.36 | H24: 10.11 | I24: 6.78 | J24: 25.78 | K24: 30.56
A25: Total Reported Non-current Assets | B25: 778.19 | C25: 857.2 | D25: 1110.33 | E25: 1458.27 | F25: 1748.4 | G25: 1670.38 | H25: 1601.17 | I25: 1528.28 | J25: 1531.45 | K25: 1536.85
A26: Current Assets:
A27: Inventories | B27: 281.71 | C27: 272.86 | D27: 338.66 | E27: 396.54 | F27: 538.34 | G27: 600.22 | H27: 625.23 | I27: 736.26 | J27: 988.74 | K27: 974.97
A28: Biological Assets other than Bearer Plants | B28: 0 | C28: 0 | D28: 0 | E28: 0 | F28: 0 | G28: 0 | H28: 0 | I28: 0 | J28: 0 | K28: 0
A29: Financial Assets :
A30: Current Investments | B30: 8 | C30: 895.55 | D30: 800.75 | E30: 419.1 | F30: 236.43 | G30: 263.58 | H30: 1.54 | I30: 1.34 | J30: 0 | K30: 0
A31: Trade Receivables | B31: 315.32 | C31: 276.92 | D31: 436.05 | E31: 390.14 | F31: 250.27 | G31: 495.43 | H31: 588.62 | I31: 642.31 | J31: 778.81 | K31: 828.58
A32: Cash and Cash Equivalents | B32: 11.21 | C32: 666.07 | D32: 197.05 | E32: 231.52 | F32: 77.46 | G32: 109.2 | H32: 183.75 | I32: 154.75 | J32: 89.58 | K32: 289.48
A33: Bank Balances Other Than Cash and Cash Equivalents | B33: 4.93 | C33: 15.39 | D33: 3.94 | E33: 2.29 | F33: 4.99 | G33: 4.91 | H33: 1.61 | I33: 3.41 | J33: 28.05 | K33: 5.22
A34: Loans - Short-term | B34: 0.09 | C34: 0.05 | D34: 0.06 | E34: 0.04 | F34: 0.04 | G34: 0.05 | H34: 0.06 | I34: 0.04 | J34: 0.06 | K34: 0.06
A35: Others Financial Assets - Short-term | B35: 2.49 | C35: 29.25 | D35: 23.65 | E35: 15.33 | F35: 9.2 | G35: 0.55 | H35: 1.71 | I35: 0.23 | J35: 4.83 | K35: 4.42
A36: Current Tax Assets - Short-term | B36: 0 | C36: 0 | D36: 0 | E36: 0 | F36: 0 | G36: 0 | H36: 0 | I36: 0 | J36: 0 | K36: 0
A37: Insurance Related Assets | B37: 0 | C37: 0 | D37: 0 | E37: 0 | F37: 0 | G37: 0 | H37: 0 | I37: 0 | J37: 0 | K37: 0
A38: Other Current Assets | B38: 124.71 | C38: 180.37 | D38: 238.25 | E38: 231.5 | F38: 260.59 | G38: 170.98 | H38: 185.95 | I38: 204.98 | J38: 139.4 | K38: 94.61
A39: Assets Classified as Held for Sale | B39: 0 | C39: 0 | D39: 0 | E39: 0 | F39: 0 | G39: 3.47 | H39: 0 | I39: 0 | J39: 0 | K39: 3.25
A40: Total Current Assets | B40: 748.46 | C40: 2336.47 | D40: 2038.41 | E40: 1686.47 | F40: 1377.32 | G40: 1648.39 | H40: 1588.47 | I40: 1743.32 | J40: 2029.47 | K40: 2197.34
...

Sheet Raw IS
A1: Finance >>Profit & Loss IND (Consolidated)>>Unichem Laboratories Ltd (Curr. in ₹ crore)
A2: Year | B2: 201703 | C2: 201803 | D2: 201903 | E2: 202003 | F2: 202103 | G2: 202203 | H2: 202303 | I2: 202403 | J2: 202503 | K2: 202603
A3: Revenue From Operations | B3: 698.67 | C3: 814.98 | D3: 1180.05 | E3: 1103.71 | F3: 1235.14 | G3: 1269.83 | H3: 1343.02 | I3: 1785.11 | J3: 2110.97 | K3: 2201.85
A4: Less: Excise Duty | B4: 0.95 | C4: 0.39 | D4: 0 | E4: 0 | F4: 0 | G4: 0 | H4: 0 | I4: 0 | J4: 0 | K4: 0
A5: Revenue From Operations(Net) | B5: 697.71 | C5: 814.59 | D5: 1180.05 | E5: 1103.71 | F5: 1235.14 | G5: 1269.83 | H5: 1343.02 | I5: 1785.11 | J5: 2110.97 | K5: 2201.85
A6: Other Income | B6: 5.5 | C6: 60.88 | D6: 98.41 | E6: 91.31 | F6: 50.19 | G6: 47.51 | H6: 38.52 | I6: 31.59 | J6: 35.32 | K6: 63.06
A7: Total Revenue | B7: 703.22 | C7: 875.47 | D7: 1278.46 | E7: 1195.03 | F7: 1285.32 | G7: 1317.34 | H7: 1381.54 | I7: 1816.7 | J7: 2146.29 | K7: 2264.91
A8: EXPENSES:
A9: Cost of Material Consumed | B9: 262.42 | C9: 387.57 | D9: 476.92 | E9: 421.88 | F9: 466.99 | G9: 456.01 | H9: 532.2 | I9: 762.83 | J9: 888.24 | K9: 768.83
A10: Internally Manufactured Intermediates or Components Consumed | B10: 0 | C10: 0 | D10: 0 | E10: 0 | F10: 0 | G10: 0 | H10: 0 | I10: 0 | J10: 0 | K10: 0
A11: Purchases of Stock-in-Trade | B11: 0 | C11: 0.16 | D11: 0.21 | E11: 1.04 | F11: 0.54 | G11: 1.35 | H11: 1.53 | I11: 80.83 | J11: 175.78 | K11: 231.51
A12: Changes in Inventories of Finished Goods, Work-in-Progress and Stock-in-Trade | B12: -3.25 | C12: -29.48 | D12: -32.48 | E12: -35.76 | F12: -88.14 | G12: -41.53 | H12: 17.2 | I12: -106.96 | J12: -200.35 | K12: -200.35
A13: Employee Benefits / Salaries & other Staff Cost | B13: 169.04 | C13: 200.64 | D13: 238.52 | E13: 273.28 | F13: 306.97 | G13: 330.49 | H13: 356.41 | I13: 403.2 | J13: 402.21 | K13: 396.63
A14: Finance Cost | B14: 3.36 | C14: 8.01 | D14: 7.52 | E14: 7.85 | F14: 5.12 | G14: 6.11 | H14: 17.31 | I14: 22.66 | J14: 21.03 | K14: 31.59
A15: Depreciation and Amortization | B15: 43.52 | C15: 50.51 | D15: 67.37 | E15: 81.67 | F15: 84.36 | G15: 91.17 | H15: 113.44 | I15: 123.16 | J15: 124.56 | K15: 125.12
A16: Other Expenses | B16: 310.9 | C16: 387.59 | D16: 580.37 | E16: 494.09 | F16: 457.67 | G16: 450.72 | H16: 481.24 | I16: 558.33 | J16: 580.23 | K16: 600.5
A17: Total Expenses | B17: 785.98 | C17: 1005 | D17: 1338.43 | E17: 1244.05 | F17: 1233.5 | G17: 1294.31 | H17: 1519.33 | I17: 1844.05 | J17: 1991.7 | K17: 2174.39
A18: Share of Profits / Loss of Associated Companies Before Tax | B18: 0.19 | C18: -0.22 | D18: 0.07 | E18: 0.81 | F18: -0.34 | G18: -1.06 | H18: 0 | I18: 0 | J18: 0 | K18: 0
A19: Minority Interest Before Net Profit | B19: 0 | C19: 0 | D19: 0 | E19: 0 | F19: 0 | G19: 0 | H19: 0 | I19: 0 | J19: 0 | K19: 0
A20: Profit Before Exceptional Items and Tax | B20: -82.58 | C20: -129.76 | D20: -59.91 | E20: -48.21 | F20: 51.48 | G20: 21.97 | H20: -137.8 | I20: -27.35 | J20: 154.59 | K20: 90.52
... A63: Unappropriated Profits Carried Forward | B63: 108.68 | C63: 2544.91 | D63: -23.8 | E63: -60.18 | F63: 34.32 | G63: 33.06 | H63: -202.23 | I63: -93.76 | J63: 137.52 | K63: 252.84
A64: Other Comprehensive Income :
A65: Other Comprehensive Income That Will Not Be Reclassified to Profit Or Loss | B65: -1.24 | C65: -1.8 | D65: -0.28 | E65: 3 | F65: 21.3 | G65: 55.37 | H65: 38.73 | I65: -0.28 | J65: 1.38 | K65: 7.6
A66: Other Comprehensive Income That Will Be Reclassified to Profit Or Loss : | B66: 0.9 | C66: -2.79 | D66: 2.15 | E66: 0.06 | F66: -4.91 | G66: -1.62 | H66: 7.2 | I66: -5.37 | J66: -8.35 | K66: 4.39
A67: Other Comprehensive Income no Specification : | B67: 0 | C67: 0 | D67: 0 | E67: 0 | F67: 0 | G67: 0 | H67: 0 | I67: 0 | J67: 0 | K67: 0
A68: Non-Controlling Interests | B68: 0 | C68: 0 | D68: 0 | E68: 0 | F68: 0 | G68: 0 | H68: 0 | I68: 0 | J68: 0 | K68: 0
A69: Total Comprehensive Income for the Year | B69: 108.34 | C69: 2540.32 | D69: -21.93 | E69: -57.13 | F69: 50.72 | G69: 86.81 | H69: -156.3 | I69: -99.41 | J69: 130.55 | K69: 264.83
A70: Net Profit attributable to:
A71: a) Owners of the Company | B71: 108.34 | C71: 2540.32 | D71: -21.93 | E71: -57.13 | F71: 50.72 | G71: 86.81 | H71: -156.3 | I71: -99.41 | J71: 130.55 | K71: 252.84
A72: b) Non Controlling Interest | B72: 0 | C72: 0 | D72: 0 | E72: 0 | F72: 0 | G72: 0 | H72: 0 | I72: 0 | J72: 0 | K72: 0
A73: Other Comprehensive Income attributable to:
A74: a) Owners of the Company | B74: 108.34 | C74: 2540.32 | D74: -21.93 | E74: -57.13 | F74: 50.72 | G74: 86.81 | H74: -156.3 | I74: -99.41 | J74: 130.55 | K74: 264.83
A75: b) Non Controlling Interest | B75: 0 | C75: 0 | D75: 0 | E75: 0 | F75: 0 | G75: 0 | H75: 0 | I75: 0 | J75: 0 | K75: 0
A76: Total Comprehensive Income attributable to:
A77: a) Owners of the Company | B77: 108.34 | C77: 2540.32 | D77: -21.93 | E77: -57.13 | F77: 50.72 | G77: 86.81 | H77: -156.3 | I77: -99.41 | J77: 130.55 | K77: 264.83
A78: b) Non Controlling Interest | B78: 0 | C78: 0 | D78: 0 | E78: 0 | F78: 0 | G78: 0 | H78: 0 | I78: 0 | J78: 0 | K78: 0
A79: Earning Per Share - Basic | B79: 11.96 | C79: 280.6 | D79: -3.38 | E79: -8.55 | F79: 4.88 | G79: 4.7 | H79: -28.72 | I79: -13.32 | J79: 19.53 | K79: 35.91
A80: Earning Per Share - Diluted | B80: 11.94 | C80: 280.41 | D80: -3.38 | E80: -8.55 | F80: 4.88 | G80: 4.68 | H80: -28.72 | I80: -13.32 | J80: 19.47 | K80: 35.85
A81: Dividend Per Share | K81: 0
A82: Interim 1 | B82: 0 | C82: 0 | D82: 0 | E82: 0 | F82: 0 | G82: 0 | H82: 0 | I82: 0 | J82: 0 | K82: 0
...

Sheet Raw CFS
A1: Finance >>Cash Flow (Consolidated)>>Unichem Laboratories Ltd (Curr. in ₹ crore)
A2: Year | B2: 201703 | C2: 201803 | D2: 201903 | E2: 202003 | F2: 202103 | G2: 202203 | H2: 202303 | I2: 202403 | J2: 202503 | K2: 202603
A3: Cash Flow Summary
A4: Cash and Cash Equivalents at Beginning of the year | B4: 11.67 | C4: 11.21 | D4: 813.24 | E4: 309.91 | F4: 231.52 | G4: 77.46 | H4: 109.2 | I4: 183.75 | J4: 154.75 | K4: 89.58
A5: Net Cash from Operating Activities | B5: 68.19 | C5: -112.34 | D5: -327.77 | E5: 19.82 | F5: 32.98 | G5: -259.61 | H5: -85.09 | I5: 14 | J5: -7.02 | K5: 3.64
A6: Net Profit before Tax & Extraordinary Items | B6: 141.25 | C6: 3241.14 | D6: -57.44 | E6: -48.21 | F6: 51.48 | G6: 21.97 | H6: -176.36 | I6: -84.96 | J6: 154.59 | K6: 90.52
A7: Depreciation | B7: 45.18 | C7: 51.77 | D7: 67.43 | E7: 81.72 | F7: 84.42 | G7: 91.23 | H7: 113.44 | I7: 123.16 | J7: 124.56 | K7: 125.12
A8: Interest (Net) | B8: 0.88 | C8: -5.52 | D8: -37.46 | E8: -30.84 | F8: -17.82 | G8: -0.37 | H8: 16.8 | I8: 21.99 | J8: 18.18 | K8: 26.17
A9: Dividend Received | B9: 0 | C9: 18.4 | D9: 10.99 | E9: 1.58 | F9: 0 | G9: 10.01 | H9: 0.01 | I9: 0 | J9: 0 | K9: 0
A10: P/L on Sales of Assets | B10: 0 | C10: 5.03 | D10: 10.28 | E10: 1.86 | F10: 0.52 | G10: 0.23 | H10: -1.28 | I10: -4.86 | J10: -0.95 | K10: -274.29
A11: P/L on Sales of Invest | B11: 0 | C11: 0 | D11: 1.95 | E11: 0 | F11: 0 | G11: 0 | H11: 5.02 | I11: -64.78 | J11: -0.02 | K11: 0
A12: Prov. & W/O (Net) | B12: -0.38 | C12: 1.68 | D12: -3.31 | E12: -0.75 | F12: -0.15 | G12: 6.13 | H12: 4.22 | I12: 126.17 | J12: 0.12 | K12: -0.69
A13: P/L in Forex | B13: 7.82 | C13: -11.2 | D13: 4.04 | E13: -5.49 | F13: 7.61 | G13: -7.22 | H13: 2.66 | I13: -1 | J13: 4.01 | K13: -5.88
A14: Fin. Lease & Rental Chrgs | B14: 0.01 | C14: 0 | D14: 0 | E14: 0 | F14: 0 | G14: 0 | H14: 0 | I14: 0 | J14: 0 | K14: 0
A15: Others | B15: 63.01 | C15: -840.42 | D15: 0 | E15: 0 | F15: 0 | G15: 0 | H15: 0 | I15: 0 | J15: 0 | K15: 0
... A83: Cash and Cash Equivalents at End of the year | B83: 11.21 | C83: 666.07 | D83: 197.05 | E83: 231.52 | F83: 77.46 | G83: 109.2 | H83: 183.75 | I83: 154.75 | J83: 89.58 | K83: 289.48

Sheet Reform Stat, Ratio, GROWTH
B1: Finance >>Profit & Loss IND (Consolidated)>>Unichem Laboratories Ltd(Curr. in ) | N1: CONDENSED INCOME STATEMENT (₹ crore) | Z1: REFORMULATED INCOME STATEMENT (₹ crore) | AL1: RATIO ANALYSIS & VALUATION DASHBOARD >> UNICHEM LABORATORIES LTD (₹ crore, except per-share data) | AY1: HISTORICAL REINVESTMENT, GROWTH & WORKING CAPITAL ANALYSIS >> UNICHEM LABORATORIES LTD
B2: Year | C2: 201703 | D2: 201803 | E2: 201903 | F2: 202003 | G2: 202103 | H2: 202203 | I2: 202303 | J2: 202403 | K2: 202503 | L2: 202603 | N2: Year | O2: 201703 | P2: 201803 | Q2: 201903 | R2: 202003 | S2: 202103 | T2: 202203 | U2: 202303 | V2: 202403 | W2: 202503 | X2: 202603 | Z2: Year | AA2: 201703 | AB2: 201803 | AC2: 201903 | AD2: 202003 | AE2: 202103 | AF2: 202203 | AG2: 202303 | AH2: 202403 | AI2: 202503 | AJ2: 202603 | AL2: Year | AM2: =O2 -> 201703 | AN2: =P2 -> 201803 | AO2: =Q2 -> 201903 | AP2: =R2 -> 202003 | AQ2: =S2 -> 202103 | AR2: =T2 -> 202203 | AS2: =U2 -> 202303 | AT2: =V2 -> 202403 | ... AV2: =X2 -> 202603 | AW2: Trend Line | AY2: Particulars | AZ2: =C2 -> 201703 | BA2: =D2 -> 201803 | BB2: =E2 -> 201903 | BC2: =F2 -> 202003 | BD2: =G2 -> 202103 | BE2: =H2 -> 202203 | BF2: =I2 -> 202303 | BG2: =J2 -> 202403 | ... BI2: =L2 -> 202603 | BJ2: Historical Average | BK2: Remarks
B3: Revenue From Operations | C3: ='Raw IS'!B3 -> 698.67 | D3: ='Raw IS'!C3 -> 814.98 | E3: ='Raw IS'!D3 -> 1180.05 | F3: ='Raw IS'!E3 -> 1103.71 | G3: ='Raw IS'!F3 -> 1235.14 | H3: ='Raw IS'!G3 -> 1269.83 | I3: ='Raw IS'!H3 -> 1343.02 | J3: ='Raw IS'!I3 -> 1785.11 | ... L3: ='Raw IS'!K3 -> 2201.85 | N3: Revenue from Operations (Net) | O3: =C5 -> 697.71 | P3: =D5 -> 814.59 | Q3: =E5 -> 1180.05 | R3: =F5 -> 1103.71 | S3: =G5 -> 1235.14 | T3: =H5 -> 1269.83 | U3: =I5 -> 1343.02 | V3: =J5 -> 1785.11 | ... X3: =L5 -> 2201.85 | Z3: Operating Revenue | AA3: =O3 -> 697.71 | AB3: =P3 -> 814.59 | AC3: =Q3 -> 1180.05 | AD3: =R3 -> 1103.71 | AE3: =S3 -> 1235.14 | AF3: =T3 -> 1269.83 | AG3: =U3 -> 1343.02 | AH3: =V3 -> 1785.11 | ... AJ3: =X3 -> 2201.85 | AL3: Growth (%) | AY3: Capital Expenditure and Reinvestment
B4: Less: Excise Duty | C4: ='Raw IS'!B4 -> 0.95 | D4: ='Raw IS'!C4 -> 0.39 | E4: ='Raw IS'!D4 -> 0 | F4: ='Raw IS'!E4 -> 0 | G4: ='Raw IS'!F4 -> 0 | H4: ='Raw IS'!G4 -> 0 | I4: ='Raw IS'!H4 -> 0 | J4: ='Raw IS'!I4 -> 0 | ... L4: ='Raw IS'!K4 -> 0 | N4: Other Income | O4: =C6 -> 5.5 | P4: =D6 -> 60.88 | Q4: =E6 -> 98.41 | R4: =F6 -> 91.31 | S4: =G6 -> 50.19 | T4: =H6 -> 47.51 | U4: =I6 -> 38.52 | V4: =J6 -> 31.59 | ... X4: =L6 -> 63.06 | Z4: Cost of Goods Sold (COGS) | AA4: =O6 -> 259.17 | AB4: =P6 -> 358.25 | AC4: =Q6 -> 444.65 | AD4: =R6 -> 387.16 | AE4: =S6 -> 379.39 | AF4: =T6 -> 415.83 | AG4: =U6 -> 550.93 | AH4: =V6 -> 736.7 | ... AJ4: =X6 -> 799.99 | AL4: Sales Growth | AM4: ="" | AN4: =IFERROR(P3/O3-1,"") -> 0.16751946 | AO4: =IFERROR(Q3/P3-1,"") -> 0.44864288 | AP4: =IFERROR(R3/Q3-1,"") -> -0.064692174 | AQ4: =IFERROR(S3/R3-1,"") -> 0.11908019 | AR4: =IFERROR(T3/S3-1,"") -> 0.028085885 | AS4: =IFERROR(U3/T3-1,"") -> 0.057637637 | AT4: =IFERROR(V3/U3-1,"") -> 0.32917604 | AU4: =IFERROR(W3/V3-1,"") -> 0.18254337 | AV4: =IFERROR(X3/W3-1,"") -> 0.043051299 | AY4: Total Capital Expenditure | AZ4: =-C175 -> 149.83 | BA4: =-D175 -> 159.57 | BB4: =-E175 -> 194.31 | BC4: =-F175 -> 386.15 | BD4: =-G175 -> 287.81 | BE4: =-H175 -> 127 | BF4: =-I175 -> 44.32 | BG4: =-J175 -> 22.55 | ... BI4: =-L175 -> 123.04 | BJ4: =AVERAGE(AZ4:BI4) -> 163.194
B5: Revenue From Operations(Net) | C5: ='Raw IS'!B5 -> 697.71 | D5: ='Raw IS'!C5 -> 814.59 | E5: ='Raw IS'!D5 -> 1180.05 | F5: ='Raw IS'!E5 -> 1103.71 | G5: ='Raw IS'!F5 -> 1235.14 | H5: ='Raw IS'!G5 -> 1269.83 | I5: ='Raw IS'!H5 -> 1343.02 | J5: ='Raw IS'!I5 -> 1785.11 | ... L5: ='Raw IS'!K5 -> 2201.85 | N5: Total Income | O5: =SUM(O3:O4) -> 703.21 | P5: =SUM(P3:P4) -> 875.47 | Q5: =SUM(Q3:Q4) -> 1278.46 | R5: =SUM(R3:R4) -> 1195.02 | S5: =SUM(S3:S4) -> 1285.33 | T5: =SUM(T3:T4) -> 1317.34 | U5: =SUM(U3:U4) -> 1381.54 | V5: =SUM(V3:V4) -> 1816.7 | ... X5: =SUM(X3:X4) -> 2264.91 | Z5: Selling, General & Administrative Expenses (SG&A) | AA5: =SUM(O7:O8) -> 479.94 | AB5: =SUM(P7:P8) -> 588.23 | AC5: =SUM(Q7:Q8) -> 818.89 | AD5: =SUM(R7:R8) -> 767.37 | AE5: =SUM(S7:S8) -> 764.64 | AF5: =SUM(T7:T8) -> 781.21 | AG5: =SUM(U7:U8) -> 837.65 | AH5: =SUM(V7:V8) -> 961.53 | ... AJ5: =SUM(X7:X8) -> 997.13 | AL5: EBITDA Growth | AM5: ="" | AN5: =IFERROR(P9/O9-1,"") -> 0.97799443 | AO5: =IFERROR(Q9/P9-1,"") -> -1.2101113 | AP5: =IFERROR(R9/Q9-1,"") -> 1.713807 | AQ5: =IFERROR(S9/R9-1,"") -> 2.4897506 | AR5: =IFERROR(T9/S9-1,"") -> -0.14861996 | AS5: =IFERROR(U9/T9-1,"") -> -1.0585204 | AT5: =IFERROR(V9/U9-1,"") -> -17.828125 | AU5: =IFERROR(W9/V9-1,"") -> 1.533806 | AV5: =IFERROR(X9/W9-1,"") -> 0.55836498 | AY5: Depreciation Expenditure | AZ5: =O10 -> 43.52 | BA5: =P10 -> 50.51 | BB5: =Q10 -> 67.37 | BC5: =R10 -> 81.67 | BD5: =S10 -> 84.36 | BE5: =T10 -> 91.17 | BF5: =U10 -> 113.44 | BG5: =V10 -> 123.16 | ... BI5: =X10 -> 125.12 | BJ5: =AVERAGE(AZ5:BI5) -> 90.488
B6: Other Income | C6: ='Raw IS'!B6 -> 5.5 | D6: ='Raw IS'!C6 -> 60.88 | E6: ='Raw IS'!D6 -> 98.41 | F6: ='Raw IS'!E6 -> 91.31 | G6: ='Raw IS'!F6 -> 50.19 | H6: ='Raw IS'!G6 -> 47.51 | I6: ='Raw IS'!H6 -> 38.52 | J6: ='Raw IS'!I6 -> 31.59 | ... L6: ='Raw IS'!K6 -> 63.06 | N6: Cost of Goods Sold | O6: =SUM(C9:C12) -> 259.17 | P6: =SUM(D9:D12) -> 358.25 | Q6: =SUM(E9:E12) -> 444.65 | R6: =SUM(F9:F12) -> 387.16 | S6: =SUM(G9:G12) -> 379.39 | T6: =SUM(H9:H12) -> 415.83 | U6: =SUM(I9:I12) -> 550.93 | V6: =SUM(J9:J12) -> 736.7 | ... X6: =SUM(L9:L12) -> 799.99 | Z6: EBITDA from Operations | AA6: =AA3-AA4-AA5 -> -41.4 | AB6: =AB3-AB4-AB5 -> -131.89 | AC6: =AC3-AC4-AC5 -> -83.49 | AD6: =AD3-AD4-AD5 -> -50.82 | AE6: =AE3-AE4-AE5 -> 91.11 | AF6: =AF3-AF4-AF5 -> 72.79 | AG6: =AG3-AG4-AG5 -> -45.56 | AH6: =AH3-AH4-AH5 -> 86.88 | ... AJ6: =AJ3-AJ4-AJ5 -> 404.73 | AL6: EBIT Growth | AM6: ="" | AN6: =IFERROR(P11/O11-1,"") -> 0.53009318 | AO6: =IFERROR(Q11/P11-1,"") -> -0.56838381 | AP6: =IFERROR(R11/Q11-1,"") -> -0.21487131 | AQ6: =IFERROR(S11/R11-1,"") -> -2.3827101 | AR6: =IFERROR(T11/S11-1,"") -> -0.48840885 | AS6: =IFERROR(U11/T11-1,"") -> -5.1359423 | AT6: =IFERROR(V11/U11-1,"") -> -0.96107238 | AU6: =IFERROR(W11/V11-1,"") -> -38.445629 | AV6: =IFERROR(X11/W11-1,"") -> 0.95120146 | AY6: Net Capital Expenditure | AZ6: =AZ4-AZ5 -> 106.31 | BA6: =BA4-BA5 -> 109.06 | BB6: =BB4-BB5 -> 126.94 | BC6: =BC4-BC5 -> 304.48 | BD6: =BD4-BD5 -> 203.45 | BE6: =BE4-BE5 -> 35.83 | BF6: =BF4-BF5 -> -69.12 | BG6: =BG4-BG5 -> -100.61 | ... BI6: =BI4-BI5 -> -2.08 | BJ6: =AVERAGE(AZ6:BI6) -> 72.706
B7: Total Revenue | C7: ='Raw IS'!B7 -> 703.22 | D7: ='Raw IS'!C7 -> 875.47 | E7: ='Raw IS'!D7 -> 1278.46 | F7: ='Raw IS'!E7 -> 1195.03 | G7: ='Raw IS'!F7 -> 1285.32 | H7: ='Raw IS'!G7 -> 1317.34 | I7: ='Raw IS'!H7 -> 1381.54 | J7: ='Raw IS'!I7 -> 1816.7 | ... L7: ='Raw IS'!K7 -> 2264.91 | N7: Employee Benefits Expense | O7: =C13 -> 169.04 | P7: =D13 -> 200.64 | Q7: =E13 -> 238.52 | R7: =F13 -> 273.28 | S7: =G13 -> 306.97 | T7: =H13 -> 330.49 | U7: =I13 -> 356.41 | V7: =J13 -> 403.2 | ... X7: =L13 -> 396.63 | Z7: Depreciation & Amortization | AA7: =O10 -> 43.52 | AB7: =P10 -> 50.51 | AC7: =Q10 -> 67.37 | AD7: =R10 -> 81.67 | AE7: =S10 -> 84.36 | AF7: =T10 -> 91.17 | AG7: =U10 -> 113.44 | AH7: =V10 -> 123.16 | ... AJ7: =X10 -> 125.12 | AL7: Net Profit Growth | AM7: ="" | AN7: =IFERROR(P17/O17-1,"") -> 0.88139666 | AO7: =IFERROR(Q17/P17-1,"") -> -0.80802464 | AP7: =IFERROR(R17/Q17-1,"") -> 1.355773 | AQ7: =IFERROR(S17/R17-1,"") -> -1.5703605 | AR7: =IFERROR(T17/S17-1,"") -> -0.037285173 | AS7: =IFERROR(U17/T17-1,"") -> -7.1186082 | AT7: =IFERROR(V17/U17-1,"") -> -0.53634655 | AU7: =IFERROR(W17/V17-1,"") -> -2.4667235 | AV7: =IFERROR(X17/W17-1,"") -> 2.4424084
B8: EXPENSES: | C8: ='Raw IS'!B8 -> 0 | D8: ='Raw IS'!C8 -> 0 | E8: ='Raw IS'!D8 -> 0 | F8: ='Raw IS'!E8 -> 0 | G8: ='Raw IS'!F8 -> 0 | H8: ='Raw IS'!G8 -> 0 | I8: ='Raw IS'!H8 -> 0 | J8: ='Raw IS'!I8 -> 0 | ... L8: ='Raw IS'!K8 -> 0 | N8: Other Operating Expenses | O8: =C16 -> 310.9 | P8: =D16 -> 387.59 | Q8: =E16 -> 580.37 | R8: =F16 -> 494.09 | S8: =G16 -> 457.67 | T8: =H16 -> 450.72 | U8: =I16 -> 481.24 | V8: =J16 -> 558.33 | ... X8: =L16 -> 600.5 | Z8: Operating Profit (EBIT) | AA8: =AA6-AA7 -> -84.92 | AB8: =AB6-AB7 -> -182.4 | AC8: =AC6-AC7 -> -150.86 | AD8: =AD6-AD7 -> -132.49 | AE8: =AE6-AE7 -> 6.75 | AF8: =AF6-AF7 -> -18.38 | AG8: =AG6-AG7 -> -159 | AH8: =AH6-AH7 -> -36.28 | ... AJ8: =AJ6-AJ7 -> 279.61 | AY8: Current Assets
B9: Cost of Material Consumed | C9: ='Raw IS'!B9 -> 262.42 | D9: ='Raw IS'!C9 -> 387.57 | E9: ='Raw IS'!D9 -> 476.92 | F9: ='Raw IS'!E9 -> 421.88 | G9: ='Raw IS'!F9 -> 466.99 | H9: ='Raw IS'!G9 -> 456.01 | I9: ='Raw IS'!H9 -> 532.2 | J9: ='Raw IS'!I9 -> 762.83 | ... L9: ='Raw IS'!K9 -> 768.83 | N9: EBITDA | O9: =O5-SUM(O6:O8) -> -35.9 | P9: =P5-SUM(P6:P8) -> -71.01 | Q9: =Q5-SUM(Q6:Q8) -> 14.92 | R9: =R5-SUM(R6:R8) -> 40.49 | S9: =S5-SUM(S6:S8) -> 141.3 | T9: =T5-SUM(T6:T8) -> 120.3 | U9: =U5-SUM(U6:U8) -> -7.04 | V9: =V5-SUM(V6:V8) -> 118.47 | ... X9: =X5-SUM(X6:X8) -> 467.79 | Z9: Less: Tax Expense | AA9: =O16 -> -11.85 | AB9: =P16 -> 3.34 | AC9: =Q16 -> -34.35 | AD9: =R16 -> 11.97 | AE9: =S16 -> 17.15 | AF9: =T16 -> -11.09 | AG9: =U16 -> 25.86 | AH9: =V16 -> 8.8 | ... AJ9: =X16 -> 39.54 | AL9: Margins (%) | AY9: Inventories | AZ9: =C65 -> 281.71 | BA9: =D65 -> 272.86 | BB9: =E65 -> 338.66 | BC9: =F65 -> 396.54 | BD9: =G65 -> 538.34 | BE9: =H65 -> 600.22 | BF9: =I65 -> 625.23 | BG9: =J65 -> 736.26 | ... BI9: =L65 -> 974.97
B10: Internally Manufactured Intermediates or Components Consumed | C10: ='Raw IS'!B10 -> 0 | D10: ='Raw IS'!C10 -> 0 | E10: ='Raw IS'!D10 -> 0 | F10: ='Raw IS'!E10 -> 0 | G10: ='Raw IS'!F10 -> 0 | H10: ='Raw IS'!G10 -> 0 | I10: ='Raw IS'!H10 -> 0 | J10: ='Raw IS'!I10 -> 0 | ... L10: ='Raw IS'!K10 -> 0 | N10: Depreciation & Amortization | O10: =C15 -> 43.52 | P10: =D15 -> 50.51 | Q10: =E15 -> 67.37 | R10: =F15 -> 81.67 | S10: =G15 -> 84.36 | T10: =H15 -> 91.17 | U10: =I15 -> 113.44 | V10: =J15 -> 123.16 | ... X10: =L15 -> 125.12 | Z10: Net Operating Profit After Tax (NOPAT) | AA10: =AA8-AA9 -> -73.07 | AB10: =AB8-AB9 -> -185.74 | AC10: =AC8-AC9 -> -116.51 | AD10: =AD8-AD9 -> -144.46 | AE10: =AE8-AE9 -> -10.4 | AF10: =AF8-AF9 -> -7.29 | AG10: =AG8-AG9 -> -184.86 | AH10: =AH8-AH9 -> -45.08 | ... AJ10: =AJ8-AJ9 -> 240.07 | AL10: Gross Margin | AM10: =IFERROR((O3-O6)/O3,0) -> 0.62854194 | AN10: =IFERROR((P3-P6)/P3,0) -> 0.5602082 | AO10: =IFERROR((Q3-Q6)/Q3,0) -> 0.62319393 | AP10: =IFERROR((R3-R6)/R3,0) -> 0.64921945 | AQ10: =IFERROR((S3-S6)/S3,0) -> 0.69283644 | AR10: =IFERROR((T3-T6)/T3,0) -> 0.67253097 | AS10: =IFERROR((U3-U6)/U3,0) -> 0.58978273 | AT10: =IFERROR((V3-V6)/V3,0) -> 0.58730835 | ... AV10: =IFERROR((X3-X6)/X3,0) -> 0.63667371 | AY10: Trade Receivables | AZ10: =C69 -> 315.32 | BA10: =D69 -> 276.92 | BB10: =E69 -> 436.05 | BC10: =F69 -> 390.14 | BD10: =G69 -> 250.27 | BE10: =H69 -> 495.43 | BF10: =I69 -> 588.62 | BG10: =J69 -> 642.31 | ... BI10: =L69 -> 828.58
B11: Purchases of Stock-in-Trade | C11: ='Raw IS'!B11 -> 0 | D11: ='Raw IS'!C11 -> 0.16 | E11: ='Raw IS'!D11 -> 0.21 | F11: ='Raw IS'!E11 -> 1.04 | G11: ='Raw IS'!F11 -> 0.54 | H11: ='Raw IS'!G11 -> 1.35 | I11: ='Raw IS'!H11 -> 1.53 | J11: ='Raw IS'!I11 -> 80.83 | ... L11: ='Raw IS'!K11 -> 231.51 | N11: EBIT | O11: =O9-O10 -> -79.42 | P11: =P9-P10 -> -121.52 | Q11: =Q9-Q10 -> -52.45 | R11: =R9-R10 -> -41.18 | S11: =S9-S10 -> 56.94 | T11: =T9-T10 -> 29.13 | U11: =U9-U10 -> -120.48 | V11: =V9-V10 -> -4.69 | ... X11: =X9-X10 -> 342.67 | Z11: Other / Non-operating Income | AA11: =O4 -> 5.5 | AB11: =P4 -> 60.88 | AC11: =Q4 -> 98.41 | AD11: =R4 -> 91.31 | AE11: =S4 -> 50.19 | AF11: =T4 -> 47.51 | AG11: =U4 -> 38.52 | AH11: =V4 -> 31.59 | ... AJ11: =X4 -> 63.06 | AL11: EBITDA Margin | AM11: =IFERROR(AA6/AA3,0) -> -0.059336974 | AN11: =IFERROR(AB6/AB3,0) -> -0.16190967 | AO11: =IFERROR(AC6/AC3,0) -> -0.070751239 | AP11: =IFERROR(AD6/AD3,0) -> -0.046044704 | AQ11: =IFERROR(AE6/AE3,0) -> 0.073764917 | AR11: =IFERROR(AF6/AF3,0) -> 0.057322634 | AS11: =IFERROR(AG6/AG3,0) -> -0.033923545 | AT11: =IFERROR(AH6/AH3,0) -> 0.04866927 | ... AV11: =IFERROR(AJ6/AJ3,0) -> 0.18381361 | AY11: Short-Term Loans and Advances | AZ11: =C72 -> 0.09 | BA11: =D72 -> 0.05 | BB11: =E72 -> 0.06 | BC11: =F72 -> 0.04 | BD11: =G72 -> 0.04 | BE11: =H72 -> 0.05 | BF11: =I72 -> 0.06 | BG11: =J72 -> 0.04 | ... BI11: =L72 -> 0.06
B12: Changes in Inventories of Finished Goods, Work-in-Progress and Stock-in-Trade | C12: ='Raw IS'!B12 -> -3.25 | D12: ='Raw IS'!C12 -> -29.48 | E12: ='Raw IS'!D12 -> -32.48 | F12: ='Raw IS'!E12 -> -35.76 | G12: ='Raw IS'!F12 -> -88.14 | H12: ='Raw IS'!G12 -> -41.53 | I12: ='Raw IS'!H12 -> 17.2 | J12: ='Raw IS'!I12 -> -106.96 | ... L12: ='Raw IS'!K12 -> -200.35 | N12: Finance Cost | O12: =C14 -> 3.36 | P12: =D14 -> 8.01 | Q12: =E14 -> 7.52 | R12: =F14 -> 7.85 | S12: =G14 -> 5.12 | T12: =H14 -> 6.11 | U12: =I14 -> 17.31 | V12: =J14 -> 22.66 | ... X12: =L14 -> 31.59 | Z12: Share of Profit/(Loss) of Associates | AA12: =O13 -> 0.19 | AB12: =P13 -> -0.22 | AC12: =Q13 -> 0.07 | AD12: =R13 -> 0.81 | AE12: =S13 -> -0.34 | AF12: =T13 -> -1.06 | AG12: =U13 -> 0 | AH12: =V13 -> 0 | ... AJ12: =X13 -> 0 | AL12: EBIT Margin | AM12: =IFERROR(AA8/AA3,0) -> -0.12171246 | AN12: =IFERROR(AB8/AB3,0) -> -0.22391633 | AO12: =IFERROR(AC8/AC3,0) -> -0.12784204 | AP12: =IFERROR(AD8/AD3,0) -> -0.12004059 | AQ12: =IFERROR(AE8/AE3,0) -> 0.0054649675 | AR12: =IFERROR(AF8/AF3,0) -> -0.014474378 | AS12: =IFERROR(AG8/AG3,0) -> -0.1183899 | AT12: =IFERROR(AH8/AH3,0) -> -0.020323678 | ... AV12: =IFERROR(AJ8/AJ3,0) -> 0.12698867 | AY12: Other Current Assets | AZ12: =C76 -> 124.71 | BA12: =D76 -> 180.37 | BB12: =E76 -> 238.25 | BC12: =F76 -> 231.5 | BD12: =G76 -> 260.59 | BE12: =H76 -> 170.98 | BF12: =I76 -> 185.95 | BG12: =J76 -> 204.98 | ... BI12: =L76 -> 94.61
B13: Employee Benefits / Salaries & other Staff Cost | C13: ='Raw IS'!B13 -> 169.04 | D13: ='Raw IS'!C13 -> 200.64 | E13: ='Raw IS'!D13 -> 238.52 | F13: ='Raw IS'!E13 -> 273.28 | G13: ='Raw IS'!F13 -> 306.97 | H13: ='Raw IS'!G13 -> 330.49 | I13: ='Raw IS'!H13 -> 356.41 | J13: ='Raw IS'!I13 -> 403.2 | ... L13: ='Raw IS'!K13 -> 396.63 | N13: Share of Profit/(Loss) of Associates | O13: =C18 -> 0.19 | P13: =D18 -> -0.22 | Q13: =E18 -> 0.07 | R13: =F18 -> 0.81 | S13: =G18 -> -0.34 | T13: =H18 -> -1.06 | U13: =I18 -> 0 | V13: =J18 -> 0 | ... X13: =L18 -> 0 | Z13: Exceptional & Other Adjustments | AA13: =O14 -> 0 | AB13: =P14 -> 0 | AC13: =Q14 -> 0 | AD13: =R14 -> 0 | AE13: =S14 -> 0 | AF13: =T14 -> 0 | AG13: =U14 -> -38.57 | AH13: =V14 -> -57.61 | ... AJ13: =X14 -> 201.86 | AL13: EBT Margin | AM13: =IFERROR(O15/O3,0) -> -0.11837296 | AN13: =IFERROR(P15/P3,0) -> -0.15928258 | AO13: =IFERROR(Q15/Q3,0) -> -0.050760561 | AP13: =IFERROR(R15/R3,0) -> -0.043689013 | AQ13: =IFERROR(S15/S3,0) -> 0.041679486 | AR13: =IFERROR(T15/T3,0) -> 0.017293653 | AS13: =IFERROR(U15/U3,0) -> -0.13131599 | AT13: =IFERROR(V15/V3,0) -> -0.047593706 | ... AV13: =IFERROR(X15/X3,0) -> 0.23295865 | AY13: Total Current Operating Assets | AZ13: =SUM(AZ9:AZ12) -> 721.83 | BA13: =SUM(BA9:BA12) -> 730.2 | BB13: =SUM(BB9:BB12) -> 1013.02 | BC13: =SUM(BC9:BC12) -> 1018.22 | BD13: =SUM(BD9:BD12) -> 1049.24 | BE13: =SUM(BE9:BE12) -> 1266.68 | BF13: =SUM(BF9:BF12) -> 1399.86 | BG13: =SUM(BG9:BG12) -> 1583.59 | ... BI13: =SUM(BI9:BI12) -> 1898.22 | BJ13: =AVERAGE(AZ13:BI13) -> 1258.787
B14: Finance Cost | C14: ='Raw IS'!B14 -> 3.36 | D14: ='Raw IS'!C14 -> 8.01 | E14: ='Raw IS'!D14 -> 7.52 | F14: ='Raw IS'!E14 -> 7.85 | G14: ='Raw IS'!F14 -> 5.12 | H14: ='Raw IS'!G14 -> 6.11 | I14: ='Raw IS'!H14 -> 17.31 | J14: ='Raw IS'!I14 -> 22.66 | ... L14: ='Raw IS'!K14 -> 31.59 | N14: Exceptional & Other Adjustments | O14: =SUM(C21,C23:C25) -> 0 | P14: =SUM(D21,D23:D25) -> 0 | Q14: =SUM(E21,E23:E25) -> 0 | R14: =SUM(F21,F23:F25) -> 0 | S14: =SUM(G21,G23:G25) -> 0 | T14: =SUM(H21,H23:H25) -> 0 | U14: =SUM(I21,I23:I25) -> -38.57 | V14: =SUM(J21,J23:J25) -> -57.61 | ... X14: =SUM(L21,L23:L25) -> 201.86 | Z14: Less: Net Finance Cost | AA14: =O12 -> 3.36 | AB14: =P12 -> 8.01 | AC14: =Q12 -> 7.52 | AD14: =R12 -> 7.85 | AE14: =S12 -> 5.12 | AF14: =T12 -> 6.11 | AG14: =U12 -> 17.31 | AH14: =V12 -> 22.66 | ... AJ14: =X12 -> 31.59 | AL14: Net Profit Margin | AM14: =IFERROR(O17/O3,0) -> -0.10138883 | AN14: =IFERROR(P17/P3,0) -> -0.16338281 | AO14: =IFERROR(Q17/Q3,0) -> -0.021651625 | AP14: =IFERROR(R17/R3,0) -> -0.054534253 | AQ14: =IFERROR(S17/S3,0) -> 0.02779442 | AR14: =IFERROR(T17/T3,0) -> 0.026027106 | AS14: =IFERROR(U17/U3,0) -> -0.1505711 | AT14: =IFERROR(V17/V3,0) -> -0.052523374 | ... AV14: =IFERROR(X17/X3,0) -> 0.21500102
B15: Depreciation and Amortization | C15: ='Raw IS'!B15 -> 43.52 | D15: ='Raw IS'!C15 -> 50.51 | E15: ='Raw IS'!D15 -> 67.37 | F15: ='Raw IS'!E15 -> 81.67 | G15: ='Raw IS'!F15 -> 84.36 | H15: ='Raw IS'!G15 -> 91.17 | I15: ='Raw IS'!H15 -> 113.44 | J15: ='Raw IS'!I15 -> 123.16 | ... L15: ='Raw IS'!K15 -> 125.12 | N15: Profit Before Tax | O15: =O11-O12+O13+O14 -> -82.59 | P15: =P11-P12+P13+P14 -> -129.75 | Q15: =Q11-Q12+Q13+Q14 -> -59.9 | R15: =R11-R12+R13+R14 -> -48.22 | S15: =S11-S12+S13+S14 -> 51.48 | T15: =T11-T12+T13+T14 -> 21.96 | U15: =U11-U12+U13+U14 -> -176.36 | V15: =V11-V12+V13+V14 -> -84.96 | ... X15: =X11-X12+X13+X14 -> 512.94 | Z15: Net Profit | AA15: =AA10+SUM(AA11:AA13)-AA14 -> -70.74 | AB15: =AB10+SUM(AB11:AB13)-AB14 -> -133.09 | AC15: =AC10+SUM(AC11:AC13)-AC14 -> -25.55 | AD15: =AD10+SUM(AD11:AD13)-AD14 -> -60.19 | AE15: =AE10+SUM(AE11:AE13)-AE14 -> 34.33 | AF15: =AF10+SUM(AF11:AF13)-AF14 -> 33.05 | AG15: =AG10+SUM(AG11:AG13)-AG14 -> -202.22 | AH15: =AH10+SUM(AH11:AH13)-AH14 -> -93.76 | ... AJ15: =AJ10+SUM(AJ11:AJ13)-AJ14 -> 473.4 | AY15: Current Liabilities
B16: Other Expenses | C16: ='Raw IS'!B16 -> 310.9 | D16: ='Raw IS'!C16 -> 387.59 | E16: ='Raw IS'!D16 -> 580.37 | F16: ='Raw IS'!E16 -> 494.09 | G16: ='Raw IS'!F16 -> 457.67 | H16: ='Raw IS'!G16 -> 450.72 | I16: ='Raw IS'!H16 -> 481.24 | J16: ='Raw IS'!I16 -> 558.33 | ... L16: ='Raw IS'!K16 -> 600.5 | N16: Tax Expense | O16: =C27 -> -11.85 | P16: =D27 -> 3.34 | Q16: =E27 -> -34.35 | R16: =F27 -> 11.97 | S16: =G27 -> 17.15 | T16: =H27 -> -11.09 | U16: =I27 -> 25.86 | V16: =J27 -> 8.8 | ... X16: =L27 -> 39.54 | Z16: Net Profit Reconciliation Check | AA16: =AA15-O17 -> 0 | AB16: =AB15-P17 -> 0 | AC16: =AC15-Q17 -> -1.030287e-13 | AD16: =AD15-R17 -> 0 | AE16: =AE15-S17 -> -5.6843419e-14 | AF16: =AF15-T17 -> -1.1368684e-13 | AG16: =AG15-U17 -> 0 | AH16: =AH15-V17 -> 0 | ... AJ16: =AJ15-X17 -> 0 | AL16: Expense Ratios (%) | AY16: Trade Payables | AZ16: =C117 -> 210.73 | BA16: =D117 -> 226.23 | BB16: =E117 -> 221.41 | BC16: =F117 -> 250.22 | BD16: =G117 -> 210.08 | BE16: =H117 -> 183.19 | BF16: =I117 -> 290.69 | BG16: =J117 -> 351.26 | ... BI16: =L117 -> 356.63
B17: Total Expenses | C17: ='Raw IS'!B17 -> 785.98 | D17: ='Raw IS'!C17 -> 1005 | E17: ='Raw IS'!D17 -> 1338.43 | F17: ='Raw IS'!E17 -> 1244.05 | G17: ='Raw IS'!F17 -> 1233.5 | H17: ='Raw IS'!G17 -> 1294.31 | I17: ='Raw IS'!H17 -> 1519.33 | J17: ='Raw IS'!I17 -> 1844.05 | ... L17: ='Raw IS'!K17 -> 2174.39 | N17: Net Profit | O17: =O15-O16 -> -70.74 | P17: =P15-P16 -> -133.09 | Q17: =Q15-Q16 -> -25.55 | R17: =R15-R16 -> -60.19 | S17: =S15-S16 -> 34.33 | T17: =T15-T16 -> 33.05 | U17: =U15-U16 -> -202.22 | V17: =V15-V16 -> -93.76 | ... X17: =X15-X16 -> 473.4 | AL17: COGS / Sales | AM17: =IFERROR(O6/O3,0) -> 0.37145806 | AN17: =IFERROR(P6/P3,0) -> 0.4397918 | AO17: =IFERROR(Q6/Q3,0) -> 0.37680607 | AP17: =IFERROR(R6/R3,0) -> 0.35078055 | AQ17: =IFERROR(S6/S3,0) -> 0.30716356 | AR17: =IFERROR(T6/T3,0) -> 0.32746903 | AS17: =IFERROR(U6/U3,0) -> 0.41021727 | AT17: =IFERROR(V6/V3,0) -> 0.41269165 | ... AV17: =IFERROR(X6/X3,0) -> 0.36332629 | AY17: Other Current Liabilities | AZ17: =C122 -> 15.26 | BA17: =D122 -> 21.01 | BB17: =E122 -> 34.74 | BC17: =F122 -> 45.31 | BD17: =G122 -> 56.63 | BE17: =H122 -> 52.65 | BF17: =I122 -> 51.89 | BG17: =J122 -> 33.96 | ... BI17: =L122 -> 29.92
B18: Share of Profits / Loss of Associated Companies Before Tax | C18: ='Raw IS'!B18 -> 0.19 | D18: ='Raw IS'!C18 -> -0.22 | E18: ='Raw IS'!D18 -> 0.07 | F18: ='Raw IS'!E18 -> 0.81 | G18: ='Raw IS'!F18 -> -0.34 | H18: ='Raw IS'!G18 -> -1.06 | I18: ='Raw IS'!H18 -> 0 | J18: ='Raw IS'!I18 -> 0 | ... L18: ='Raw IS'!K18 -> 0 | N18: Net Profit Reconciliation Check | O18: =O17-C36 -> -0.02 | P18: =P17-D36 -> 0.01 | Q18: =Q17-E36 -> 0.01 | R18: =R17-F36 -> -0.01 | S18: =S17-G36 -> 0.01 | T18: =T17-H36 -> -0.01 | U18: =U17-I36 -> 0.01 | V18: =V17-J36 -> -1.8474111e-13 | ... X18: =X17-L36 -> 220.56 | AL18: Employee Expenses / Sales | AM18: =IFERROR(O7/O3,0) -> 0.24227831 | AN18: =IFERROR(P7/P3,0) -> 0.24630796 | AO18: =IFERROR(Q7/Q3,0) -> 0.20212703 | AP18: =IFERROR(R7/R3,0) -> 0.24760127 | AQ18: =IFERROR(S7/S3,0) -> 0.24853053 | AR18: =IFERROR(T7/T3,0) -> 0.26026318 | AS18: =IFERROR(U7/U3,0) -> 0.26537952 | AT18: =IFERROR(V7/V3,0) -> 0.22586843 | ... AV18: =IFERROR(X7/X3,0) -> 0.18013489 | AY18: Total Current Operating Liabilities | AZ18: =SUM(AZ16:AZ17) -> 225.99 | BA18: =SUM(BA16:BA17) -> 247.24 | BB18: =SUM(BB16:BB17) -> 256.15 | BC18: =SUM(BC16:BC17) -> 295.53 | BD18: =SUM(BD16:BD17) -> 266.71 | BE18: =SUM(BE16:BE17) -> 235.84 | BF18: =SUM(BF16:BF17) -> 342.58 | BG18: =SUM(BG16:BG17) -> 385.22 | ... BI18: =SUM(BI16:BI17) -> 386.55 | BJ18: =AVERAGE(AZ18:BI18) -> 305.174
B19: Minority Interest Before Net Profit | C19: ='Raw IS'!B19 -> 0 | D19: ='Raw IS'!C19 -> 0 | E19: ='Raw IS'!D19 -> 0 | F19: ='Raw IS'!E19 -> 0 | G19: ='Raw IS'!F19 -> 0 | H19: ='Raw IS'!G19 -> 0 | I19: ='Raw IS'!H19 -> 0 | J19: ='Raw IS'!I19 -> 0 | ... L19: ='Raw IS'!K19 -> 0 | AL19: Other Expenses / Sales | AM19: =IFERROR(O8/O3,0) -> 0.44560061 | AN19: =IFERROR(P8/P3,0) -> 0.47580992 | AO19: =IFERROR(Q8/Q3,0) -> 0.49181814 | AP19: =IFERROR(R8/R3,0) -> 0.44766288 | AQ19: =IFERROR(S8/S3,0) -> 0.37054099 | AR19: =IFERROR(T8/T3,0) -> 0.35494515 | AS19: =IFERROR(U8/U3,0) -> 0.35832676 | AT19: =IFERROR(V8/V3,0) -> 0.31277064 | ... AV19: =IFERROR(X8/X3,0) -> 0.27272521
B20: Profit Before Exceptional Items and Tax | C20: ='Raw IS'!B20 -> -82.58 | D20: ='Raw IS'!C20 -> -129.76 | E20: ='Raw IS'!D20 -> -59.91 | F20: ='Raw IS'!E20 -> -48.21 | G20: ='Raw IS'!F20 -> 51.48 | H20: ='Raw IS'!G20 -> 21.97 | I20: ='Raw IS'!H20 -> -137.8 | J20: ='Raw IS'!I20 -> -27.35 | ... L20: ='Raw IS'!K20 -> 90.52 | AL20: Depreciation / Sales | AM20: =IFERROR(O10/O3,0) -> 0.062375486 | AN20: =IFERROR(P10/P3,0) -> 0.062006654 | AO20: =IFERROR(Q10/Q3,0) -> 0.057090801 | AP20: =IFERROR(R10/R3,0) -> 0.073995887 | AQ20: =IFERROR(S10/S3,0) -> 0.06829995 | AR20: =IFERROR(T10/T3,0) -> 0.071797012 | AS20: =IFERROR(U10/U3,0) -> 0.084466352 | AT20: =IFERROR(V10/V3,0) -> 0.068992947 | ... AV20: =IFERROR(X10/X3,0) -> 0.056824943 | AY20: Net Working Capital | AZ20: =AZ13-AZ18 -> 495.84 | BA20: =BA13-BA18 -> 482.96 | BB20: =BB13-BB18 -> 756.87 | BC20: =BC13-BC18 -> 722.69 | BD20: =BD13-BD18 -> 782.53 | BE20: =BE13-BE18 -> 1030.84 | BF20: =BF13-BF18 -> 1057.28 | BG20: =BG13-BG18 -> 1198.37 | ... BI20: =BI13-BI18 -> 1511.67 | BJ20: =AVERAGE(AZ20:BI20) -> 953.613
B21: Exceptional Items Before Tax | C21: ='Raw IS'!B21 -> 0 | D21: ='Raw IS'!C21 -> 0 | E21: ='Raw IS'!D21 -> 0 | F21: ='Raw IS'!E21 -> 0 | G21: ='Raw IS'!F21 -> 0 | H21: ='Raw IS'!G21 -> 0 | I21: ='Raw IS'!H21 -> -38.57 | J21: ='Raw IS'!I21 -> -57.61 | ... L21: ='Raw IS'!K21 -> 201.86 | AL21: Finance Cost / Sales | AM21: =IFERROR(O12/O3,0) -> 0.0048157544 | AN21: =IFERROR(P12/P3,0) -> 0.0098331676 | AO21: =IFERROR(Q12/Q3,0) -> 0.0063726113 | AP21: =IFERROR(R12/R3,0) -> 0.0071123755 | AQ21: =IFERROR(S12/S3,0) -> 0.0041452791 | AR21: =IFERROR(T12/T3,0) -> 0.0048116677 | AS21: =IFERROR(U12/U3,0) -> 0.012888862 | AT21: =IFERROR(V12/V3,0) -> 0.012693896 | ... AV21: =IFERROR(X12/X3,0) -> 0.014347026 | AY21: Change in Working Capital | AZ21: ="" | BA21: =BA20-AZ20 -> -12.88 | BB21: =BB20-BA20 -> 273.91 | BC21: =BC20-BB20 -> -34.18 | BD21: =BD20-BC20 -> 59.84 | BE21: =BE20-BD20 -> 248.31 | BF21: =BF20-BE20 -> 26.44 | BG21: =BG20-BF20 -> 141.09 | BH21: =BH20-BG20 -> 298.71 | BI21: =BI20-BH20 -> 14.59 | BJ21: =AVERAGE(BA21:BI21) -> 112.87
B22: Profit Before Extraordinary Items and Tax | C22: ='Raw IS'!B22 -> -82.58 | D22: ='Raw IS'!C22 -> -129.76 | E22: ='Raw IS'!D22 -> -59.91 | F22: ='Raw IS'!E22 -> -48.21 | G22: ='Raw IS'!F22 -> 51.48 | H22: ='Raw IS'!G22 -> 21.97 | I22: ='Raw IS'!H22 -> -176.36 | J22: ='Raw IS'!I22 -> -84.96 | ... L22: ='Raw IS'!K22 -> 292.38 | AL22: Tax / Sales | AM22: =IFERROR(O16/O3,0) -> -0.016984134 | AN22: =IFERROR(P16/P3,0) -> 0.0041002222 | AO22: =IFERROR(Q16/Q3,0) -> -0.029108936 | AP22: =IFERROR(R16/R3,0) -> 0.01084524 | AQ22: =IFERROR(S16/S3,0) -> 0.013885066 | AR22: =IFERROR(T16/T3,0) -> -0.0087334525 | AS22: =IFERROR(U16/U3,0) -> 0.019255112 | AT22: =IFERROR(V16/V3,0) -> 0.0049296682 | ... AV22: =IFERROR(X16/X3,0) -> 0.017957627 | AY22: Total Reinvestment (Net Capex + Change in WC) | AZ22: ="" | BA22: =BA6+BA21 -> 96.18 | BB22: =BB6+BB21 -> 400.85 | BC22: =BC6+BC21 -> 270.3 | BD22: =BD6+BD21 -> 263.29 | BE22: =BE6+BE21 -> 284.14 | BF22: =BF6+BF21 -> -42.68 | BG22: =BG6+BG21 -> 40.48 | BH22: =BH6+BH21 -> 311.51 | BI22: =BI6+BI21 -> 12.51 | BJ22: =AVERAGE(BA22:BI22) -> 181.84222
B23: Prior Year Adjustments | C23: ='Raw IS'!B23 -> 0 | D23: ='Raw IS'!C23 -> 0 | E23: ='Raw IS'!D23 -> 0 | F23: ='Raw IS'!E23 -> 0 | G23: ='Raw IS'!F23 -> 0 | H23: ='Raw IS'!G23 -> 0 | I23: ='Raw IS'!H23 -> 0 | J23: ='Raw IS'!I23 -> 0 | ... L23: ='Raw IS'!K23 -> 0
B24: Other Adjustments Before Tax | C24: ='Raw IS'!B24 -> 0 | D24: ='Raw IS'!C24 -> 0 | E24: ='Raw IS'!D24 -> 0 | F24: ='Raw IS'!E24 -> 0 | G24: ='Raw IS'!F24 -> 0 | H24: ='Raw IS'!G24 -> 0 | I24: ='Raw IS'!H24 -> 0 | J24: ='Raw IS'!I24 -> 0 | ... L24: ='Raw IS'!K24 -> 0 | AL24: Return Ratios (%) | AY24: EBIT | AZ24: =O11 -> -79.42 | BA24: =P11 -> -121.52 | BB24: =Q11 -> -52.45 | BC24: =R11 -> -41.18 | BD24: =S11 -> 56.94 | BE24: =T11 -> 29.13 | BF24: =U11 -> -120.48 | BG24: =V11 -> -4.69 | ... BI24: =X11 -> 342.67 | BJ24: =AVERAGE(AZ24:BI24) -> 18.462
B25: Extraordinary Items Before Tax | C25: ='Raw IS'!B25 -> 0 | D25: ='Raw IS'!C25 -> 0 | E25: ='Raw IS'!D25 -> 0 | F25: ='Raw IS'!E25 -> 0 | G25: ='Raw IS'!F25 -> 0 | H25: ='Raw IS'!G25 -> 0 | I25: ='Raw IS'!H25 -> 0 | J25: ='Raw IS'!I25 -> 0 | ... L25: ='Raw IS'!K25 -> 0 | AL25: Return on Capital Employed (ROCE) | AM25: ="" | AN25: =IFERROR(AB8/AVERAGE((P51+P52+P53+P54+P55+P58+P59),(O51+O52+O53+O54+O55+O58+O59)),"") -> -0.091376356 | AO25: =IFERROR(AC8/AVERAGE((Q51+Q52+Q53+Q54+Q55+Q58+Q59),(P51+P52+P53+P54+P55+P58+P59)),"") -> -0.053399029 | AP25: =IFERROR(AD8/AVERAGE((R51+R52+R53+R54+R55+R58+R59),(Q51+Q52+Q53+Q54+Q55+Q58+Q59)),"") -> -0.047873878 | AQ25: =IFERROR(AE8/AVERAGE((S51+S52+S53+S54+S55+S58+S59),(R51+R52+R53+R54+R55+R58+R59)),"") -> 0.0025126376 | AR25: =IFERROR(AF8/AVERAGE((T51+T52+T53+T54+T55+T58+T59),(S51+S52+S53+S54+S55+S58+S59)),"") -> -0.0065471346 | AS25: =IFERROR(AG8/AVERAGE((U51+U52+U53+U54+U55+U58+U59),(T51+T52+T53+T54+T55+T58+T59)),"") -> -0.05578732 | AT25: =IFERROR(AH8/AVERAGE((V51+V52+V53+V54+V55+V58+V59),(U51+U52+U53+U54+U55+U58+U59)),"") -> -0.013414977 | AU25: =IFERROR(AI8/AVERAGE((W51+W52+W53+W54+W55+W58+W59),(V51+V52+V53+V54+V55+V58+V59)),"") -> 0.050507141 | AV25: =IFERROR(AJ8/AVERAGE((X51+X52+X53+X54+X55+X58+X59),(W51+W52+W53+W54+W55+W58+W59)),"") -> 0.091564782 | AY25: Reinvestment Rate | AZ25: ="" | BA25: =IFERROR(BA22/BA24,"") -> -0.79147465 | BB25: =IFERROR(BB22/BB24,"") -> -7.6425167 | BC25: =IFERROR(BC22/BC24,"") -> -6.563866 | BD25: =IFERROR(BD22/BD24,"") -> 4.6239902 | BE25: =IFERROR(BE22/BE24,"") -> 9.7542053 | BF25: =IFERROR(BF22/BF24,"") -> 0.35424967 | BG25: =IFERROR(BG22/BG24,"") -> -8.6311301 | BH25: =IFERROR(BH22/BH24,"") -> 1.7737729 | BI25: =IFERROR(BI22/BI24,"") -> 0.036507427 | BJ25: =AVERAGE(BA25:BI25) -> -0.78736243 | BK25: Average reinvestment rate
B26: Profit Before Tax | C26: ='Raw IS'!B26 -> -82.58 | D26: ='Raw IS'!C26 -> -129.76 | E26: ='Raw IS'!D26 -> -59.91 | F26: ='Raw IS'!E26 -> -48.21 | G26: ='Raw IS'!F26 -> 51.48 | H26: ='Raw IS'!G26 -> 21.97 | I26: ='Raw IS'!H26 -> -176.36 | J26: ='Raw IS'!I26 -> -84.96 | ... L26: ='Raw IS'!K26 -> 292.38 | AL26: Return on Assets (ROA) | AM26: ="" | AN26: =IFERROR(P17/AVERAGE(P49,O49),"") -> -0.056390125 | AO26: =IFERROR(Q17/AVERAGE(Q49,P49),"") -> -0.008056887 | AP26: =IFERROR(R17/AVERAGE(R49,Q49),"") -> -0.019278845 | AQ26: =IFERROR(S17/AVERAGE(S49,R49),"") -> 0.011118902 | AR26: =IFERROR(T17/AVERAGE(T49,S49),"") -> 0.010330659 | AS26: =IFERROR(U17/AVERAGE(U49,T49),"") -> -0.062141042 | AT26: =IFERROR(V17/AVERAGE(V49,U49),"") -> -0.029022293 | AU26: =IFERROR(W17/AVERAGE(W49,V49),"") -> 0.040254547 | AV26: =IFERROR(X17/AVERAGE(X49,W49),"") -> 0.12972777 | AY26: Total Capital Employed | AZ26: =SUM(O51:O53)+O54+O55+O58+O59-O47 -> 1145.43 | BA26: =SUM(P51:P53)+P54+P55+P58+P59-P47 -> 2149.25 | BB26: =SUM(Q51:Q53)+Q54+Q55+Q58+Q59-Q47 -> 2618.59 | BC26: =SUM(R51:R53)+R54+R55+R58+R59-R47 -> 2481.57 | BD26: =SUM(S51:S53)+S54+S55+S58+S59-S47 -> 2575.01 | BE26: =SUM(T51:T53)+T54+T55+T58+T59-T47 -> 2843.1 | BF26: =SUM(U51:U53)+U54+U55+U58+U59-U47 -> 2557.65 | BG26: =SUM(V51:V53)+V54+V55+V58+V59-V47 -> 2507.71 | ... BI26: =SUM(X51:X53)+X54+X55+X58+X59-X47 -> 2922.89 | BJ26: =AVERAGE(AZ26:BI26) -> 2457.335
B27: Tax Expenses | C27: ='Raw IS'!B27 -> -11.85 | D27: ='Raw IS'!C27 -> 3.34 | E27: ='Raw IS'!D27 -> -34.35 | F27: ='Raw IS'!E27 -> 11.97 | G27: ='Raw IS'!F27 -> 17.15 | H27: ='Raw IS'!G27 -> -11.09 | I27: ='Raw IS'!H27 -> 25.86 | J27: ='Raw IS'!I27 -> 8.8 | ... L27: ='Raw IS'!K27 -> 39.54 | AL27: Return on Equity (ROE) | AM27: ="" | AN27: =IFERROR(P17/AVERAGE(SUM(P51:P52),SUM(O51:O52)),"") -> -0.071102682 | AO27: =IFERROR(Q17/AVERAGE(SUM(Q51:Q52),SUM(P51:P52)),"") -> -0.0096415094 | AP27: =IFERROR(R17/AVERAGE(SUM(R51:R52),SUM(Q51:Q52)),"") -> -0.02336904 | AQ27: =IFERROR(S17/AVERAGE(SUM(S51:S52),SUM(R51:R52)),"") -> 0.013494019 | AR27: =IFERROR(T17/AVERAGE(SUM(T51:T52),SUM(S51:S52)),"") -> 0.012772355 | AS27: =IFERROR(U17/AVERAGE(SUM(U51:U52),SUM(T51:T52)),"") -> -0.080028336 | AT27: =IFERROR(V17/AVERAGE(SUM(V51:V52),SUM(U51:U52)),"") -> -0.038476691 | AU27: =IFERROR(W17/AVERAGE(SUM(W51:W52),SUM(V51:V52)),"") -> 0.056258169 | AV27: =IFERROR(X17/AVERAGE(SUM(X51:X52),SUM(W51:W52)),"") -> 0.18320327 | AY27: Return on Capital Employed | AZ27: =IFERROR(AZ24/AZ26,"") -> -0.069336406 | BA27: =IFERROR(BA24/BA26,"") -> -0.056540654 | BB27: =IFERROR(BB24/BB26,"") -> -0.020029863 | BC27: =IFERROR(BC24/BC26,"") -> -0.016594333 | BD27: =IFERROR(BD24/BD26,"") -> 0.022112535 | BE27: =IFERROR(BE24/BE26,"") -> 0.010245858 | BF27: =IFERROR(BF24/BF26,"") -> -0.047105742 | BG27: =IFERROR(BG24/BG26,"") -> -0.0018702322 | ... BI27: =IFERROR(BI24/BI26,"") -> 0.11723671 | BJ27: =AVERAGE(AZ27:BI27) -> 0.00014694209
B28: Current Tax | C28: ='Raw IS'!B28 -> -13.66 | D28: ='Raw IS'!C28 -> 1.15 | E28: ='Raw IS'!D28 -> 7.14 | F28: ='Raw IS'!E28 -> 5.47 | G28: ='Raw IS'!F28 -> 16.68 | H28: ='Raw IS'!G28 -> 10.51 | I28: ='Raw IS'!H28 -> 11.06 | J28: ='Raw IS'!I28 -> 7.94 | ... L28: ='Raw IS'!K28 -> 3.57 | AL28: Return on Invested Capital (ROIC) | AM28: ="" | AN28: =IFERROR(AB10/AVERAGE(AB77,AA77),"") -> -0.15657547 | AO28: =IFERROR(AC10/AVERAGE(AC77,AB77),"") -> -0.079468256 | AP28: =IFERROR(AD10/AVERAGE(AD77,AC77),"") -> -0.080501308 | AQ28: =IFERROR(AE10/AVERAGE(AE77,AD77),"") -> -0.005131849 | AR28: =IFERROR(AF10/AVERAGE(AF77,AE77),"") -> -0.0030750022 | AS28: =IFERROR(AG10/AVERAGE(AG77,AF77),"") -> -0.071811626 | AT28: =IFERROR(AH10/AVERAGE(AH77,AG77),"") -> -0.017741675 | AU28: =IFERROR(AI10/AVERAGE(AI77,AH77),"") -> 0.046418509 | AV28: =IFERROR(AJ10/AVERAGE(AJ77,AI77),"") -> 0.084095813
B29: Deferred Tax | C29: ='Raw IS'!B29 -> 1.81 | D29: ='Raw IS'!C29 -> 14.91 | E29: ='Raw IS'!D29 -> -40.24 | F29: ='Raw IS'!E29 -> 6.5 | G29: ='Raw IS'!F29 -> -0.15 | H29: ='Raw IS'!G29 -> -21.84 | I29: ='Raw IS'!H29 -> 15.35 | J29: ='Raw IS'!I29 -> 0.86 | ... L29: ='Raw IS'!K29 -> 35.53 | AY29: Expected Growth | AZ29: ="" | BA29: =IFERROR(BA25*BA27,"") -> 0.044750494 | BB29: =IFERROR(BB25*BB27,"") -> 0.15307857 | BC29: =IFERROR(BC25*BC27,"") -> 0.10892298 | BD29: =IFERROR(BD25*BD27,"") -> 0.10224815 | BE29: =IFERROR(BE25*BE27,"") -> 0.099940206 | BF29: =IFERROR(BF25*BF27,"") -> -0.016687193 | BG29: =IFERROR(BG25*BG27,"") -> 0.016142217 | BH29: =IFERROR(BH25*BH27,"") -> 0.11237126 | BI29: =IFERROR(BI25*BI27,"") -> 0.0042800105 | BJ29: =AVERAGE(BA29:BI29) -> 0.069449632 | BK29: Average expected growth
